Workbook

Sheet Base Data
A1: Expiry | D1: 18NovFut | G1: 18DecFut | H1: 19JanFut
A2: Initial Portfolio Size (Rs.) | D2: 100000
A3: Initial Max. Risk per Trade % | D3: 0.105
A4: Current P&L (Rs.) | F4: Link this cell to the current P&L
A5: Current Portfolio Size (Rs.) | D5: =D2+D4 -> 100000
A6: Current Max. Risk per Trade % | D6: =IF((D5>=100%*D2),D3,IF(AND((D5>=90%*D2),(D5<100%*D2)),C23,IF(AND((D5>=80%*D2),(D5<90%*D2)),D23,IF(AND((D5>=70%*D2),(D5<80%*D2)),E23,IF(AND((D5>=60%*D2),(D5<70%*D2)),F23,IF(AND((D5>=50%*D2),(D5<60%*D2)),G23,IF(AND((D5>=40%*D2),(D5<50%*D2)),H23,IF(AND((D5>=30%*D2),(D5<40%*D2)),I23,IF(AND((D5>=20%*D2),(D5<30%*D2)),J23,IF(AND((D5>=10%*D2),(D5<20%*D2)),K23,IF((D5<=10%*D2),L23,"Check"))))))))))) -> 0.105
A7: Max. Risk per Trade (Rs.) [Unit] | D7: =D5*D6 -> 10500
A8: Avg. No. of Trades | D8: =D5/D7 -> 9.5238095
A9: % Reduction in Risk | D9: 0.1
A10: ATR Multiple for SL & TP (Positional) | D10: 2
A11: Max. Positions per Scrip for Pyramiding (Positional) | D11: 5
A12: ATR Multiple for Pyramiding (Positional) | D12: 0.4
A13: ATR Multiple for SL & TP (Intraday) | D13: 0.75
A14: ORB - Points Above / Below Entry Criteria | D14: 0.05
A15: Trend Finder - MFI Up / Down Value | D15: 50 | E15: 50
A16: MFI Max. / Min. Alert Breach Level | D16: 2 | E16: 2
A17: Gann Angle - Trade Type (IntraDay = 0 / Positional = 1) | D17: 0
A18: Gann Angle - Trade Holding Period (Positional Trades) | D18: 10
A19: Gann Angle - Market Stabilisation Period | D19: =DATE(YEAR(NOW()),MONTH(NOW()),DAY(NOW()))+TIME(9,15,0) -> 45769.385 | E19: 0.39583333
A20: Gann Angle - Current Time | D20: =NOW() -> 45769.773
A22: DrawDown % | C22: 90-100% | D22: 80-90% | E22: 70-80% | F22: 60-70% | G22: 50-60% | H22: 40-50% | I22: 30-40% | J22: 20-30% | K22: 10-20% | L22: 0-10%
A23: Max. Risk per Trade % | C23: =D3 -> 0.105 | D23: =C23*(100%-$D$9) -> 0.0945 | E23: =D23*(100%-$D$9) -> 0.08505 | F23: =E23*(100%-$D$9) -> 0.076545 | G23: =F23*(100%-$D$9) -> 0.0688905 | H23: =G23*(100%-$D$9) -> 0.06200145 | I23: =H23*(100%-$D$9) -> 0.055801305 | J23: =I23*(100%-$D$9) -> 0.050221175 | K23: =J23*(100%-$D$9) -> 0.045199057 | L23: =K23*(100%-$D$9) -> 0.040679151
A25: Charges | C25: Brokerage | D25: Turnover | E25: Service Tax | F25: Edu. Cess | G25: H. Edu. Cess | H25: SEBI | I25: Stamp | J25: STT | K25: Slippage
A26: % of Turnover | C26: 0.0002 | D26: 2.1e-05 | E26: 0.14 | F26: 0.005 | G26: 0.005 | H26: - | I26: 2e-05 | J26: 0.0001 | K26: 0.0004
A27: Rate per Transaction (Rs.) | C27: 20 | D27: - | E27: - | F27: - | G27: - | H27: =20/10000000 -> 2e-06 | I27: - | J27: -
A79: Trade Type
A80: 0 | B80: IntraDay
A81: 1 | B81: Positional

Sheet All Columns
B1: =[1]NOW!$C$6 -> 9345 | C1: =[1]NOW!$E$6 -> 28.3 | D1: =NOW() -> 45769.773 | F1: Positional | G1: Positional | H1: IntraDay | BN1: Gap Up/Dn | CJ1: MFI Crossover [Price should be above 55 VW SMA Open for Long & vice versa] | CQ1: Price SMA Crossover [Price should be above 55 VW SMA Open for Long & vice versa] | DG1: Positional (MFI Crossover & SMA Crossover Strategies) | DR1: IntraDay (ORB, Gap Up/Dn & O=H/O=L Strategies) | EM1: ORB | EO1: ORB
A2: Sr. No. | B2: Scrip | C2: Current Market Price | D2: LTP - Curr. Open | E2: LTP - Prev. Close | F2: RSI Cross Decision to Trade | G2: SMA Cross Decision to Trade | H2: IntraDay Recommendation | I2: Basic Reco. | J2: Gap Up / Dn | K2: Gap Zone | L2: Gap Zone Reco. (Fade / GA) | M2: O=H & O=L | N2: Prev. Day's High/Low Break-Out | O2: IntraDay Trend (Impulse System) | P2: IntraDay Trend (Tom Demark Method) | Q2: IntraDay Trend (Modified Pivot) | R2: IAV Status | S2: No. of Lots (I) | T2: IntraDay Strength / Weakness of Market | U2: IntraDay Strength / Weakness of Market | V2: IntraDay Rank (Strong) | W2: IntraDay Rank (Weak) | X2: IntraDay Trend (Choppy Market Index) | Y2: IntraDay Trend (Buy/Sell Easier Day) | Z2: VW Avg. True Range % (21) | AA2: VW Avg. True Range % (8) | AB2: Positional Strength / Weakness of Market | AC2: Positional Rank (Strong) | AD2: Positional Rank (Weak) | AE2: Positional Trend (LTP & 13 VW EMA Open with 5 VW EMA HLC Avg. %Diff.) | AF2: Positional Trend [VW MACD Hist., MFI(14) & SMA MFI(14)] | AG2: Volume Status | AH2: No. of Lots (P) | AI2: Enter Buy / Sell Price | AJ2: Enter Strategy Type | AK2: Points | AL2: Net Profit / Loss (Post Charges) | AM2: %Returns (Post Charges) | AN2: Rank | AO2: Approx. Margin Utilised | AP2: Transaction Value | AQ2: Brokerage | AR2: Turnover Charges | AS2: Service Tax (incl. Cess) | AT2: SEBI Charges | AU2: Stamp Duty Charges | AV2: STT | AW2: Slippage | AX2: Total Charges | AY2: Gross Profit / Loss (Pre Charges) | AZ2: In Market | BA2: Scrip with Expiry | BB2: Best Buy Rate | BC2: Last Traded Price | BD2: Best Sell Rate | BE2: Qty | BF2: Approx. Margin Required Per Lot | BG2: Open | BH2: High | BI2: Low | BJ2: Prev. Open | BK2: Prev. High | BL2: Prev. Low | BM2: Prev. Close | BN2: Gap Size | BO2: Gap Size (%) | BP2: Beta with Nifty (21 D) | BQ2: Volume | BR2: Volume (21 Day SMA) | BS2: IAV | BT2: IAV (21 Day SMA) | BU2: VM SMA (Open) [55 Day] (Curr.) | BV2: VM EMA (Open) [13 Day] (Curr.) | BW2: VM EMA (Open) [13 Day] (Prev.) | BX2: VM EMA (HLC Average) [5 Day] (Curr.) | BY2: VM EMA (HLC Average) [5 Day] (Prev.) | BZ2: % Diff. [LTP & 5 VM EMA HLC Average] (Curr.) | CA2: % Diff. [P. Close & 5 VM EMA HLC Average] (Prev.) | CB2: VW MACD Hist. [HLC Avg.] (Curr.) | CC2: VW MACD Hist. [HLC Avg.] (Prev.) | CD2: VW MACD Hist. [HLC Avg.] (Prev.-1) | CE2: MFI (14) [HLC Avg.] (Curr.) | CF2: MFI (14) [HLC Avg.] (Prev.) | CG2: MFI (14) [HLC Avg.] (Prev.-1) | CH2: MFI (14) Max. Breach Level | CI2: MFI (14) Min. Breach Level | CJ2: SMA [34 Day - MFI(14)] [HLC Avg.] (Curr.) | CK2: SMA [34 Day - MFI(14)] [HLC Avg.] (Prev.) | CL2: SMA [34 Day - MFI(14)] [HLC Avg.] (Prev.-1) | CM2: SMA [21 Day - MFI(14)] [HLC Avg.] (Curr.) | CN2: SMA [21 Day - MFI(14)] [HLC Avg.] (Prev.) | CO2: Entry [MFI(14) & SMA MFI(14) Crossover] | CP2: Exit [MFI(14) & SMA MFI(14) Crossover] | CQ2: VW SMA [34 Day Open] (Curr.) | CR2: VW SMA [34 Day Open] (Prev.) | CS2: VW SMA [13 Day Low] (Curr.) | CT2: VW SMA [13 Day Low] (Prev.) | CU2: VW SMA [13 Day High] (Curr.) | CV2: VW SMA [13 Day High] (Prev.) | CW2: VW SMA [13 Day Open] (Curr.) | CX2: VW SMA [13 Day Open] (Prev.) | CY2: VW SMA [5 Day Low] (Curr.) | CZ2: VW SMA [5 Day Low] (Prev.) | DA2: VW SMA [5 Day High] (Curr.) | DB2: VW SMA [5 Day High] (Prev.) | DC2: Entry [LTP & VW SMA Open Crossover] | DD2: Exit [LTP & VW SMA Low/High Crossover] | DE2: Common Entry [LTP & VW SMA Open] with [MFI(14) & SMA MFI(14)] | DF2: Common Exit [LTP & VW SMA Low/High] with [MFI(14) & SMA MFI(14)] | DG2: VW Average True Range (21) | DH2: =CONCATENATE("Max. Lots with Risk per Trade of Rs. ",'Base Data'!$D$7," [No. of Lots]") -> Max. Lots with Risk per Trade of Rs. 10500 [No. of Lots] | DI2: =CONCATENATE("Hard Stop Loss & Target Points. from Entry [",'Base Data'!$D$10,"N]") -> Hard Stop Loss & Target Points. from Entry [2N] | DJ2: Points till Hard Stop Loss | DK2: =CONCATENATE("Hard Stop Loss [",'Base Data'!$D$10,"N]") -> Hard Stop Loss [2N] | DL2: =CONCATENATE("Enter Additional Position [",1*'Base Data'!$D$12,"N]") -> Enter Additional Position [0.4N] | DM2: =CONCATENATE("Enter Additional Position [",2*'Base Data'!$D$12,"N]") -> Enter Additional Position [0.8N] | DN2: =CONCATENATE("Enter Additional Position [",3*'Base Data'!$D$12,"N]") -> Enter Additional Position [1.2N] | DO2: =CONCATENATE("Enter Additional Position [",4*'Base Data'!$D$12,"N]") -> Enter Additional Position [1.6N] | DP2: =CONCATENATE("Target [",'Base Data'!$D$10,"N]") -> Target [2N] | DQ2: Points till Target | DR2: VW Average True Range (8) | DS2: =CONCATENATE("Max. Lots with Risk per Trade of Rs. ",'Base Data'!$D$7," [No. of Lots]") -> Max. Lots with Risk per Trade of Rs. 10500 [No. of Lots] | DT2: =CONCATENATE("Hard Stop Loss & Target Points. from Entry [",'Base Data'!$D$13,"N]") -> Hard Stop Loss & Target Points. from Entry [0.75N] | DU2: Points till Hard Stop Loss | DV2: =CONCATENATE("Hard Stop Loss [",'Base Data'!$D$13,"N]") -> Hard Stop Loss [0.75N] | DW2: =CONCATENATE("Target [",'Base Data'!$D$13,"N]") -> Target [0.75N] | DX2: Pomits till Target | DY2: Ageing | DZ2: Reco. | EA2: New Buy / Sell Reco. | EB2: Sector Buy / Sell Reco. | EC2: TP 10K | ED2: Exits | EE2: Profit | EF2: Loss | EG2: Margin Utilised for Long Trades (Positional) | EH2: Margin Utilised for Short Trades (Positional) | EI2: Margin Utilised for Long Trades (IntraDay) | EJ2: Margin Utilised for Short Trades (IntraDay) | EK2: No. of Profitable Trade | EL2: No. of Losing Trades | EM2: ORB Decision to Trade | EN2: Reco. ORB (Basic) | EO2: ORB Enter High at 9:30 AM | EP2: ORB Enter Low at 9:30 AM | EQ2: ORB Exit / Hold | ER2: % Change (LTP - Prev. Close) | ES2: % Diff. (High - Low) | ET2: HL Avg. % Change Status | EU2: HL Avg. % Change (8 Day) | EV2: HL Avg. % Change (13 Day) | EW2: HL Avg. % Change (21 Day) | EX2: HL Avg. % Change (55 Day) | EY2: ORB In Trade | EZ2: Exit & Reverse
A5: 1 | B5: BankNifty | C5: =IF(AND(I5=1,BD5<>0),BD5,IF(AND(I5=2,BB5<>0),BB5,BC5)) -> 25845.55 | D5: =(BC5-BG5) -> 115.55 | E5: =(BC5-BM5) -> 2503.8 | I5: =IF(OR(J5=0,K5=0),0,IF(AND(M5=1,N5="Up-BO"),IF(OR(AND(J5="PGDn",K5="D-CL"),AND(J5="FGDn",K5="D-L"),AND(J5="PGDn",K5="U-CO"),AND(J5="PGDn",K5="U-OL"),AND(J5="PGUp",K5="U-HC"),AND(J5="PGUp",K5="D-OC"),AND(J5="PGUp",K5="D-HO"),AND(J5="FGDn",K5="U-L")),1,IF(AND(M5=2,N5="Dn-BO"),IF(OR(AND(J5="PGDUp",K5="U-HC"),AND(J5="FGUp",K5="U-H"),AND(J5="PGUp",K5="D-OC"),AND(J5="PGUp",K5="D-HO"),AND(J5="PGDn",K5="D-CL"),AND(J5="PGDn",K5="U-CO"),AND(J5="PGDn",K5="U-OL"),AND(J5="FGUp",K5="D-H")),2,IF(AND(M5=1,N5="Dn2Up-BO"),1,IF(AND(M5=2,N5="Up2Dn-BO"),2,0))),0)),IF(AND(M5=1,N5="Up-BO"),IF(OR(AND(J5="PGDn",K5="D-CL"),AND(J5="FGDn",K5="D-L"),AND(J5="PGDn",K5="U-CO"),AND(J5="PGDn",K5="U-OL"),AND(J5="PGUp",K5="U-HC"),AND(J5="PGUp",K5="D-OC"),AND(J5="PGUp",K5="D-HO"),AND(J5="FGDn",K5="U-L")),1,IF(AND(M5=2,N5="Dn-BO"),IF(OR(AND(J5="PGDUp",K5="U-HC"),AND(J5="FGUp",K5="U-H"),AND(J5="PGUp",K5="D-OC"),AND(J5="PGUp",K5="D-HO"),AND(J5="PGDn",K5="D-CL"),AND(J5="PGDn",K5="U-CO"),AND(J5="PGDn",K5="U-OL"),AND(J5="FGUp",K5="D-H")),2,IF(AND(M5=1,N5="Dn2Up-BO"),1,IF(AND(M5=2,N5="Up2Dn-BO"),2,0))),0)),0))) -> 0 | J5: =IF(AND(BG5>BM5,BG5<=BK5),"PGUp",IF(AND(BG5>BM5,BG5>BK5),"FGUp",IF(AND(BG5<BM5,BG5>=BL5),"PGDn",IF(AND(BG5<BM5,BG5<BL5),"FGDn",0)))) -> FGUp | K5: =IF(BM5>BJ5,IF(BG5>BK5,"U-H",IF(AND(BG5<=BK5,BG5>BM5),"U-HC",IF(AND(BG5<BM5,BG5>=BJ5),"U-CO",IF(AND(BG5<BJ5,BG5>=BL5),"U-OL",IF(BG5<BL5,"U-L",0))))),IF(BM5<BJ5,IF(BG5>BK5,"D-H",IF(AND(BG5<=BK5,BG5>BJ5),"D-HO",IF(AND(BG5<=BJ5,BG5>BM5),"D-OC",IF(AND(BG5<BM5,BG5>=BL5),"D-CL",IF(BG5<BL5,"D-L",0))))),0)) -> D-H | L5: =IF(BM5>BJ5,IF(BG5>BK5,"Fade-Short",IF(AND(BG5<=BK5,BG5>BM5),"Fade-Short",IF(AND(BG5<BM5,BG5>=BJ5),"Fade-Long",IF(AND(BG5<BJ5,BG5>=BL5),"Fade-Long",IF(BG5<BL5,"GA-Short",0))))),IF(BM5<BJ5,IF(BG5>BK5,"GA-Long",IF(AND(BG5<=BK5,BG5>BJ5),"Fade-Short",IF(AND(BG5<=BJ5,BG5>BM5),"Fade-Short",IF(AND(BG5<BM5,BG5>=BL5),"Fade-Long",IF(BG5<BL5,"Fade-Long",0))))),0)) -> GA-Long | M5: =IF(BG5=BI5,1,IF(BG5=BH5,2,0)) -> 0 | N5: =IF(AND(BG5<BK5,BC5>BK5),"Up-BO",IF(AND(BG5>BL5,BC5<BL5),"Dn-BO",IF(AND(J5="FGDn",BC5>BL5),"Dn2Up-BO",IF(AND(J5="FGUp",BC5<BK5),"Up2Dn-BO",0)))) -> 0 | O5: =IF(AND((IF(BV5>BW5,1,-1)>0),(IF(CB5>CC5,1,-1)>0)),1,IF(AND((IF(BV5>BW5,1,-1)<0),(IF(CB5>CC5,1,-1)<0)),2,0)) -> 1 | P5: =IF(BC5>(BH5-(BG5*0.5%)),1,IF(BC5<(BI5+(BG5*0.5%)),2,0)) -> 1 | Q5: =IF(C5>((BG5+BK5+BL5+BM5)/4),1,IF(C5<((BG5+BK5+BL5+BM5)/4),2,0)) -> 1 | R5: =IF((BS5>BT5),1,0) -> 1 | S5: =DS5 -> 0 | T5: ='BNF-Nifty'!$FC$69 -> 2.7487488 | U5: =IF(S5<>0,T5,"-") -> - | V5: =IF(U5="-","-",_xlfn.RANK.EQ(U5,$U$5:$U$12,0)) -> - | W5: =IF(U5="-","-",_xlfn.RANK.EQ(U5,$U$5:$U$12,1)) -> - | X5: ='BNF-Nifty'!$FS$69 -> T-R | Y5: ='BNF-Nifty'!$FP$69 -> 2 | Z5: ='BNF-Nifty'!$DZ$69 -> 0.022468629 | AA5: ='BNF-Nifty'!$ER$69 -> 0.038260261 | AB5: ='BNF-Nifty'!$FB$69 -> 5.0661725 | AC5: =_xlfn.RANK.AVG(AB5,$AB$5:$AB$12,0) -> 2 | AD5: =_xlfn.RANK.AVG(AB5,$AB$5:$AB$12,1) -> 3 | AE5: =IF(AND(BC5>BU5,BC5>BV5,BZ5>=CA5,BX5>BY5),"1. Strong Up-R",IF(AND(BC5>BU5,BC5>BV5,BZ5>=CA5,BX5=BY5),"1. Strong Up-F",IF(AND(BC5>BU5,BC5>BV5,BZ5>=CA5,BX5<BY5),"1. Strong Up-D",IF(AND(BC5>BU5,BC5>BV5,BZ5<CA5,BX5>BY5),"2. Weak Up-R",IF(AND(BC5>BU5,BC5>BV5,BZ5<CA5,BX5=BY5),"2. Weak Up-F",IF(AND(BC5>BU5,BC5>BV5,BZ5<CA5,BX5<BY5),"2. Weak Up-D",IF(AND(BC5<BU5,BC5<BV5,BZ5<=CA5,BX5<BY5),"1. Strong Dn-D",IF(AND(BC5<BU5,BC5<BV5,BZ5<=CA5,BX5=BY5),"1. Strong Dn-F",IF(AND(BC5<BU5,BC5<BV5,BZ5<=CA5,BX5>BY5),"1. Strong Dn-R",IF(AND(BC5<BU5,BC5<BV5,BZ5>CA5,BX5<BY5),"2. Weak Dn-D",IF(AND(BC5<BU5,BC5<BV5,BZ5>CA5,BX5=BY5),"2. Weak Dn-F",IF(AND(BC5<BU5,BC5<BV5,BZ5>CA5,BX5>BY5),"2. Weak Dn-R","-")))))))))))) -> 1. Strong Up-R | AF5: =IF(CE5>CH5,"MFI Nr. Max. Level",IF(CE5<CI5,"MFI Nr. Min. Level",IF(AND(BC5>BU5,CB5>CC5,CC5>CD5,CB5>=0,CE5>CJ5,CE5>CF5,CE5>=50,CF5>=50),"1. Ultimate Up - R",IF(AND(BC5>BU5,CB5>CC5,CC5>CD5,CB5>=0,CE5>CJ5,CE5=CF5,CE5>=50,CF5>=50),"1. Ultimate Up - F",IF(AND(BC5>BU5,CB5>CC5,CC5>CD5,CB5>=0,CE5>CJ5,CE5<CF5,CE5>=50,CF5>=50),"1. Ultimate Up - D",IF(AND(BC5>BU5,CB5>CC5,CC5>CD5,CB5<0,CE5>CJ5,CE5>CF5,CE5>=50,CF5>=50),"2. Extreme Up - R",IF(AND(BC5>BU5,CB5>CC5,CC5>CD5,CB5<0,CE5>CJ5,CE5=CF5,CE5>=50,CF5>=50),"2. Extreme Up - F",IF(AND(BC5>BU5,CB5>CC5,CC5>CD5,CB5<0,CE5>CJ5,CE5<CF5,CE5>=50,CF5>=50),"2. Extreme Up - D",IF(AND(BC5>BU5,CB5>CC5,CC5>CD5,CB5>=0,CE5>CJ5,CE5>CF5,CE5>=50,CF5<50),"3. Uber Up",IF(AND(BC5>BU5,CB5>CC5,CC5>CD5,CB5<0,CE5>CJ5,CE5>CF5,CE5>=50,CF5<50),"4. Ultra Up",IF(AND(BC5>BU5,CB5>CC5,CC5>CD5,CB5>=0,CE5>CJ5,CE5>CF5,CE5<50),"5. Hyper Up - R",IF(AND(BC5>BU5,CB5>CC5,CC5>CD5,CB5>=0,CE5>CJ5,CE5=CF5,CE5<50),"5. Hyper Up - F",IF(AND(BC5>BU5,CB5>CC5,CC5>CD5,CB5>=0,CE5>CJ5,CE5<CF5,CE5<50),"5. Hyper Up - D",IF(AND(BC5>BU5,CB5>CC5,CC5>CD5,CB5<0,CE5>CJ5,CE5>CF5,CE5<50),"6. Super Up - R",IF(AND(BC5>BU5,CB5>CC5,CC5>CD5,CB5<0,CE5>CJ5,CE5=CF5,CE5<50),"6. Super Up - F",IF(AND(BC5>BU5,CB5>CC5,CC5>CD5,CB5<0,CE5>CJ5,CE5<CF5,CE5<50),"6. Super Up - D",IF(AND(BC5>BU5,CB5>CC5,CC5<CD5,CB5>=0,CE5>CF5,CE5>=50,CF5>=50),"7. Extra Strong Up - R",IF(AND(BC5>BU5,CB5>CC5,CC5<CD5,CB5>=0,CE5=CF5,CE5>=50,CF5>=50),"7. Extra Strong Up - F",IF(AND(BC5>BU5,CB5>CC5,CC5<CD5,CB5>=0,CE5<CF5,CE5>=50,CF5>=50),"7. Extra Strong Up - D",IF(AND(BC5>BU5,CB5>CC5,CC5<CD5,CB5>=0,CE5>CF5,CE5>=50,CF5<50),"8. Strong Up",IF(AND(BC5>BU5,CB5>CC5,CC5<CD5,CB5<0,CE5>CJ5,CE5>CF5,CE5>=50,CF5>=50),"9. Up - R",IF(AND(BC5>BU5,CB5>CC5,CC5<CD5,CB5<0,CE5>CJ5,CE5=CF5,CE5>=50,CF5>=50),"9. Up - F",IF(AND(BC5>BU5,CB5>CC5,CC5<CD5,CB5<0,CE5>CJ5,CE5<CF5,CE5>=50,CF5>=50),"9. Up - D",IF(AND(BC5>BU5,CB5>CC5,CC5<CD5,CB5<0,CE5>CF5,CE5>=50,CF5>=50),"10. Weak Up - R",IF(AND(BC5>BU5,CB5>CC5,CC5<CD5,CB5<0,CE5=CF5,CE5>=50,CF5>=50),"10. Weak Up - F",IF(AND(BC5>BU5,CB5>CC5,CC5<CD5,CB5<0,CE5<CF5,CE5>=50,CF5>=50),"10. Weak Up - D",IF(AND(BC5>BU5,CB5>CC5,CC5<CD5,CB5<0,CE5>CF5,CE5>=50,CF5<50),"11. Extra Weak Up",IF(AND(BC5>BU5,CB5>CC5,CC5>CD5,CE5>CF5,CE5<50,CF5<50),"12. Very Weak Up - R",IF(AND(BC5>BU5,CB5>CC5,CC5>CD5,CE5=CF5,CE5<50,CF5<50),"12. Very Weak Up - F",IF(AND(BC5>BU5,CB5>CC5,CC5>CD5,CE5<CF5,CE5<50,CF5<50),"12. Very Weak Up - D",IF(AND(BC5<BU5,CB5<CC5,CC5<CD5,CB5<=0,CE5<CJ5,CE5<CF5,CE5<50,CF5<50),"1. Ultimate Dn - D",IF(AND(BC5<BU5,CB5<CC5,CC5<CD5,CB5<=0,CE5<CJ5,CE5=CF5,CE5<50,CF5<50),"1. Ultimate Dn - F",IF(AND(BC5<BU5,CB5<CC5,CC5<CD5,CB5<=0,CE5<CJ5,CE5>CF5,CE5<50,CF5<50),"1. Ultimate Up - R",IF(AND(BC5<BU5,CB5<CC5,CC5<CD5,CB5>0,CE5<CJ5,CE5<CF5,CE5<50,CF5<50),"2. Extreme Dn - D",IF(AND(BC5<BU5,CB5<CC5,CC5<CD5,CB5>0,CE5<CJ5,CE5=CF5,CE5<50,CF5<50),"2. Extreme Dn - F",IF(AND(BC5<BU5,CB5<CC5,CC5<CD5,CB5>0,CE5<CJ5,CE5>CF5,CE5<50,CF5<50),"2. Extreme Dn - R",IF(AND(BC5<BU5,CB5<CC5,CC5<CD5,CB5<=0,CE5<CJ5,CE5<CF5,CE5<50,CF5>=50),"3. Uber Dn",IF(AND(BC5<BU5,CB5<CC5,CC5<CD5,CB5>0,CE5<CJ5,CE5<CF5,CE5<50,CF5>=50),"4. Ultra Dn",IF(AND(BC5<BU5,CB5<CC5,CC5<CD5,CB5<=0,CE5<CJ5,CE5<CF5,CE5>=50),"5. Hyper Dn - D",IF(AND(BC5<BU5,CB5<CC5,CC5<CD5,CB5<=0,CE5<CJ5,CE5=CF5,CE5>=50),"5. Hyper Dn - F",IF(AND(BC5<BU5,CB5<CC5,CC5<CD5,CB5<=0,CE5<CJ5,CE5>CF5,CE5>=50),"5. Hyper Dn - R",IF(AND(BC5<BU5,CB5<CC5,CC5<CD5,CB5>0,CE5<CJ5,CE5<CF5,CE5>=50),"6. Super Dn - D",IF(AND(BC5<BU5,CB5<CC5,CC5<CD5,CB5>0,CE5<CJ5,CE5=CF5,CE5>=50),"6. Super Dn - F",IF(AND(BC5<BU5,CB5<CC5,CC5<CD5,CB5>0,CE5<CJ5,CE5>CF5,CE5>=50),"6. Super Dn - R",IF(AND(BC5<BU5,CB5<CC5,CC5>CD5,CB5<=0,CE5<CF5,CE5<50,CF5<50),"7. Extra Strong Dn - D",IF(AND(BC5<BU5,CB5<CC5,CC5>CD5,CB5<=0,CE5=CF5,CE5<50,CF5<50),"7. Extra Strong Dn - F",IF(AND(BC5<BU5,CB5<CC5,CC5>CD5,CB5<=0,CE5>CF5,CE5<50,CF5<50),"7. Extra Strong Dn - R",IF(AND(BC5<BU5,CB5<CC5,CC5>CD5,CB5<=0,CE5<CF5,CE5<50,CF5>=50),"8. Strong Dn",IF(AND(BC5<BU5,CB5<CC5,CC5>CD5,CB5>0,CE5<CJ5,CE5<CF5,CE5<50,CF5<50),"9. Dn - D",IF(AND(BC5<BU5,CB5<CC5,CC5>CD5,CB5>0,CE5<CJ5,CE5=CF5,CE5<50,CF5<50),"9. Dn - F",IF(AND(BC5<BU5,CB5<CC5,CC5>CD5,CB5>0,CE5<CJ5,CE5>CF5,CE5<50,CF5<50),"9. Dn - R",IF(AND(BC5<BU5,CB5<CC5,CC5>CD5,CB5>0,CE5<CF5,CE5<50,CF5<50),"10. Weak Dn - D",IF(AND(BC5<BU5,CB5<CC5,CC5>CD5,CB5>0,CE5=CF5,CE5<50,CF5<50),"10. Weak Dn - F",IF(AND(BC5<BU5,CB5<CC5,CC5>CD5,CB5>0,CE5>CF5,CE5<50,CF5<50),"10. Weak Dn - R",IF(AND(BC5<BU5,CB5<CC5,CC5>CD5,CB5>0,CE5<CF5,CE5<50,CF5>=50),"11. Extra Weak Dn",IF(AND(BC5<BU5,CB5<CC5,CC5<CD5,CE5<CF5,CE5>=50,CF5>=50),"12. Very Weak Dn - D",IF(AND(BC5<BU5,CB5<CC5,CC5<CD5,CE5=CF5,CE5>=50,CF5>=50),"12. Very Weak Dn - F",IF(AND(BC5<BU5,CB5<CC5,CC5<CD5,CE5>CF5,CE5>=50,CF5>=50),"12. Very Weak Dn - R","No Trend")))))))))))))))))))))))))))))))))))))))))))))))))))))))))) -> 1. Ultimate Up - R | AG5: =IF(BQ5>BR5,1,0) -> 1 | AH5: =DH5 -> 0 | AK5: =IF(AI5="","",IF(AI5>0,(C5-AI5),IF(AI5<0,(-AI5-C5),"Check"))) | AL5: =IF(AI5="","",(AY5-AX5)) | AM5: =IF(AI5<>"",AL5/AO5,"") | AO5: =IF(AI5<>"",(BF5*AH5),"") | AP5: =(C5*AH5*BE5) -> 0 | AQ5: =IF(AI5="","",(AP5*'Base Data'!$C$26*2)) | AR5: =IF(AI5="","",(AP5*'Base Data'!$D$26*2)) | AS5: =IF(AI5="","",((AQ5+AR5)*'Base Data'!$E$26)+(((AQ5+AR5)*'Base Data'!$E$26)*'Base Data'!$F$26)+(((AQ5+AR5)*'Base Data'!$E$26)*'Base Data'!$G$26)) | AT5: =IF(AI5="","",(AP5*'Base Data'!$H$27*2)) | AU5: =IF(AI5="","",(AP5*'Base Data'!$I$26*2)) | AV5: =IF(AI5="","",(AP5*'Base Data'!$J$26)) | AW5: =IF(AI5="","",(AP5*'Base Data'!$K$26*2)) | AX5: =IF(AI5="","",SUM(AQ5:AW5)) | AY5: =IF(AI5="","",IF(AI5>0,((C5-AI5)*AH5*BE5),IF(AI5<0,((-AI5-C5)*AH5*BE5),"Check"))) | AZ5: =IF(AI5="","",IF(AI5>0,1,IF(AI5<0,2,0))) | BA5: =CONCATENATE(B5,'Base Data'!$D$1) -> BankNifty18NovFut | BB5: =VLOOKUP(BA5,[2]Sheet1!$A:$D,2,FALSE) -> 25845 | BC5: =VLOOKUP(BA5,[2]Sheet1!$A:$D,3,FALSE) -> 25845.55 | BD5: =VLOOKUP(BA5,[2]Sheet1!$A:$D,4,FALSE) -> 25848 | BE5: =VLOOKUP(B5,'[3]Margin - NSE Fut (5Paisa)'!$A:$K,2,FALSE) -> 20 | BF5: =VLOOKUP(B5,'[3]Margin - NSE Fut (5Paisa)'!$A:$K,11,FALSE) -> 49806.74 | BG5: =VLOOKUP(BA5,[2]Sheet1!$A:$L,9,FALSE) -> 25730 | BH5: =VLOOKUP(BA5,[2]Sheet1!$A:$L,10,FALSE) -> 25880 | BI5: =VLOOKUP(BA5,[2]Sheet1!$A:$L,11,FALSE) -> 25630.1 | BJ5: ='BNF-Nifty'!$N$67 -> 23389.5 | BK5: ='BNF-Nifty'!$O$67 -> 23399 | BL5: ='BNF-Nifty'!$P$67 -> 23280 | BM5: ='BNF-Nifty'!$Q$67 -> 23341.75 | BN5: =(BG5-BM5) -> 2388.25 | BO5: =(BG5-BM5)/BM5 -> 0.10231666 | BP5: ='BNF-Nifty'!$AB$69 -> 1.0780018 | BQ5: ='BNF-Nifty'!$R$69 -> 107918 | BR5: ='BNF-Nifty'!$R$73 -> 68980.952 | BS5: ='BNF-Nifty'!$AS$69 -> 0.2098598 | BT5: ='BNF-Nifty'!$AS$73 -> 0.19464595 | BU5: ='BNF-Nifty'!$AY$69 -> 22205.745 | BV5: ='BNF-Nifty'!$BD$69 -> 23545.59 | BW5: ='BNF-Nifty'!$BD$67 -> 22960.067 | BX5: ='BNF-Nifty'!$BI$69 -> 24422.162 | BY5: ='BNF-Nifty'!$BI$67 -> 23213.905 | BZ5: =IF(BX5="","",(BC5-BX5)/BX5) -> 0.05828263 | CA5: =IF(BY5="","",(BM5-BY5)/BY5) -> 0.0055072442 | CB5: ='BNF-Nifty'!$CP$69 -> 227.94465 | CC5: ='BNF-Nifty'!$CP$67 -> 4.7441657 | CD5: ='BNF-Nifty'!$CP$66 -> 1.4390278 | CE5: ='BNF-Nifty'!$DF$69 -> 72.348014 | CF5: ='BNF-Nifty'!$DF$67 -> 64.697314 | CG5: ='BNF-Nifty'!$DF$66 -> 60.944039 | CH5: ='BNF-Nifty'!$DD$73 -> 84 | CI5: ='BNF-Nifty'!$DG$73 -> 48 | CJ5: ='BNF-Nifty'!$DG$69 -> 69.790174 | CK5: ='BNF-Nifty'!$DG$67 -> 69.839329 | CL5: ='BNF-Nifty'!$DG$66 -> 70.011303 | CM5: ='BNF-Nifty'!$DH$69 -> 72.568943 | CN5: ='BNF-Nifty'!$DH$67 -> 72.696507 | CO5: =IF(AND(BC5>BU5,CG5<CL5,CF5>CK5,CE5>CJ5,CE5>CF5,CJ5>CK5),"M34-1",IF(AND(BC5<BU5,CG5>CL5,CF5<CK5,CE5<CJ5,CE5<CF5,CJ5<CK5),"M34-2",0)) -> 0 | CP5: =IF(AI5="",0,IF(AND(AJ5="M34-1",CF5>CN5,CE5<CM5),"Exit-Long",IF(AND(AJ5="M34-2",CF5<CN5,CE5>CM5),"Exit-Short","Hold"))) -> 0 | CQ5: ='BNF-Nifty'!$BW$69 -> 22654.619 | CR5: ='BNF-Nifty'!$BW$67 -> 22490.244 | CS5: ='BNF-Nifty'!$BX$69 -> 23134.929 | CT5: ='BNF-Nifty'!$BX$67 -> 22813.486 | CU5: ='BNF-Nifty'!$BY$69 -> 23424.381 | CV5: ='BNF-Nifty'!$BY$67 -> 23101.251 | CW5: ='BNF-Nifty'!$BT$69 -> 23236.289 | CX5: ='BNF-Nifty'!$BT$67 -> 22912.98 | CY5: ='BNF-Nifty'!$BU$69 -> 23966.107 | CZ5: ='BNF-Nifty'!$BU$67 -> 23155.23 | DA5: ='BNF-Nifty'!$BV$69 -> 24158.939 | DB5: ='BNF-Nifty'!$BV$67 -> 23348.441 | DC5: =IF(AND(BC5>BU5,BM5<CR5,BC5>CQ5,BC5>BM5),"P34-1",IF(AND(BC5<BU5,BM5>CR5,BC5<CQ5,BC5<BM5),"P34-2",IF(AND(BC5>BU5,BM5<CX5,BC5>CW5,BC5>BM5),"P13-1",IF(AND(BC5<BU5,BM5>CX5,BC5<CW5,BC5<BM5),"P13-2",0)))) -> 0 | DD5: =IF(AI5="",0,IF(OR(AND(AJ5="P34-1",BM5>CT5,BC5<CS5),AND(AJ5="P13-1",BM5>CZ5,BC5<CY5)),"Exit-Long",IF(OR(AND(AJ5="P34-2",BM5<CV5,BC5>CU5),AND(AJ5="P13-2",BM5<DB5,BC5>DA5)),"Exit-Short","Hold"))) -> 0 | DE5: =IF(AND(BC5>BU5,CG5<CL5,CF5>CK5,CE5>CJ5,CE5>CF5,CJ5>CK5),"M34-1",IF(AND(BC5<BU5,CG5>CL5,CF5<CK5,CE5<CJ5,CE5<CF5,CJ5<CK5),"M34-2",IF(AND(BC5>BU5,BM5<CR5,BC5>CQ5,BC5>BM5),"P34-1",IF(AND(BC5<BU5,BM5>CR5,BC5<CQ5,BC5<BM5),"P34-2",IF(AND(BC5>BU5,BM5<CX5,BC5>CW5,BC5>BM5),"P13-1",IF(AND(BC5<BU5,BM5>CX5,BC5<CW5,BC5<BM5),"P13-2",0)))))) -> 0 | DF5: =IF(AI5="",0,IF(OR(AND(AJ5="M34-1",CF5>CK5,CE5<CJ5),AND(AJ5="P34-1",BM5>CT5,BC5<CS5),AND(AJ5="P13-1",BM5>CZ5,BC5<CY5)),"Exit-Long",IF(OR(AND(AJ5="M34-2",CF5<CK5,CE5>CJ5),AND(AJ5="P34-2",BM5<CV5,BC5>CU5),AND(AJ5="P13-2",BM5<DB5,BC5>DA5)),"Exit-Short","Hold"))) -> 0 | DG5: ='BNF-Nifty'!$DV$69 -> 580.71406 | DH5: ='BNF-Nifty'!$DY$69 -> 0 | DI5: =IF(AI5="","-",'Base Data'!$D$10*DG5) -> - | DJ5: =IF(DK5="-","-",IF(AI5>0,(DK5-AI5),IF(AI5<0,(DK5+AI5),"Check"))) -> - | DK5: =IF(AI5="","-",IF(AI5>0,(AI5-DI5),IF(AI5<0,(-AI5+DI5),"Check"))) -> - | DL5: =IF(AI5="","-",IF(AI5>0,(AI5+(1*'Base Data'!$D$12*DG5)),IF(AI5<0,(-AI5-(1*'Base Data'!$D$12*DG5)),"Check"))) -> - | DM5: =IF(AI5="","-",IF(AI5>0,(AI5+(2*'Base Data'!$D$12*DG5)),IF(AI5<0,(-AI5-(2*'Base Data'!$D$12*DG5)),"Check"))) -> - | DN5: =IF(AI5="","-",IF(AI5>0,(AI5+(3*'Base Data'!$D$12*DG5)),IF(AI5<0,(-AI5-(3*'Base Data'!$D$12*DG5)),"Check"))) -> - | DO5: =IF(AI5="","-",IF(AI5>0,(AI5+(4*'Base Data'!$D$12*DG5)),IF(AI5<0,(-AI5-(4*'Base Data'!$D$12*DG5)),"Check"))) -> - | DP5: =IF(AI5="","-",IF(AI5>0,(AI5+DI5),IF(AI5<0,(-AI5-DI5),"Check"))) -> - | DQ5: =IF(DP5="-","-",IF(AI5>0,(DP5-AI5),IF(AI5<0,(DP5+AI5),"Check"))) -> - | DR5: ='BNF-Nifty'!$EN$69 -> 988.85749 | DS5: ='BNF-Nifty'!$EQ$69 -> 0 | DT5: =IF(AI5="","-",'Base Data'!$D$13*DR5) -> - | DU5: =IF(DV5="-","-",IF(AI5>0,(DV5-AI5),IF(AI5<0,(DV5+AI5),"Check"))) -> - | DV5: =IF(AI5="","-",IF(AI5>0,(AI5-DT5),IF(AI5<0,(-AI5+DT5),"Check"))) -> - | DW5: =IF(AI5="","-",IF(AI5>0,(AI5+DT5),IF(AI5<0,(-AI5-DT5),"Check"))) -> - | DX5: =IF(DW5="-","-",IF(AI5>0,(DW5-AI5),IF(AI5<0,(DW5+AI5),"Check"))) -> - | EE5: =IF(AI5="","",IF(AL5>0,AL5,0)) | EF5: =IF(AI5="","",IF(AL5<=0,AL5,0)) | EG5: =IF(AI5="","",IF(AI5>0,(BF5*AH5),0)) | EH5: =IF(AI5="","",IF(AI5<=0,(BF5*AH5),0)) | EI5: =IF(AI5="","",IF(AI5>0,(BF5*S5),0)) | EJ5: =IF(AI5="","",IF(AI5<=0,(BF5*S5),0)) | EK5: =IF(AI5="","",IF(AL5>0,1,0)) | EL5: =IF(AI5="","",IF(AL5<=0,1,0)) | EM5: =IF(AND(EN5=1,OR(AND(ER5>=0.5%,ER5<=1.5%),AND(ER5<=-0.5%,ER5>=-1.5%)),ES5>=0.5%),CONCATENATE("Long ",B5),IF(AND(EN5=2,OR(AND(ER5>=0.5%,ER5<=1.5%),AND(ER5<=-0.5%,ER5>=-1.5%)),ES5>=0.5%),CONCATENATE("Short ",B5),"Do Not Trade")) -> Do Not Trade | EN5: =IF(OR(EO5="",EP5=""),"",IF(BC5>=(EO5+'Base Data'!$D$14),1,IF(BC5<=(EP5-'Base Data'!$D$14),2,0))) -> 0 | EO5: =BH5 -> 25880 | EP5: =BI5 -> 25630.1 | EQ5: =IF(AI5="","",IF(AI5>0,IF(BC5<EP5,"Exit Long & Go Short",IF(BC5>(AI5+(EO5-EP5)),"Exit - TP","Hold")),IF(AI5<0,IF(BC5>EO5,"Exit Short & Go Long",IF(BC5<(-AI5-(EO5-EP5)),"Exit - TP","Hold"))))) | ER5: =(BC5-BM5)/BM5 -> 0.10726702 | ES5: =IF(OR(EO5<>"",EP5<>""),(EO5-EP5)/BG5,(BH5-BI5)/BG5) -> 0.009712398 | ET5: =IF(AND(EU5="",EV5="",EW5="",EX5=""),"",IF(AND(EU5<(80%*EX5),EV5<(80%*EX5),EW5<(80%*EX5)),0,IF(AND(EU5>=(80%*EX5),EV5<(80%*EX5),EW5<(80%*EX5)),5,IF(AND(EU5<(80%*EX5),EV5>=(80%*EX5),EW5<(80%*EX5)),10,IF(AND(EU5<(80%*EX5),EV5<(80%*EX5),EW5>=(80%*EX5)),15,IF(AND(EU5>=(80%*EX5),EV5>=(80%*EX5),EW5<(80%*EX5)),20,IF(AND(EU5>=(80%*EX5),EV5<(80%*EX5),EW5>=(80%*EX5)),25,IF(AND(EU5<(80%*EX5),EV5>=(80%*EX5),EW5>=(80%*EX5)),30,IF(AND(EU5>=(80%*EX5),EV5>=(80%*EX5),EW5>=(80%*EX5)),35,"Check"))))))))) -> 35 | EU5: ='BNF-Nifty'!$FH$69 -> 0.011999153 | EV5: ='BNF-Nifty'!$FI$69 -> 0.010656266 | EW5: ='BNF-Nifty'!$FJ$69 -> 0.0097105908 | EX5: ='BNF-Nifty'!$FG$73 -> 0.0095637767 | EY5: =IF(OR(AND(EN5=1,OR(AND(ER5>=0.5%,ER5<=1.5%),AND(ER5<=-0.5%,ER5>=-1.5%)),ES5>=0.5%),AND(EN5=2,OR(AND(ER5>=0.5%,ER5<=1.5%),AND(ER5<=-0.5%,ER5>=-1.5%)),ES5>=0.5%)),1,0) -> 0 | EZ5: =IF(OR(EQ5="Exit Long & Go Short",EQ5="Exit Short & Go Long"),1,0) -> 0
A7: =A5+1 -> 2 | B7: Nifty | C7: =IF(AND(I7=1,BD7<>0),BD7,IF(AND(I7=2,BB7<>0),BB7,BC7)) -> 10619.8 | D7: =(BC7-BG7) -> 18.8 | E7: =(BC7-BM7) -> 967.2 | J7: =IF(AND(BG7>BM7,BG7<=BK7),"PGUp",IF(AND(BG7>BM7,BG7>BK7),"FGUp",IF(AND(BG7<BM7,BG7>=BL7),"PGDn",IF(AND(BG7<BM7,BG7<BL7),"FGDn",0)))) -> FGUp | K7: =IF(BM7>BJ7,IF(BG7>BK7,"U-H",IF(AND(BG7<=BK7,BG7>BM7),"U-HC",IF(AND(BG7<BM7,BG7>=BJ7),"U-CO",IF(AND(BG7<BJ7,BG7>=BL7),"U-OL",IF(BG7<BL7,"U-L",0))))),IF(BM7<BJ7,IF(BG7>BK7,"D-H",IF(AND(BG7<=BK7,BG7>BJ7),"D-HO",IF(AND(BG7<=BJ7,BG7>BM7),"D-OC",IF(AND(BG7<BM7,BG7>=BL7),"D-CL",IF(BG7<BL7,"D-L",0))))),0)) -> D-H | L7: =IF(BM7>BJ7,IF(BG7>BK7,"Fade-Short",IF(AND(BG7<=BK7,BG7>BM7),"Fade-Short",IF(AND(BG7<BM7,BG7>=BJ7),"Fade-Long",IF(AND(BG7<BJ7,BG7>=BL7),"Fade-Long",IF(BG7<BL7,"GA-Short",0))))),IF(BM7<BJ7,IF(BG7>BK7,"GA-Long",IF(AND(BG7<=BK7,BG7>BJ7),"Fade-Short",IF(AND(BG7<=BJ7,BG7>BM7),"Fade-Short",IF(AND(BG7<BM7,BG7>=BL7),"Fade-Long",IF(BG7<BL7,"Fade-Long",0))))),0)) -> GA-Long | M7: =IF(BG7=BI7,1,IF(BG7=BH7,2,0)) -> 0 | N7: =IF(AND(BG7<BK7,BC7>BK7),"Up-BO",IF(AND(BG7>BL7,BC7<BL7),"Dn-BO",IF(AND(J7="FGDn",BC7>BL7),"Dn2Up-BO",IF(AND(J7="FGUp",BC7<BK7),"Up2Dn-BO",0)))) -> 0 | O7: =IF(AND((IF(BV7>BW7,1,-1)>0),(IF(CB7>CC7,1,-1)>0)),1,IF(AND((IF(BV7>BW7,1,-1)<0),(IF(CB7>CC7,1,-1)<0)),2,0)) -> 1 | P7: =IF(BC7>(BH7-(BG7*0.5%)),1,IF(BC7<(BI7+(BG7*0.5%)),2,0)) -> 1 | Q7: =IF(C7>((BG7+BK7+BL7+BM7)/4),1,IF(C7<((BG7+BK7+BL7+BM7)/4),2,0)) -> 1 | R7: =IF((BS7>BT7),1,0) -> 1 | S7: =DS7 -> 0 | T7: ='BNF-Nifty'!$FE$69 -> 3.4614677 | U7: =IF(S7<>0,T7,"-") -> - | V7: =IF(U7="-","-",_xlfn.RANK.EQ(U7,$U$5:$U$12,0)) -> - | W7: =IF(U7="-","-",_xlfn.RANK.EQ(U7,$U$5:$U$12,1)) -> - | X7: ='BNF-Nifty'!$FU$69 -> T-R | Y7: ='BNF-Nifty'!$FQ$69 -> 2 | Z7: ='BNF-Nifty'!$EI$69 -> 0.015880955 | AA7: ='BNF-Nifty'!$FA$69 -> 0.028731564 | AB7: ='BNF-Nifty'!$FD$69 -> 6.794639 | AC7: =_xlfn.RANK.AVG(AB7,$AB$5:$AB$12,0) -> 1 | AD7: =_xlfn.RANK.AVG(AB7,$AB$5:$AB$12,1) -> 4 | AE7: =IF(AND(BC7>BU7,BC7>BV7,BZ7>=CA7,BX7>BY7),"1. Strong Up-R",IF(AND(BC7>BU7,BC7>BV7,BZ7>=CA7,BX7=BY7),"1. Strong Up-F",IF(AND(BC7>BU7,BC7>BV7,BZ7>=CA7,BX7<BY7),"1. Strong Up-D",IF(AND(BC7>BU7,BC7>BV7,BZ7<CA7,BX7>BY7),"2. Weak Up-R",IF(AND(BC7>BU7,BC7>BV7,BZ7<CA7,BX7=BY7),"2. Weak Up-F",IF(AND(BC7>BU7,BC7>BV7,BZ7<CA7,BX7<BY7),"2. Weak Up-D",IF(AND(BC7<BU7,BC7<BV7,BZ7<=CA7,BX7<BY7),"1. Strong Dn-D",IF(AND(BC7<BU7,BC7<BV7,BZ7<=CA7,BX7=BY7),"1. Strong Dn-F",IF(AND(BC7<BU7,BC7<BV7,BZ7<=CA7,BX7>BY7),"1. Strong Dn-R",IF(AND(BC7<BU7,BC7<BV7,BZ7>CA7,BX7<BY7),"2. Weak Dn-D",IF(AND(BC7<BU7,BC7<BV7,BZ7>CA7,BX7=BY7),"2. Weak Dn-F",IF(AND(BC7<BU7,BC7<BV7,BZ7>CA7,BX7>BY7),"2. Weak Dn-R","-")))))))))))) -> 1. Strong Up-R | AF7: =IF(CE7>CH7,"MFI Nr. Max. Level",IF(CE7<CI7,"MFI Nr. Min. Level",IF(AND(BC7>BU7,CB7>CC7,CC7>CD7,CB7>=0,CE7>CJ7,CE7>CF7,CE7>=50,CF7>=50),"1. Ultimate Up - R",IF(AND(BC7>BU7,CB7>CC7,CC7>CD7,CB7>=0,CE7>CJ7,CE7=CF7,CE7>=50,CF7>=50),"1. Ultimate Up - F",IF(AND(BC7>BU7,CB7>CC7,CC7>CD7,CB7>=0,CE7>CJ7,CE7<CF7,CE7>=50,CF7>=50),"1. Ultimate Up - D",IF(AND(BC7>BU7,CB7>CC7,CC7>CD7,CB7<0,CE7>CJ7,CE7>CF7,CE7>=50,CF7>=50),"2. Extreme Up - R",IF(AND(BC7>BU7,CB7>CC7,CC7>CD7,CB7<0,CE7>CJ7,CE7=CF7,CE7>=50,CF7>=50),"2. Extreme Up - F",IF(AND(BC7>BU7,CB7>CC7,CC7>CD7,CB7<0,CE7>CJ7,CE7<CF7,CE7>=50,CF7>=50),"2. Extreme Up - D",IF(AND(BC7>BU7,CB7>CC7,CC7>CD7,CB7>=0,CE7>CJ7,CE7>CF7,CE7>=50,CF7<50),"3. Uber Up",IF(AND(BC7>BU7,CB7>CC7,CC7>CD7,CB7<0,CE7>CJ7,CE7>CF7,CE7>=50,CF7<50),"4. Ultra Up",IF(AND(BC7>BU7,CB7>CC7,CC7>CD7,CB7>=0,CE7>CJ7,CE7>CF7,CE7<50),"5. Hyper Up - R",IF(AND(BC7>BU7,CB7>CC7,CC7>CD7,CB7>=0,CE7>CJ7,CE7=CF7,CE7<50),"5. Hyper Up - F",IF(AND(BC7>BU7,CB7>CC7,CC7>CD7,CB7>=0,CE7>CJ7,CE7<CF7,CE7<50),"5. Hyper Up - D",IF(AND(BC7>BU7,CB7>CC7,CC7>CD7,CB7<0,CE7>CJ7,CE7>CF7,CE7<50),"6. Super Up - R",IF(AND(BC7>BU7,CB7>CC7,CC7>CD7,CB7<0,CE7>CJ7,CE7=CF7,CE7<50),"6. Super Up - F",IF(AND(BC7>BU7,CB7>CC7,CC7>CD7,CB7<0,CE7>CJ7,CE7<CF7,CE7<50),"6. Super Up - D",IF(AND(BC7>BU7,CB7>CC7,CC7<CD7,CB7>=0,CE7>CF7,CE7>=50,CF7>=50),"7. Extra Strong Up - R",IF(AND(BC7>BU7,CB7>CC7,CC7<CD7,CB7>=0,CE7=CF7,CE7>=50,CF7>=50),"7. Extra Strong Up - F",IF(AND(BC7>BU7,CB7>CC7,CC7<CD7,CB7>=0,CE7<CF7,CE7>=50,CF7>=50),"7. Extra Strong Up - D",IF(AND(BC7>BU7,CB7>CC7,CC7<CD7,CB7>=0,CE7>CF7,CE7>=50,CF7<50),"8. Strong Up",IF(AND(BC7>BU7,CB7>CC7,CC7<CD7,CB7<0,CE7>CJ7,CE7>CF7,CE7>=50,CF7>=50),"9. Up - R",IF(AND(BC7>BU7,CB7>CC7,CC7<CD7,CB7<0,CE7>CJ7,CE7=CF7,CE7>=50,CF7>=50),"9. Up - F",IF(AND(BC7>BU7,CB7>CC7,CC7<CD7,CB7<0,CE7>CJ7,CE7<CF7,CE7>=50,CF7>=50),"9. Up - D",IF(AND(BC7>BU7,CB7>CC7,CC7<CD7,CB7<0,CE7>CF7,CE7>=50,CF7>=50),"10. Weak Up - R",IF(AND(BC7>BU7,CB7>CC7,CC7<CD7,CB7<0,CE7=CF7,CE7>=50,CF7>=50),"10. Weak Up - F",IF(AND(BC7>BU7,CB7>CC7,CC7<CD7,CB7<0,CE7<CF7,CE7>=50,CF7>=50),"10. Weak Up - D",IF(AND(BC7>BU7,CB7>CC7,CC7<CD7,CB7<0,CE7>CF7,CE7>=50,CF7<50),"11. Extra Weak Up",IF(AND(BC7>BU7,CB7>CC7,CC7>CD7,CE7>CF7,CE7<50,CF7<50),"12. Very Weak Up - R",IF(AND(BC7>BU7,CB7>CC7,CC7>CD7,CE7=CF7,CE7<50,CF7<50),"12. Very Weak Up - F",IF(AND(BC7>BU7,CB7>CC7,CC7>CD7,CE7<CF7,CE7<50,CF7<50),"12. Very Weak Up - D",IF(AND(BC7<BU7,CB7<CC7,CC7<CD7,CB7<=0,CE7<CJ7,CE7<CF7,CE7<50,CF7<50),"1. Ultimate Dn - D",IF(AND(BC7<BU7,CB7<CC7,CC7<CD7,CB7<=0,CE7<CJ7,CE7=CF7,CE7<50,CF7<50),"1. Ultimate Dn - F",IF(AND(BC7<BU7,CB7<CC7,CC7<CD7,CB7<=0,CE7<CJ7,CE7>CF7,CE7<50,CF7<50),"1. Ultimate Up - R",IF(AND(BC7<BU7,CB7<CC7,CC7<CD7,CB7>0,CE7<CJ7,CE7<CF7,CE7<50,CF7<50),"2. Extreme Dn - D",IF(AND(BC7<BU7,CB7<CC7,CC7<CD7,CB7>0,CE7<CJ7,CE7=CF7,CE7<50,CF7<50),"2. Extreme Dn - F",IF(AND(BC7<BU7,CB7<CC7,CC7<CD7,CB7>0,CE7<CJ7,CE7>CF7,CE7<50,CF7<50),"2. Extreme Dn - R",IF(AND(BC7<BU7,CB7<CC7,CC7<CD7,CB7<=0,CE7<CJ7,CE7<CF7,CE7<50,CF7>=50),"3. Uber Dn",IF(AND(BC7<BU7,CB7<CC7,CC7<CD7,CB7>0,CE7<CJ7,CE7<CF7,CE7<50,CF7>=50),"4. Ultra Dn",IF(AND(BC7<BU7,CB7<CC7,CC7<CD7,CB7<=0,CE7<CJ7,CE7<CF7,CE7>=50),"5. Hyper Dn - D",IF(AND(BC7<BU7,CB7<CC7,CC7<CD7,CB7<=0,CE7<CJ7,CE7=CF7,CE7>=50),"5. Hyper Dn - F",IF(AND(BC7<BU7,CB7<CC7,CC7<CD7,CB7<=0,CE7<CJ7,CE7>CF7,CE7>=50),"5. Hyper Dn - R",IF(AND(BC7<BU7,CB7<CC7,CC7<CD7,CB7>0,CE7<CJ7,CE7<CF7,CE7>=50),"6. Super Dn - D",IF(AND(BC7<BU7,CB7<CC7,CC7<CD7,CB7>0,CE7<CJ7,CE7=CF7,CE7>=50),"6. Super Dn - F",IF(AND(BC7<BU7,CB7<CC7,CC7<CD7,CB7>0,CE7<CJ7,CE7>CF7,CE7>=50),"6. Super Dn - R",IF(AND(BC7<BU7,CB7<CC7,CC7>CD7,CB7<=0,CE7<CF7,CE7<50,CF7<50),"7. Extra Strong Dn - D",IF(AND(BC7<BU7,CB7<CC7,CC7>CD7,CB7<=0,CE7=CF7,CE7<50,CF7<50),"7. Extra Strong Dn - F",IF(AND(BC7<BU7,CB7<CC7,CC7>CD7,CB7<=0,CE7>CF7,CE7<50,CF7<50),"7. Extra Strong Dn - R",IF(AND(BC7<BU7,CB7<CC7,CC7>CD7,CB7<=0,CE7<CF7,CE7<50,CF7>=50),"8. Strong Dn",IF(AND(BC7<BU7,CB7<CC7,CC7>CD7,CB7>0,CE7<CJ7,CE7<CF7,CE7<50,CF7<50),"9. Dn - D",IF(AND(BC7<BU7,CB7<CC7,CC7>CD7,CB7>0,CE7<CJ7,CE7=CF7,CE7<50,CF7<50),"9. Dn - F",IF(AND(BC7<BU7,CB7<CC7,CC7>CD7,CB7>0,CE7<CJ7,CE7>CF7,CE7<50,CF7<50),"9. Dn - R",IF(AND(BC7<BU7,CB7<CC7,CC7>CD7,CB7>0,CE7<CF7,CE7<50,CF7<50),"10. Weak Dn - D",IF(AND(BC7<BU7,CB7<CC7,CC7>CD7,CB7>0,CE7=CF7,CE7<50,CF7<50),"10. Weak Dn - F",IF(AND(BC7<BU7,CB7<CC7,CC7>CD7,CB7>0,CE7>CF7,CE7<50,CF7<50),"10. Weak Dn - R",IF(AND(BC7<BU7,CB7<CC7,CC7>CD7,CB7>0,CE7<CF7,CE7<50,CF7>=50),"11. Extra Weak Dn",IF(AND(BC7<BU7,CB7<CC7,CC7<CD7,CE7<CF7,CE7>=50,CF7>=50),"12. Very Weak Dn - D",IF(AND(BC7<BU7,CB7<CC7,CC7<CD7,CE7=CF7,CE7>=50,CF7>=50),"12. Very Weak Dn - F",IF(AND(BC7<BU7,CB7<CC7,CC7<CD7,CE7>CF7,CE7>=50,CF7>=50),"12. Very Weak Dn - R","No Trend")))))))))))))))))))))))))))))))))))))))))))))))))))))))))) -> 1. Ultimate Up - R | AG7: =IF(BQ7>BR7,1,0) -> 1 | AH7: =DH7 -> 0 | AK7: =IF(AI7="","",IF(AI7>0,(C7-AI7),IF(AI7<0,(-AI7-C7),"Check"))) | AL7: =IF(AI7="","",(AY7-AX7)) | AM7: =IF(AI7<>"",AL7/AO7,"") | AO7: =IF(AI7<>"",(BF7*AH7),"") | AP7: =(C7*AH7*BE7) -> 0 | AQ7: =IF(AI7="","",(AP7*'Base Data'!$C$26*2)) | AR7: =IF(AI7="","",(AP7*'Base Data'!$D$26*2)) | AS7: =IF(AI7="","",((AQ7+AR7)*'Base Data'!$E$26)+(((AQ7+AR7)*'Base Data'!$E$26)*'Base Data'!$F$26)+(((AQ7+AR7)*'Base Data'!$E$26)*'Base Data'!$G$26)) | AT7: =IF(AI7="","",(AP7*'Base Data'!$H$27*2)) | AU7: =IF(AI7="","",(AP7*'Base Data'!$I$26*2)) | AV7: =IF(AI7="","",(AP7*'Base Data'!$J$26)) | AW7: =IF(AI7="","",(AP7*'Base Data'!$K$26*2)) | AX7: =IF(AI7="","",SUM(AQ7:AW7)) | AY7: =IF(AI7="","",IF(AI7>0,((C7-AI7)*AH7*BE7),IF(AI7<0,((-AI7-C7)*AH7*BE7),"Check"))) | AZ7: =IF(AI7="","",IF(AI7>0,1,IF(AI7<0,2,0))) | BA7: =CONCATENATE(B7,'Base Data'!$D$1) -> Nifty18NovFut | BB7: =VLOOKUP(BA7,[2]Sheet1!$A:$D,2,FALSE) -> 10618 | BC7: =VLOOKUP(BA7,[2]Sheet1!$A:$D,3,FALSE) -> 10619.8 | BD7: =VLOOKUP(BA7,[2]Sheet1!$A:$D,4,FALSE) -> 10619.8 | BE7: =VLOOKUP(B7,'[3]Margin - NSE Fut (5Paisa)'!$A:$K,2,FALSE) -> 75 | BF7: =VLOOKUP(B7,'[3]Margin - NSE Fut (5Paisa)'!$A:$K,11,FALSE) -> 76212.887 | BG7: =VLOOKUP(BA7,[2]Sheet1!$A:$L,9,FALSE) -> 10601 | BH7: =VLOOKUP(BA7,[2]Sheet1!$A:$L,10,FALSE) -> 10643.95 | BI7: =VLOOKUP(BA7,[2]Sheet1!$A:$L,11,FALSE) -> 10571.1 | BJ7: ='BNF-Nifty'!$T$67 -> 9660.15 | BK7: ='BNF-Nifty'!$U$67 -> 9672 | BL7: ='BNF-Nifty'!$V$67 -> 9643.2 | BM7: ='BNF-Nifty'!$W$67 -> 9652.6 | BN7: =(BG7-BM7) -> 948.4 | BO7: =(BG7-BM7)/BM7 -> 0.09825332 | BP7: ='BNF-Nifty'!$AC$69 -> 1 | BQ7: ='BNF-Nifty'!$X$69 -> 120113 | BR7: ='BNF-Nifty'!$X$73 -> 110474.9 | BS7: ='BNF-Nifty'!$AW$69 -> 0.1421066 | BT7: ='BNF-Nifty'!$AW$73 -> 0.13531035 | BU7: ='BNF-Nifty'!$BA$69 -> 9322.5794 | BV7: ='BNF-Nifty'!$BL$69 -> 9673.2394 | BW7: ='BNF-Nifty'!$BL$67 -> 9503.0505 | BX7: ='BNF-Nifty'!$BQ$69 -> 9996.6574 | BY7: ='BNF-Nifty'!$BQ$67 -> 9592.903 | BZ7: =IF(BX7="","",(BC7-BX7)/BX7) -> 0.0623351 | CA7: =IF(BY7="","",(BM7-BY7)/BY7) -> 0.0062230414 | CB7: ='BNF-Nifty'!$CY$69 -> 79.196764 | CC7: ='BNF-Nifty'!$CY$67 -> 9.0270957 | CD7: ='BNF-Nifty'!$CY$66 -> 6.7447966 | CE7: ='BNF-Nifty'!$DO$69 -> 69.940468 | CF7: ='BNF-Nifty'!$DO$67 -> 64.29137 | CG7: ='BNF-Nifty'!$DO$66 -> 60.69472 | CH7: ='BNF-Nifty'!$DM$73 -> 77 | CI7: ='BNF-Nifty'!$DP$73 -> 31 | CJ7: ='BNF-Nifty'!$DP$69 -> 57.031464 | CK7: ='BNF-Nifty'!$DP$67 -> 56.281433 | CL7: ='BNF-Nifty'!$DP$66 -> 55.852217 | CM7: ='BNF-Nifty'!$DQ$69 -> 59.912579 | CN7: ='BNF-Nifty'!$DQ$67 -> 59.708349 | CO7: =IF(AND(BC7>BU7,CG7<CL7,CF7>CK7,CE7>CJ7,CE7>CF7,CJ7>CK7),"M34-1",IF(AND(BC7<BU7,CG7>CL7,CF7<CK7,CE7<CJ7,CE7<CF7,CJ7<CK7),"M34-2",0)) -> 0 | CP7: =IF(AI7="",0,IF(AND(AJ7="M34-1",CF7>CN7,CE7<CM7),"Exit-Long",IF(AND(AJ7="M34-2",CF7<CN7,CE7>CM7),"Exit-Short","Hold"))) -> 0 | CQ7: ='BNF-Nifty'!$CE$69 -> 9416.3593 | CR7: ='BNF-Nifty'!$CE$67 -> 9373.7556 | CS7: ='BNF-Nifty'!$CF$69 -> 9541.0905 | CT7: ='BNF-Nifty'!$CF$67 -> 9458.3208 | CU7: ='BNF-Nifty'!$CG$69 -> 9624.6759 | CV7: ='BNF-Nifty'!$CG$67 -> 9542.1021 | CW7: ='BNF-Nifty'!$CB$69 -> 9575.9034 | CX7: ='BNF-Nifty'!$CB$67 -> 9491.4507 | CY7: ='BNF-Nifty'!$CC$69 -> 9872.9021 | CZ7: ='BNF-Nifty'!$CC$67 -> 9586.8301 | DA7: ='BNF-Nifty'!$CD$69 -> 9922.475 | DB7: ='BNF-Nifty'!$CD$67 -> 9645.0047 | DC7: =IF(AND(BC7>BU7,BM7<CR7,BC7>CQ7,BC7>BM7),"P34-1",IF(AND(BC7<BU7,BM7>CR7,BC7<CQ7,BC7<BM7),"P34-2",IF(AND(BC7>BU7,BM7<CX7,BC7>CW7,BC7>BM7),"P13-1",IF(AND(BC7<BU7,BM7>CX7,BC7<CW7,BC7<BM7),"P13-2",0)))) -> 0 | DD7: =IF(AI7="",0,IF(OR(AND(AJ7="P34-1",BM7>CT7,BC7<CS7),AND(AJ7="P13-1",BM7>CZ7,BC7<CY7)),"Exit-Long",IF(OR(AND(AJ7="P34-2",BM7<CV7,BC7>CU7),AND(AJ7="P13-2",BM7<DB7,BC7>DA7)),"Exit-Short","Hold"))) -> 0 | DE7: =IF(AND(BC7>BU7,CG7<CL7,CF7>CK7,CE7>CJ7,CE7>CF7,CJ7>CK7),"M34-1",IF(AND(BC7<BU7,CG7>CL7,CF7<CK7,CE7<CJ7,CE7<CF7,CJ7<CK7),"M34-2",IF(AND(BC7>BU7,BM7<CR7,BC7>CQ7,BC7>BM7),"P34-1",IF(AND(BC7<BU7,BM7>CR7,BC7<CQ7,BC7<BM7),"P34-2",IF(AND(BC7>BU7,BM7<CX7,BC7>CW7,BC7>BM7),"P13-1",IF(AND(BC7<BU7,BM7>CX7,BC7<CW7,BC7<BM7),"P13-2",0)))))) -> 0 | DF7: =IF(AI7="",0,IF(OR(AND(AJ7="M34-1",CF7>CK7,CE7<CJ7),AND(AJ7="P34-1",BM7>CT7,BC7<CS7),AND(AJ7="P13-1",BM7>CZ7,BC7<CY7)),"Exit-Long",IF(OR(AND(AJ7="M34-2",CF7<CK7,CE7>CJ7),AND(AJ7="P34-2",BM7<CV7,BC7>CU7),AND(AJ7="P13-2",BM7<DB7,BC7>DA7)),"Exit-Short","Hold"))) -> 0 | DG7: ='BNF-Nifty'!$EE$69 -> 168.65257 | DH7: ='BNF-Nifty'!$EH$69 -> 0 | DI7: =IF(AI7="","-",'Base Data'!$D$10*DG7) -> - | DJ7: =IF(DK7="-","-",IF(AI7>0,(DK7-AI7),IF(AI7<0,(DK7+AI7),"Check"))) -> - | DK7: =IF(AI7="","-",IF(AI7>0,(AI7-DI7),IF(AI7<0,(-AI7+DI7),"Check"))) -> - | DL7: =IF(AI7="","-",IF(AI7>0,(AI7+(1*'Base Data'!$D$12*DG7)),IF(AI7<0,(-AI7-(1*'Base Data'!$D$12*DG7)),"Check"))) -> - | DM7: =IF(AI7="","-",IF(AI7>0,(AI7+(2*'Base Data'!$D$12*DG7)),IF(AI7<0,(-AI7-(2*'Base Data'!$D$12*DG7)),"Check"))) -> - | DN7: =IF(AI7="","-",IF(AI7>0,(AI7+(3*'Base Data'!$D$12*DG7)),IF(AI7<0,(-AI7-(3*'Base Data'!$D$12*DG7)),"Check"))) -> - | DO7: =IF(AI7="","-",IF(AI7>0,(AI7+(4*'Base Data'!$D$12*DG7)),IF(AI7<0,(-AI7-(4*'Base Data'!$D$12*DG7)),"Check"))) -> - | DP7: =IF(AI7="","-",IF(AI7>0,(AI7+DI7),IF(AI7<0,(-AI7-DI7),"Check"))) -> - | DQ7: =IF(DP7="-","-",IF(AI7>0,(DP7-AI7),IF(AI7<0,(DP7+AI7),"Check"))) -> - | DR7: ='BNF-Nifty'!$EW$69 -> 305.12346 | DS7: ='BNF-Nifty'!$EZ$69 -> 0 | DT7: =IF(AI7="","-",'Base Data'!$D$13*DR7) -> - | DU7: =IF(DV7="-","-",IF(AI7>0,(DV7-AI7),IF(AI7<0,(DV7+AI7),"Check"))) -> - | DV7: =IF(AI7="","-",IF(AI7>0,(AI7-DT7),IF(AI7<0,(-AI7+DT7),"Check"))) -> - | DW7: =IF(AI7="","-",IF(AI7>0,(AI7+DT7),IF(AI7<0,(-AI7-DT7),"Check"))) -> - | DX7: =IF(DW7="-","-",IF(AI7>0,(DW7-AI7),IF(AI7<0,(DW7+AI7),"Check"))) -> - | EE7: =IF(AI7="","",IF(AL7>0,AL7,0)) | EF7: =IF(AI7="","",IF(AL7<=0,AL7,0)) | EG7: =IF(AI7="","",IF(AI7>0,(BF7*AH7),0)) | EH7: =IF(AI7="","",IF(AI7<=0,(BF7*AH7),0)) | EI7: =IF(AI7="","",IF(AI7>0,(BF7*S7),0)) | EJ7: =IF(AI7="","",IF(AI7<=0,(BF7*S7),0)) | EK7: =IF(AI7="","",IF(AL7>0,1,0)) | EL7: =IF(AI7="","",IF(AL7<=0,1,0)) | EM7: =IF(AND(EN7=1,OR(AND(ER7>=0.5%,ER7<=1.5%),AND(ER7<=-0.5%,ER7>=-1.5%)),ES7>=0.5%),CONCATENATE("Long ",B7),IF(AND(EN7=2,OR(AND(ER7>=0.5%,ER7<=1.5%),AND(ER7<=-0.5%,ER7>=-1.5%)),ES7>=0.5%),CONCATENATE("Short ",B7),"Do Not Trade")) -> Do Not Trade | EN7: =IF(OR(EO7="",EP7=""),"",IF(BC7>=(EO7+'Base Data'!$D$14),1,IF(BC7<=(EP7-'Base Data'!$D$14),2,0))) -> 0 | EO7: =BH7 -> 10643.95 | EP7: =BI7 -> 10571.1 | EQ7: =IF(AI7="","",IF(AI7>0,IF(BC7<EP7,"Exit Long & Go Short",IF(BC7>(AI7+(EO7-EP7)),"Exit - TP","Hold")),IF(AI7<0,IF(BC7>EO7,"Exit Short & Go Long",IF(BC7<(-AI7-(EO7-EP7)),"Exit - TP","Hold"))))) | ER7: =(BC7-BM7)/BM7 -> 0.10020098 | ES7: =IF(OR(EO7<>"",EP7<>""),(EO7-EP7)/BG7,(BH7-BI7)/BG7) -> 0.0068719932 | ET7: =IF(AND(EU7="",EV7="",EW7="",EX7=""),"",IF(AND(EU7<(80%*EX7),EV7<(80%*EX7),EW7<(80%*EX7)),0,IF(AND(EU7>=(80%*EX7),EV7<(80%*EX7),EW7<(80%*EX7)),5,IF(AND(EU7<(80%*EX7),EV7>=(80%*EX7),EW7<(80%*EX7)),10,IF(AND(EU7<(80%*EX7),EV7<(80%*EX7),EW7>=(80%*EX7)),15,IF(AND(EU7>=(80%*EX7),EV7>=(80%*EX7),EW7<(80%*EX7)),20,IF(AND(EU7>=(80%*EX7),EV7<(80%*EX7),EW7>=(80%*EX7)),25,IF(AND(EU7<(80%*EX7),EV7>=(80%*EX7),EW7>=(80%*EX7)),30,IF(AND(EU7>=(80%*EX7),EV7>=(80%*EX7),EW7>=(80%*EX7)),35,"Check"))))))))) -> 35 | EU7: ='BNF-Nifty'!$FM$69 -> 0.0075649755 | EV7: ='BNF-Nifty'!$FN$69 -> 0.0076803294 | EW7: ='BNF-Nifty'!$FO$69 -> 0.0067478588 | EX7: ='BNF-Nifty'!$FL$73 -> 0.0064854968 | EY7: =IF(OR(AND(EN7=1,OR(AND(ER7>=0.5%,ER7<=1.5%),AND(ER7<=-0.5%,ER7>=-1.5%)),ES7>=0.5%),AND(EN7=2,OR(AND(ER7>=0.5%,ER7<=1.5%),AND(ER7<=-0.5%,ER7>=-1.5%)),ES7>=0.5%)),1,0) -> 0 | EZ7: =IF(OR(EQ7="Exit Long & Go Short",EQ7="Exit Short & Go Long"),1,0) -> 0
A9: =A7+1 -> 3 | B9: AshokLey | C9: =IF(AND(I9=1,BD9<>0),BD9,IF(AND(I9=2,BB9<>0),BB9,BC9)) -> 94.4 | D9: =(BC9-BG9) -> 1.4 | E9: =(BC9-BM9) -> 1 | I9: =IF(OR(J9=0,K9=0),0,IF(AND(M9=1,N9="Up-BO"),IF(OR(AND(J9="PGDn",K9="D-CL"),AND(J9="FGDn",K9="D-L"),AND(J9="PGDn",K9="U-CO"),AND(J9="PGDn",K9="U-OL"),AND(J9="PGUp",K9="U-HC"),AND(J9="PGUp",K9="D-OC"),AND(J9="PGUp",K9="D-HO"),AND(J9="FGDn",K9="U-L")),1,IF(AND(M9=2,N9="Dn-BO"),IF(OR(AND(J9="PGDUp",K9="U-HC"),AND(J9="FGUp",K9="U-H"),AND(J9="PGUp",K9="D-OC"),AND(J9="PGUp",K9="D-HO"),AND(J9="PGDn",K9="D-CL"),AND(J9="PGDn",K9="U-CO"),AND(J9="PGDn",K9="U-OL"),AND(J9="FGUp",K9="D-H")),2,IF(AND(M9=1,N9="Dn2Up-BO"),1,IF(AND(M9=2,N9="Up2Dn-BO"),2,0))),0)),IF(AND(M9=1,N9="Up-BO"),IF(OR(AND(J9="PGDn",K9="D-CL"),AND(J9="FGDn",K9="D-L"),AND(J9="PGDn",K9="U-CO"),AND(J9="PGDn",K9="U-OL"),AND(J9="PGUp",K9="U-HC"),AND(J9="PGUp",K9="D-OC"),AND(J9="PGUp",K9="D-HO"),AND(J9="FGDn",K9="U-L")),1,IF(AND(M9=2,N9="Dn-BO"),IF(OR(AND(J9="PGDUp",K9="U-HC"),AND(J9="FGUp",K9="U-H"),AND(J9="PGUp",K9="D-OC"),AND(J9="PGUp",K9="D-HO"),AND(J9="PGDn",K9="D-CL"),AND(J9="PGDn",K9="U-CO"),AND(J9="PGDn",K9="U-OL"),AND(J9="FGUp",K9="D-H")),2,IF(AND(M9=1,N9="Dn2Up-BO"),1,IF(AND(M9=2,N9="Up2Dn-BO"),2,0))),0)),0))) -> 0 | J9: =IF(AND(BG9>BM9,BG9<=BK9),"PGUp",IF(AND(BG9>BM9,BG9>BK9),"FGUp",IF(AND(BG9<BM9,BG9>=BL9),"PGDn",IF(AND(BG9<BM9,BG9<BL9),"FGDn",0)))) -> PGDn | K9: =IF(BM9>BJ9,IF(BG9>BK9,"U-H",IF(AND(BG9<=BK9,BG9>BM9),"U-HC",IF(AND(BG9<BM9,BG9>=BJ9),"U-CO",IF(AND(BG9<BJ9,BG9>=BL9),"U-OL",IF(BG9<BL9,"U-L",0))))),IF(BM9<BJ9,IF(BG9>BK9,"D-H",IF(AND(BG9<=BK9,BG9>BJ9),"D-HO",IF(AND(BG9<=BJ9,BG9>BM9),"D-OC",IF(AND(BG9<BM9,BG9>=BL9),"D-CL",IF(BG9<BL9,"D-L",0))))),0)) -> U-CO | L9: =IF(BM9>BJ9,IF(BG9>BK9,"Fade-Short",IF(AND(BG9<=BK9,BG9>BM9),"Fade-Short",IF(AND(BG9<BM9,BG9>=BJ9),"Fade-Long",IF(AND(BG9<BJ9,BG9>=BL9),"Fade-Long",IF(BG9<BL9,"GA-Short",0))))),IF(BM9<BJ9,IF(BG9>BK9,"GA-Long",IF(AND(BG9<=BK9,BG9>BJ9),"Fade-Short",IF(AND(BG9<=BJ9,BG9>BM9),"Fade-Short",IF(AND(BG9<BM9,BG9>=BL9),"Fade-Long",IF(BG9<BL9,"Fade-Long",0))))),0)) -> Fade-Long | M9: =IF(BG9=BI9,1,IF(BG9=BH9,2,0)) -> 0 | N9: =IF(AND(BG9<BK9,BC9>BK9),"Up-BO",IF(AND(BG9>BL9,BC9<BL9),"Dn-BO",IF(AND(J9="FGDn",BC9>BL9),"Dn2Up-BO",IF(AND(J9="FGUp",BC9<BK9),"Up2Dn-BO",0)))) -> Up-BO | O9: =IF(AND((IF(BV9>BW9,1,-1)>0),(IF(CB9>CC9,1,-1)>0)),1,IF(AND((IF(BV9>BW9,1,-1)<0),(IF(CB9>CC9,1,-1)<0)),2,0)) -> 0 | P9: =IF(BC9>(BH9-(BG9*0.5%)),1,IF(BC9<(BI9+(BG9*0.5%)),2,0)) -> 1 | Q9: =IF(C9>((BG9+BK9+BL9+BM9)/4),1,IF(C9<((BG9+BK9+BL9+BM9)/4),2,0)) -> 1 | R9: =IF((BS9>BT9),1,0) -> 1 | S9: =DS9 -> 0 | T9: ='Ashok-AsianP'!$ES$69 -> 0.98020726 | U9: =IF(S9<>0,T9,"-") -> - | V9: =IF(U9="-","-",_xlfn.RANK.EQ(U9,$U$5:$U$12,0)) -> - | W9: =IF(U9="-","-",_xlfn.RANK.EQ(U9,$U$5:$U$12,1)) -> - | X9: ='Ashok-AsianP'!$FI$69 -> T-R | Y9: ='Ashok-AsianP'!$FF$69 -> 2 | Z9: ='Ashok-AsianP'!$DP$69 -> 0.039765198 | AA9: ='Ashok-AsianP'!$EH$69 -> 0.040639285 | AB9: ='Ashok-AsianP'!$ER$69 -> 1.8626455 | AC9: =_xlfn.RANK.AVG(AB9,$AB$5:$AB$12,0) -> 3 | AD9: =_xlfn.RANK.AVG(AB9,$AB$5:$AB$12,1) -> 2 | AE9: =IF(AND(BC9>BU9,BC9>BV9,BZ9>=CA9,BX9>BY9),"1. Strong Up-R",IF(AND(BC9>BU9,BC9>BV9,BZ9>=CA9,BX9=BY9),"1. Strong Up-F",IF(AND(BC9>BU9,BC9>BV9,BZ9>=CA9,BX9<BY9),"1. Strong Up-D",IF(AND(BC9>BU9,BC9>BV9,BZ9<CA9,BX9>BY9),"2. Weak Up-R",IF(AND(BC9>BU9,BC9>BV9,BZ9<CA9,BX9=BY9),"2. Weak Up-F",IF(AND(BC9>BU9,BC9>BV9,BZ9<CA9,BX9<BY9),"2. Weak Up-D",IF(AND(BC9<BU9,BC9<BV9,BZ9<=CA9,BX9<BY9),"1. Strong Dn-D",IF(AND(BC9<BU9,BC9<BV9,BZ9<=CA9,BX9=BY9),"1. Strong Dn-F",IF(AND(BC9<BU9,BC9<BV9,BZ9<=CA9,BX9>BY9),"1. Strong Dn-R",IF(AND(BC9<BU9,BC9<BV9,BZ9>CA9,BX9<BY9),"2. Weak Dn-D",IF(AND(BC9<BU9,BC9<BV9,BZ9>CA9,BX9=BY9),"2. Weak Dn-F",IF(AND(BC9<BU9,BC9<BV9,BZ9>CA9,BX9>BY9),"2. Weak Dn-R","-")))))))))))) -> 1. Strong Up-R | AF9: =IF(CE9>CH9,"MFI Nr. Max. Level",IF(CE9<CI9,"MFI Nr. Min. Level",IF(AND(BC9>BU9,CB9>CC9,CC9>CD9,CB9>=0,CE9>CJ9,CE9>CF9,CE9>=50,CF9>=50),"1. Ultimate Up - R",IF(AND(BC9>BU9,CB9>CC9,CC9>CD9,CB9>=0,CE9>CJ9,CE9=CF9,CE9>=50,CF9>=50),"1. Ultimate Up - F",IF(AND(BC9>BU9,CB9>CC9,CC9>CD9,CB9>=0,CE9>CJ9,CE9<CF9,CE9>=50,CF9>=50),"1. Ultimate Up - D",IF(AND(BC9>BU9,CB9>CC9,CC9>CD9,CB9<0,CE9>CJ9,CE9>CF9,CE9>=50,CF9>=50),"2. Extreme Up - R",IF(AND(BC9>BU9,CB9>CC9,CC9>CD9,CB9<0,CE9>CJ9,CE9=CF9,CE9>=50,CF9>=50),"2. Extreme Up - F",IF(AND(BC9>BU9,CB9>CC9,CC9>CD9,CB9<0,CE9>CJ9,CE9<CF9,CE9>=50,CF9>=50),"2. Extreme Up - D",IF(AND(BC9>BU9,CB9>CC9,CC9>CD9,CB9>=0,CE9>CJ9,CE9>CF9,CE9>=50,CF9<50),"3. Uber Up",IF(AND(BC9>BU9,CB9>CC9,CC9>CD9,CB9<0,CE9>CJ9,CE9>CF9,CE9>=50,CF9<50),"4. Ultra Up",IF(AND(BC9>BU9,CB9>CC9,CC9>CD9,CB9>=0,CE9>CJ9,CE9>CF9,CE9<50),"5. Hyper Up - R",IF(AND(BC9>BU9,CB9>CC9,CC9>CD9,CB9>=0,CE9>CJ9,CE9=CF9,CE9<50),"5. Hyper Up - F",IF(AND(BC9>BU9,CB9>CC9,CC9>CD9,CB9>=0,CE9>CJ9,CE9<CF9,CE9<50),"5. Hyper Up - D",IF(AND(BC9>BU9,CB9>CC9,CC9>CD9,CB9<0,CE9>CJ9,CE9>CF9,CE9<50),"6. Super Up - R",IF(AND(BC9>BU9,CB9>CC9,CC9>CD9,CB9<0,CE9>CJ9,CE9=CF9,CE9<50),"6. Super Up - F",IF(AND(BC9>BU9,CB9>CC9,CC9>CD9,CB9<0,CE9>CJ9,CE9<CF9,CE9<50),"6. Super Up - D",IF(AND(BC9>BU9,CB9>CC9,CC9<CD9,CB9>=0,CE9>CF9,CE9>=50,CF9>=50),"7. Extra Strong Up - R",IF(AND(BC9>BU9,CB9>CC9,CC9<CD9,CB9>=0,CE9=CF9,CE9>=50,CF9>=50),"7. Extra Strong Up - F",IF(AND(BC9>BU9,CB9>CC9,CC9<CD9,CB9>=0,CE9<CF9,CE9>=50,CF9>=50),"7. Extra Strong Up - D",IF(AND(BC9>BU9,CB9>CC9,CC9<CD9,CB9>=0,CE9>CF9,CE9>=50,CF9<50),"8. Strong Up",IF(AND(BC9>BU9,CB9>CC9,CC9<CD9,CB9<0,CE9>CJ9,CE9>CF9,CE9>=50,CF9>=50),"9. Up - R",IF(AND(BC9>BU9,CB9>CC9,CC9<CD9,CB9<0,CE9>CJ9,CE9=CF9,CE9>=50,CF9>=50),"9. Up - F",IF(AND(BC9>BU9,CB9>CC9,CC9<CD9,CB9<0,CE9>CJ9,CE9<CF9,CE9>=50,CF9>=50),"9. Up - D",IF(AND(BC9>BU9,CB9>CC9,CC9<CD9,CB9<0,CE9>CF9,CE9>=50,CF9>=50),"10. Weak Up - R",IF(AND(BC9>BU9,CB9>CC9,CC9<CD9,CB9<0,CE9=CF9,CE9>=50,CF9>=50),"10. Weak Up - F",IF(AND(BC9>BU9,CB9>CC9,CC9<CD9,CB9<0,CE9<CF9,CE9>=50,CF9>=50),"10. Weak Up - D",IF(AND(BC9>BU9,CB9>CC9,CC9<CD9,CB9<0,CE9>CF9,CE9>=50,CF9<50),"11. Extra Weak Up",IF(AND(BC9>BU9,CB9>CC9,CC9>CD9,CE9>CF9,CE9<50,CF9<50),"12. Very Weak Up - R",IF(AND(BC9>BU9,CB9>CC9,CC9>CD9,CE9=CF9,CE9<50,CF9<50),"12. Very Weak Up - F",IF(AND(BC9>BU9,CB9>CC9,CC9>CD9,CE9<CF9,CE9<50,CF9<50),"12. Very Weak Up - D",IF(AND(BC9<BU9,CB9<CC9,CC9<CD9,CB9<=0,CE9<CJ9,CE9<CF9,CE9<50,CF9<50),"1. Ultimate Dn - D",IF(AND(BC9<BU9,CB9<CC9,CC9<CD9,CB9<=0,CE9<CJ9,CE9=CF9,CE9<50,CF9<50),"1. Ultimate Dn - F",IF(AND(BC9<BU9,CB9<CC9,CC9<CD9,CB9<=0,CE9<CJ9,CE9>CF9,CE9<50,CF9<50),"1. Ultimate Up - R",IF(AND(BC9<BU9,CB9<CC9,CC9<CD9,CB9>0,CE9<CJ9,CE9<CF9,CE9<50,CF9<50),"2. Extreme Dn - D",IF(AND(BC9<BU9,CB9<CC9,CC9<CD9,CB9>0,CE9<CJ9,CE9=CF9,CE9<50,CF9<50),"2. Extreme Dn - F",IF(AND(BC9<BU9,CB9<CC9,CC9<CD9,CB9>0,CE9<CJ9,CE9>CF9,CE9<50,CF9<50),"2. Extreme Dn - R",IF(AND(BC9<BU9,CB9<CC9,CC9<CD9,CB9<=0,CE9<CJ9,CE9<CF9,CE9<50,CF9>=50),"3. Uber Dn",IF(AND(BC9<BU9,CB9<CC9,CC9<CD9,CB9>0,CE9<CJ9,CE9<CF9,CE9<50,CF9>=50),"4. Ultra Dn",IF(AND(BC9<BU9,CB9<CC9,CC9<CD9,CB9<=0,CE9<CJ9,CE9<CF9,CE9>=50),"5. Hyper Dn - D",IF(AND(BC9<BU9,CB9<CC9,CC9<CD9,CB9<=0,CE9<CJ9,CE9=CF9,CE9>=50),"5. Hyper Dn - F",IF(AND(BC9<BU9,CB9<CC9,CC9<CD9,CB9<=0,CE9<CJ9,CE9>CF9,CE9>=50),"5. Hyper Dn - R",IF(AND(BC9<BU9,CB9<CC9,CC9<CD9,CB9>0,CE9<CJ9,CE9<CF9,CE9>=50),"6. Super Dn - D",IF(AND(BC9<BU9,CB9<CC9,CC9<CD9,CB9>0,CE9<CJ9,CE9=CF9,CE9>=50),"6. Super Dn - F",IF(AND(BC9<BU9,CB9<CC9,CC9<CD9,CB9>0,CE9<CJ9,CE9>CF9,CE9>=50),"6. Super Dn - R",IF(AND(BC9<BU9,CB9<CC9,CC9>CD9,CB9<=0,CE9<CF9,CE9<50,CF9<50),"7. Extra Strong Dn - D",IF(AND(BC9<BU9,CB9<CC9,CC9>CD9,CB9<=0,CE9=CF9,CE9<50,CF9<50),"7. Extra Strong Dn - F",IF(AND(BC9<BU9,CB9<CC9,CC9>CD9,CB9<=0,CE9>CF9,CE9<50,CF9<50),"7. Extra Strong Dn - R",IF(AND(BC9<BU9,CB9<CC9,CC9>CD9,CB9<=0,CE9<CF9,CE9<50,CF9>=50),"8. Strong Dn",IF(AND(BC9<BU9,CB9<CC9,CC9>CD9,CB9>0,CE9<CJ9,CE9<CF9,CE9<50,CF9<50),"9. Dn - D",IF(AND(BC9<BU9,CB9<CC9,CC9>CD9,CB9>0,CE9<CJ9,CE9=CF9,CE9<50,CF9<50),"9. Dn - F",IF(AND(BC9<BU9,CB9<CC9,CC9>CD9,CB9>0,CE9<CJ9,CE9>CF9,CE9<50,CF9<50),"9. Dn - R",IF(AND(BC9<BU9,CB9<CC9,CC9>CD9,CB9>0,CE9<CF9,CE9<50,CF9<50),"10. Weak Dn - D",IF(AND(BC9<BU9,CB9<CC9,CC9>CD9,CB9>0,CE9=CF9,CE9<50,CF9<50),"10. Weak Dn - F",IF(AND(BC9<BU9,CB9<CC9,CC9>CD9,CB9>0,CE9>CF9,CE9<50,CF9<50),"10. Weak Dn - R",IF(AND(BC9<BU9,CB9<CC9,CC9>CD9,CB9>0,CE9<CF9,CE9<50,CF9>=50),"11. Extra Weak Dn",IF(AND(BC9<BU9,CB9<CC9,CC9<CD9,CE9<CF9,CE9>=50,CF9>=50),"12. Very Weak Dn - D",IF(AND(BC9<BU9,CB9<CC9,CC9<CD9,CE9=CF9,CE9>=50,CF9>=50),"12. Very Weak Dn - F",IF(AND(BC9<BU9,CB9<CC9,CC9<CD9,CE9>CF9,CE9>=50,CF9>=50),"12. Very Weak Dn - R","No Trend")))))))))))))))))))))))))))))))))))))))))))))))))))))))))) -> No Trend | AG9: =IF(BQ9>BR9,1,0) -> 0 | AH9: =DH9 -> 0 | AK9: =IF(AI9="","",IF(AI9>0,(C9-AI9),IF(AI9<0,(-AI9-C9),"Check"))) | AL9: =IF(AI9="","",(AY9-AX9)) | AM9: =IF(AI9<>"",AL9/AO9,"") | AO9: =IF(AI9<>"",(BF9*AH9),"") | AP9: =(C9*AH9*BE9) -> 0 | AQ9: =IF(AI9="","",(AP9*'Base Data'!$C$26*2)) | AR9: =IF(AI9="","",(AP9*'Base Data'!$D$26*2)) | AS9: =IF(AI9="","",((AQ9+AR9)*'Base Data'!$E$26)+(((AQ9+AR9)*'Base Data'!$E$26)*'Base Data'!$F$26)+(((AQ9+AR9)*'Base Data'!$E$26)*'Base Data'!$G$26)) | AT9: =IF(AI9="","",(AP9*'Base Data'!$H$27*2)) | AU9: =IF(AI9="","",(AP9*'Base Data'!$I$26*2)) | AV9: =IF(AI9="","",(AP9*'Base Data'!$J$26)) | AW9: =IF(AI9="","",(AP9*'Base Data'!$K$26*2)) | AX9: =IF(AI9="","",SUM(AQ9:AW9)) | AY9: =IF(AI9="","",IF(AI9>0,((C9-AI9)*AH9*BE9),IF(AI9<0,((-AI9-C9)*AH9*BE9),"Check"))) | AZ9: =IF(AI9="","",IF(AI9>0,1,IF(AI9<0,2,0))) | BA9: =CONCATENATE(B9,'Base Data'!$D$1) -> AshokLey18NovFut | BB9: 94.6 | BC9: 94.4 | BD9: 94.8 | BE9: =VLOOKUP(B9,'[3]Margin - NSE Fut (5Paisa)'!$A:$K,2,FALSE) -> 4000 | BF9: =VLOOKUP(B9,'[3]Margin - NSE Fut (5Paisa)'!$A:$K,11,FALSE) -> 70890 | BG9: ='Ashok-AsianP'!N69 -> 93 | BH9: ='Ashok-AsianP'!O69 -> 94.8 | BI9: ='Ashok-AsianP'!P69 -> 92.65 | BJ9: ='Ashok-AsianP'!$N$67 -> 92 | BK9: ='Ashok-AsianP'!$O$67 -> 93.8 | BL9: ='Ashok-AsianP'!$P$67 -> 91.65 | BM9: ='Ashok-AsianP'!$Q$67 -> 93.4 | BN9: =(BG9-BM9) -> -0.4 | BO9: =(BG9-BM9)/BM9 -> -0.0042826552 | BP9: ='Ashok-AsianP'!$AB$69 -> 0.24141069 | BQ9: ='Ashok-AsianP'!$R$69 -> 4000 | BR9: ='Ashok-AsianP'!$R$73 -> 4493.1905 | BS9: ='Ashok-AsianP'!$AO$69 -> 0.60350919 | BT9: ='Ashok-AsianP'!$AO$73 -> 0.50677009 | BU9: ='Ashok-AsianP'!$AU$69 -> 87.048785 | BV9: ='Ashok-AsianP'!$AZ$69 -> 90.188119 | BW9: ='Ashok-AsianP'!$AZ$67 -> 89.838461 | BX9: ='Ashok-AsianP'!$BE$69 -> 92.641307 | BY9: ='Ashok-AsianP'!$BE$67 -> 92.162392 | BZ9: =IF(BX9="","",(BC9-BX9)/BX9) -> 0.018983892 | CA9: =IF(BY9="","",(BM9-BY9)/BY9) -> 0.013428557 | CB9: ='Ashok-AsianP'!$CF$69 -> 0.59567751 | CC9: ='Ashok-AsianP'!$CF$67 -> 0.64363946 | CD9: ='Ashok-AsianP'!$CF$66 -> 0.75672579 | CE9: ='Ashok-AsianP'!$CV$69 -> 69.987294 | CF9: ='Ashok-AsianP'!$CV$67 -> 66.355511 | CG9: ='Ashok-AsianP'!$CV$66 -> 62.9643 | CH9: ='Ashok-AsianP'!$CT$73 -> 75 | CI9: ='Ashok-AsianP'!$CW$73 -> 27 | CJ9: ='Ashok-AsianP'!$CW$69 -> 52.995639 | CK9: ='Ashok-AsianP'!$CW$67 -> 52.246161 | CL9: ='Ashok-AsianP'!$CW$66 -> 51.453433 | CM9: ='Ashok-AsianP'!$CX$69 -> 56.956051 | CN9: ='Ashok-AsianP'!$CX$67 -> 55.673738 | CO9: =IF(AND(BC9>BU9,CG9<CL9,CF9>CK9,CE9>CJ9,CE9>CF9,CJ9>CK9),"M34-1",IF(AND(BC9<BU9,CG9>CL9,CF9<CK9,CE9<CJ9,CE9<CF9,CJ9<CK9),"M34-2",0)) -> 0 | CP9: =IF(AI9="",0,IF(AND(AJ9="M34-1",CF9>CN9,CE9<CM9),"Exit-Long",IF(AND(AJ9="M34-2",CF9<CN9,CE9>CM9),"Exit-Short","Hold"))) -> 0 | CQ9: ='Ashok-AsianP'!$BQ$69 -> 87.419748 | CR9: ='Ashok-AsianP'!$BQ$67 -> 87.182338 | CS9: ='Ashok-AsianP'!$BR$69 -> 89.687796 | CT9: ='Ashok-AsianP'!$BR$67 -> 89.351441 | CW9: ='Ashok-AsianP'!$BO$69 -> 88.987695 | CX9: ='Ashok-AsianP'!$BO$67 -> 88.70244 | CY9: ='Ashok-AsianP'!$BP$69 -> 93.531406 | CZ9: ='Ashok-AsianP'!$BP$67 -> 93.104412 | DC9: =IF(AND(BC9>BU9,BM9<CR9,BC9>CQ9,BC9>BM9),"P34-1",IF(AND(BC9<BU9,BM9>CR9,BC9<CQ9,BC9<BM9),"P34-2",IF(AND(BC9>BU9,BM9<CX9,BC9>CW9,BC9>BM9),"P13-1",IF(AND(BC9<BU9,BM9>CX9,BC9<CW9,BC9<BM9),"P13-2",0)))) -> 0 | DD9: =IF(AI9="",0,IF(OR(AND(AJ9="P34-1",BM9>CT9,BC9<CS9),AND(AJ9="P13-1",BM9>CZ9,BC9<CY9)),"Exit-Long",IF(OR(AND(AJ9="P34-2",BM9<CV9,BC9>CU9),AND(AJ9="P13-2",BM9<DB9,BC9>DA9)),"Exit-Short","Hold"))) -> 0 | DE9: =IF(AND(BC9>BU9,CG9<CL9,CF9>CK9,CE9>CJ9,CE9>CF9,CJ9>CK9),"M34-1",IF(AND(BC9<BU9,CG9>CL9,CF9<CK9,CE9<CJ9,CE9<CF9,CJ9<CK9),"M34-2",IF(AND(BC9>BU9,BM9<CR9,BC9>CQ9,BC9>BM9),"P34-1",IF(AND(BC9<BU9,BM9>CR9,BC9<CQ9,BC9<BM9),"P34-2",IF(AND(BC9>BU9,BM9<CX9,BC9>CW9,BC9>BM9),"P13-1",IF(AND(BC9<BU9,BM9>CX9,BC9<CW9,BC9<BM9),"P13-2",0)))))) -> 0 | DF9: =IF(AI9="",0,IF(OR(AND(AJ9="M34-1",CF9>CK9,CE9<CJ9),AND(AJ9="P34-1",BM9>CT9,BC9<CS9),AND(AJ9="P13-1",BM9>CZ9,BC9<CY9)),"Exit-Long",IF(OR(AND(AJ9="M34-2",CF9<CK9,CE9>CJ9),AND(AJ9="P34-2",BM9<CV9,BC9>CU9),AND(AJ9="P13-2",BM9<DB9,BC9>DA9)),"Exit-Short","Hold"))) -> 0 | DG9: ='Ashok-AsianP'!$DL$69 -> 3.7538347 | DH9: ='Ashok-AsianP'!$DO$69 -> 0 | DI9: =IF(AI9="","-",'Base Data'!$D$10*DG9) -> - | DJ9: =IF(DK9="-","-",IF(AI9>0,(DK9-AI9),IF(AI9<0,(DK9+AI9),"Check"))) -> - | DK9: =IF(AI9="","-",IF(AI9>0,(AI9-DI9),IF(AI9<0,(-AI9+DI9),"Check"))) -> - | DL9: =IF(AI9="","-",IF(AI9>0,(AI9+(1*'Base Data'!$D$12*DG9)),IF(AI9<0,(-AI9-(1*'Base Data'!$D$12*DG9)),"Check"))) -> - | DM9: =IF(AI9="","-",IF(AI9>0,(AI9+(2*'Base Data'!$D$12*DG9)),IF(AI9<0,(-AI9-(2*'Base Data'!$D$12*DG9)),"Check"))) -> - | DN9: =IF(AI9="","-",IF(AI9>0,(AI9+(3*'Base Data'!$D$12*DG9)),IF(AI9<0,(-AI9-(3*'Base Data'!$D$12*DG9)),"Check"))) -> - | DO9: =IF(AI9="","-",IF(AI9>0,(AI9+(4*'Base Data'!$D$12*DG9)),IF(AI9<0,(-AI9-(4*'Base Data'!$D$12*DG9)),"Check"))) -> - | DP9: =IF(AI9="","-",IF(AI9>0,(AI9+DI9),IF(AI9<0,(-AI9-DI9),"Check"))) -> - | DQ9: =IF(DP9="-","-",IF(AI9>0,(DP9-AI9),IF(AI9<0,(DP9+AI9),"Check"))) -> - | DR9: ='Ashok-AsianP'!$ED$69 -> 3.8363485 | DS9: ='Ashok-AsianP'!$EG$69 -> 0 | DT9: =IF(AI9="","-",'Base Data'!$D$13*DR9) -> - | DU9: =IF(DV9="-","-",IF(AI9>0,(DV9-AI9),IF(AI9<0,(DV9+AI9),"Check"))) -> - | DV9: =IF(AI9="","-",IF(AI9>0,(AI9-DT9),IF(AI9<0,(-AI9+DT9),"Check"))) -> - | DW9: =IF(AI9="","-",IF(AI9>0,(AI9+DT9),IF(AI9<0,(-AI9-DT9),"Check"))) -> - | DX9: =IF(DW9="-","-",IF(AI9>0,(DW9-AI9),IF(AI9<0,(DW9+AI9),"Check"))) -> - | EE9: =IF(AI9="","",IF(AL9>0,AL9,0)) | EF9: =IF(AI9="","",IF(AL9<=0,AL9,0)) | EG9: =IF(AI9="","",IF(AI9>0,(BF9*AH9),0)) | EH9: =IF(AI9="","",IF(AI9<=0,(BF9*AH9),0)) | EI9: =IF(AI9="","",IF(AI9>0,(BF9*S9),0)) | EJ9: =IF(AI9="","",IF(AI9<=0,(BF9*S9),0)) | EK9: =IF(AI9="","",IF(AL9>0,1,0)) | EL9: =IF(AI9="","",IF(AL9<=0,1,0)) | EM9: =IF(AND(EN9=1,OR(AND(ER9>=0.5%,ER9<=1.5%),AND(ER9<=-0.5%,ER9>=-1.5%)),ES9>=0.5%),CONCATENATE("Long ",B9),IF(AND(EN9=2,OR(AND(ER9>=0.5%,ER9<=1.5%),AND(ER9<=-0.5%,ER9>=-1.5%)),ES9>=0.5%),CONCATENATE("Short ",B9),"Do Not Trade")) -> Do Not Trade | EN9: =IF(OR(EO9="",EP9=""),"",IF(BC9>=(EO9+'Base Data'!$D$14),1,IF(BC9<=(EP9-'Base Data'!$D$14),2,0))) -> 0 | EO9: =BH9 -> 94.8 | EP9: =BI9 -> 92.65 | EQ9: =IF(AI9="","",IF(AI9>0,IF(BC9<EP9,"Exit Long & Go Short",IF(BC9>(AI9+(EO9-EP9)),"Exit - TP","Hold")),IF(AI9<0,IF(BC9>EO9,"Exit Short & Go Long",IF(BC9<(-AI9-(EO9-EP9)),"Exit - TP","Hold"))))) | ER9: =(BC9-BM9)/BM9 -> 0.010706638 | ES9: =IF(OR(EO9<>"",EP9<>""),(EO9-EP9)/BG9,(BH9-BI9)/BG9) -> 0.02311828 | ET9: =IF(AND(EU9="",EV9="",EW9="",EX9=""),"",IF(AND(EU9<(80%*EX9),EV9<(80%*EX9),EW9<(80%*EX9)),0,IF(AND(EU9>=(80%*EX9),EV9<(80%*EX9),EW9<(80%*EX9)),5,IF(AND(EU9<(80%*EX9),EV9>=(80%*EX9),EW9<(80%*EX9)),10,IF(AND(EU9<(80%*EX9),EV9<(80%*EX9),EW9>=(80%*EX9)),15,IF(AND(EU9>=(80%*EX9),EV9>=(80%*EX9),EW9<(80%*EX9)),20,IF(AND(EU9>=(80%*EX9),EV9<(80%*EX9),EW9>=(80%*EX9)),25,IF(AND(EU9<(80%*EX9),EV9>=(80%*EX9),EW9>=(80%*EX9)),30,IF(AND(EU9>=(80%*EX9),EV9>=(80%*EX9),EW9>=(80%*EX9)),35,"Check"))))))))) -> 35 | EU9: ='Ashok-AsianP'!$EX$69 -> 0.038418909 | EV9: ='Ashok-AsianP'!$EY$69 -> 0.035183383 | EW9: ='Ashok-AsianP'!$EZ$69 -> 0.029175952 | EX9: ='Ashok-AsianP'!$EW$73 -> 0.024366132 | EY9: =IF(OR(AND(EN9=1,OR(AND(ER9>=0.5%,ER9<=1.5%),AND(ER9<=-0.5%,ER9>=-1.5%)),ES9>=0.5%),AND(EN9=2,OR(AND(ER9>=0.5%,ER9<=1.5%),AND(ER9<=-0.5%,ER9>=-1.5%)),ES9>=0.5%)),1,0) -> 0 | EZ9: =IF(OR(EQ9="Exit Long & Go Short",EQ9="Exit Short & Go Long"),1,0) -> 0
