Workbook

Sheet Risk per Trade Sample
A2: Sr. No. | B2: Scrip | C2: Risk per Trade per Lot | D2: Margin per Lot | E2: Lots | F2: Total Risk | G2: Total Margin | H2: Profit / Loss | I2: % Returns | J2: Lots | K2: Total Risk | L2: Total Margin | M2: Profit / Loss | N2: % Returns
A4: 1 | B4: BANKNIFTY | C4: 9290.1051 | D4: 40556.975 | E4: 1 | F4: =C4*E4 -> 9290.1051 | G4: =D4*E4 -> 40556.975 | H4: =F4 -> 9290.1051 | I4: =H4/G4 -> 0.22906307 | J4: 2 | K4: =C4*J4 -> 18580.21 | L4: =D4*J4 -> 81113.95 | M4: =K4 -> 18580.21 | N4: =M4/L4 -> 0.22906307
A5: =A4+1 -> 2 | B5: NIFTY | C5: 7876.69 | D5: 47947.287 | E5: 1 | F5: =C5*E5 -> 7876.69 | G5: =D5*E5 -> 47947.287 | H5: =F5 -> 7876.69 | I5: =H5/G5 -> 0.16427811 | J5: 2 | K5: =C5*J5 -> 15753.38 | L5: =D5*J5 -> 95894.575 | M5: =K5 -> 15753.38 | N5: =M5/L5 -> 0.16427811
A7: =A5+1 -> 3 | B7: ABIRLANUVO | C7: 4845.5655 | D7: 27083 | E7: 1 | F7: =C7*E7 -> 4845.5655 | G7: =D7*E7 -> 27083 | H7: =F7 -> 4845.5655 | I7: =H7/G7 -> 0.17891539 | J7: 4 | K7: =C7*J7 -> 19382.262 | L7: =D7*J7 -> 108332 | M7: =K7 -> 19382.262 | N7: =M7/L7 -> 0.17891539
A8: =A7+1 -> 4 | B8: ACC | C8: 10062.172 | D8: 67126.438 | E8: 1 | F8: =C8*E8 -> 10062.172 | G8: =D8*E8 -> 67126.438 | H8: =F8 -> 10062.172 | I8: =H8/G8 -> 0.14989879 | J8: 1 | K8: =C8*J8 -> 10062.172 | L8: =D8*J8 -> 67126.438 | M8: =K8 -> 10062.172 | N8: =M8/L8 -> 0.14989879
A10: =A8+1 -> 5 | B10: ALBK | C10: 13565.33 | D10: 52710 | E10: 1 | F10: =C10*E10 -> 13565.33 | G10: =D10*E10 -> 52710 | H10: =F10 -> 13565.33 | I10: =H10/G10 -> 0.2573578 | J10: 1 | K10: =C10*J10 -> 13565.33 | L10: =D10*J10 -> 52710 | M10: =K10 -> 13565.33 | N10: =M10/L10 -> 0.2573578
A11: =A10+1 -> 6 | B11: AMBUJACEM | C11: 16201.164 | D11: 59377.5 | E11: 1 | F11: =C11*E11 -> 16201.164 | G11: =D11*E11 -> 59377.5 | H11: =F11 -> 16201.164 | I11: =H11/G11 -> 0.27285023 | J11: 1 | K11: =C11*J11 -> 16201.164 | L11: =D11*J11 -> 59377.5 | M11: =K11 -> 16201.164 | N11: =M11/L11 -> 0.27285023
A13: =A11+1 -> 7 | B13: ANDHRABANK | C13: 11403.796 | D13: 59100 | E13: 1 | F13: =C13*E13 -> 11403.796 | G13: =D13*E13 -> 59100 | H13: =F13 -> 11403.796 | I13: =H13/G13 -> 0.19295763 | J13: 1 | K13: =C13*J13 -> 11403.796 | L13: =D13*J13 -> 59100 | M13: =K13 -> 11403.796 | N13: =M13/L13 -> 0.19295763
A14: =A13+1 -> 8 | B14: APOLLOTYRE | C14: 15122.628 | D14: 62475 | E14: 1 | F14: =C14*E14 -> 15122.628 | G14: =D14*E14 -> 62475 | H14: =F14 -> 15122.628 | I14: =H14/G14 -> 0.24205888 | J14: 1 | K14: =C14*J14 -> 15122.628 | L14: =D14*J14 -> 62475 | M14: =K14 -> 15122.628 | N14: =M14/L14 -> 0.24205888
A16: =A14+1 -> 9 | B16: ADANIPOWER | C16: 19778.989 | D16: 94464.8 | E16: 1 | F16: =C16*E16 -> 19778.989 | G16: =D16*E16 -> 94464.8 | H16: =F16 -> 19778.989 | I16: =H16/G16 -> 0.20937947 | J16: 1 | K16: =C16*J16 -> 19778.989 | L16: =D16*J16 -> 94464.8 | M16: =K16 -> 19778.989 | N16: =M16/L16 -> 0.20937947
A17: =A16+1 -> 10 | B17: ASHOKLEY | C17: 18149.713 | D17: 95252.5 | E17: 1 | F17: =C17*E17 -> 18149.713 | G17: =D17*E17 -> 95252.5 | H17: =F17 -> 18149.713 | I17: =H17/G17 -> 0.19054316 | J17: 1 | K17: =C17*J17 -> 18149.713 | L17: =D17*J17 -> 95252.5 | M17: =K17 -> 18149.713 | N17: =M17/L17 -> 0.19054316
A19: =A17+1 -> 11 | B19: AXISBANK | C19: 15292.986 | D19: 58177.5 | E19: 1 | F19: =C19*E19 -> 15292.986 | G19: =D19*E19 -> 58177.5 | H19: =F19 -> 15292.986 | I19: =H19/G19 -> 0.2628677 | J19: 1 | K19: =C19*J19 -> 15292.986 | L19: =D19*J19 -> 58177.5 | M19: =K19 -> 15292.986 | N19: =M19/L19 -> 0.2628677
A20: =A19+1 -> 12 | B20: BHEL | C20: 9333.7463 | D20: 37410 | E20: 1 | F20: =C20*E20 -> 9333.7463 | G20: =D20*E20 -> 37410 | H20: =F20 -> 9333.7463 | I20: =H20/G20 -> 0.2494987 | J20: 2 | K20: =C20*J20 -> 18667.493 | L20: =D20*J20 -> 74820 | M20: =K20 -> 18667.493 | N20: =M20/L20 -> 0.2494987
A22: =A20+1 -> 13 | B22: BANKBARODA | C22: 16765.762 | D22: 74934.75 | E22: 1 | F22: =C22*E22 -> 16765.762 | G22: =D22*E22 -> 74934.75 | H22: =F22 -> 16765.762 | I22: =H22/G22 -> 0.22373814 | J22: 1 | K22: =C22*J22 -> 16765.762 | L22: =D22*J22 -> 74934.75 | M22: =K22 -> 16765.762 | N22: =M22/L22 -> 0.22373814
A23: =A22+1 -> 14 | B23: BANKINDIA | C23: 8922.0672 | D23: 38542.5 | E23: 1 | F23: =C23*E23 -> 8922.0672 | G23: =D23*E23 -> 38542.5 | H23: =F23 -> 8922.0672 | I23: =H23/G23 -> 0.23148647 | J23: 2 | K23: =C23*J23 -> 17844.134 | L23: =D23*J23 -> 77085 | M23: =K23 -> 17844.134 | N23: =M23/L23 -> 0.23148647
A25: =A23+1 -> 15 | B25: BHARATFORG | C25: 12934.086 | D25: 50323.75 | E25: 1 | F25: =C25*E25 -> 12934.086 | G25: =D25*E25 -> 50323.75 | H25: =F25 -> 12934.086 | I25: =H25/G25 -> 0.25701754 | J25: 1 | K25: =C25*J25 -> 12934.086 | L25: =D25*J25 -> 50323.75 | M25: =K25 -> 12934.086 | N25: =M25/L25 -> 0.25701754
A26: =A25+1 -> 16 | B26: BHARTIARTL | C26: 14700.217 | D26: 56196 | E26: 1 | F26: =C26*E26 -> 14700.217 | G26: =D26*E26 -> 56196 | H26: =F26 -> 14700.217 | I26: =H26/G26 -> 0.26158832 | J26: 1 | K26: =C26*J26 -> 14700.217 | L26: =D26*J26 -> 56196 | M26: =K26 -> 14700.217 | N26: =M26/L26 -> 0.26158832
A28: =A26+1 -> 17 | B28: BPCL | C28: 13615.757 | D28: 73602 | E28: 1 | F28: =C28*E28 -> 13615.757 | G28: =D28*E28 -> 73602 | H28: =F28 -> 13615.757 | I28: =H28/G28 -> 0.18499168 | J28: 1 | K28: =C28*J28 -> 13615.757 | L28: =D28*J28 -> 73602 | M28: =K28 -> 13615.757 | N28: =M28/L28 -> 0.18499168
A29: =A28+1 -> 18 | B29: CAIRN | C29: 14752.736 | D29: 57225 | E29: 1 | F29: =C29*E29 -> 14752.736 | G29: =D29*E29 -> 57225 | H29: =F29 -> 14752.736 | I29: =H29/G29 -> 0.25780229 | J29: 1 | K29: =C29*J29 -> 14752.736 | L29: =D29*J29 -> 57225 | M29: =K29 -> 14752.736 | N29: =M29/L29 -> 0.25780229
A31: =A29+1 -> 19 | B31: CANBK | C31: 15742.461 | D31: 61600 | E31: 1 | F31: =C31*E31 -> 15742.461 | G31: =D31*E31 -> 61600 | H31: =F31 -> 15742.461 | I31: =H31/G31 -> 0.25555943 | J31: 1 | K31: =C31*J31 -> 15742.461 | L31: =D31*J31 -> 61600 | M31: =K31 -> 15742.461 | N31: =M31/L31 -> 0.25555943
A32: =A31+1 -> 20 | B32: CENTURYTEX | C32: 13727.055 | D32: 68024 | E32: 1 | F32: =C32*E32 -> 13727.055 | G32: =D32*E32 -> 68024 | H32: =F32 -> 13727.055 | I32: =H32/G32 -> 0.20179723 | J32: 1 | K32: =C32*J32 -> 13727.055 | L32: =D32*J32 -> 68024 | M32: =K32 -> 13727.055 | N32: =M32/L32 -> 0.20179723
A34: =A32+1 -> 21 | B34: COLPAL | C34: 8381.2798 | D34: 53498.75 | E34: 1 | F34: =C34*E34 -> 8381.2798 | G34: =D34*E34 -> 53498.75 | H34: =F34 -> 8381.2798 | I34: =H34/G34 -> 0.1566631 | J34: 2 | K34: =C34*J34 -> 16762.56 | L34: =D34*J34 -> 106997.5 | M34: =K34 -> 16762.56 | N34: =M34/L34 -> 0.1566631
A35: =A34+1 -> 22 | B35: DISHTV | C35: 13254.079 | D35: 65250 | E35: 1 | F35: =C35*E35 -> 13254.079 | G35: =D35*E35 -> 65250 | H35: =F35 -> 13254.079 | I35: =H35/G35 -> 0.20312765 | J35: 1 | K35: =C35*J35 -> 13254.079 | L35: =D35*J35 -> 65250 | M35: =K35 -> 13254.079 | N35: =M35/L35 -> 0.20312765
A37: =A35+1 -> 23 | B37: BAJFINANCE | C37: 21333.034 | D37: 108768 | E37: 1 | F37: =C37*E37 -> 21333.034 | G37: =D37*E37 -> 108768 | H37: =F37 -> 21333.034 | I37: =H37/G37 -> 0.19613337 | J37: 0 | K37: =C37*J37 -> 0 | L37: =D37*J37 -> 0 | M37: =K37 -> 0 | N37: =M37/L37 -> #DIV/0!
A38: =A37+1 -> 24 | B38: BOSCHLTD | C38: 11121.344 | D38: 63324.5 | E38: 1 | F38: =C38*E38 -> 11121.344 | G38: =D38*E38 -> 63324.5 | H38: =F38 -> 11121.344 | I38: =H38/G38 -> 0.17562466 | J38: 1 | K38: =C38*J38 -> 11121.344 | L38: =D38*J38 -> 63324.5 | M38: =K38 -> 11121.344 | N38: =M38/L38 -> 0.17562466
A40: =A38+1 -> 25 | B40: ADANIPORTS | C40: 12251.123 | D40: 54640 | E40: 1 | F40: =C40*E40 -> 12251.123 | G40: =D40*E40 -> 54640 | H40: =F40 -> 12251.123 | I40: =H40/G40 -> 0.22421529 | J40: 1 | K40: =C40*J40 -> 12251.123 | L40: =D40*J40 -> 54640 | M40: =K40 -> 12251.123 | N40: =M40/L40 -> 0.22421529
A41: =A40+1 -> 26 | B41: ARVIND | C41: 15819.071 | D41: 61977.75 | E41: 1 | F41: =C41*E41 -> 15819.071 | G41: =D41*E41 -> 61977.75 | H41: =F41 -> 15819.071 | I41: =H41/G41 -> 0.25523791 | J41: 1 | K41: =C41*J41 -> 15819.071 | L41: =D41*J41 -> 61977.75 | M41: =K41 -> 15819.071 | N41: =M41/L41 -> 0.25523791

Sheet ORB Rules
A2: Strategy 1 : | B2: Simple Opening Range Break-Out (ORB)
A3: 1 | B3: Scrip Selection Criteria 1 : 1 Day H-L Range % Diff. >= 80% of 500 Day H-L Range % Diff.
A4: =A3+1 -> 2 | B4: Scrip Selection Criteria 2 : 11 Day H-L Range % Diff. >= 80% of 500 Day H-L Range % Diff.
A5: =A4+1 -> 3 | B5: Scrip Selection Criteria 3 : 21 Day H-L Range % Diff. >= 80% of 500 Day H-L Range % Diff.
A6: =A5+1 -> 4 | B6: Identify the HL Range of the Scrip @ 9:30 AM [HL Range = High @ 9:30 AM - Low @ 9:30 AM]
A7: =A6+1 -> 5 | B7: Entry Criteria 1 : The % Difference of (High - Low) should be >= 0.50% [(High - Low) / (LTP @ 9:30 AM) x 100]
A8: =A7+1 -> 6 | B8: Entry Criteria 2 : The % Change should be >=0.50% & <=1.50% [(Curr. Open - Prev. Close) / Prev. Close x 100]
A9: =A8+1 -> 7 | B9: Entry Criteria 3 : Go Long if Price crosses Above High by Rs. 0.05 [Long @ High + 0.05] OR Go Short if Price crosses Below Low by Rs. 0.05 [Short @ Low - 0.05]
A10: =A9+1 -> 8 | B10: Exit Criteria 1 : Long Target = Entry + HL Range OR Short Target = Entry - HL Range
A11: =A10+1 -> 9 | B11: Exit Criteria 2 : Long SL => When Price crosses Below Low @ 9:30 AM OR Short SL => When Price crosses Above High @ 9:30 AM
A12: =A11+1 -> 10 | B12: Exit Criteria 3 : If Target or SL is not Hit during the day, Exit the position @ 3:15 PM
A13: =A12+1 -> 11 | B13: Exit & Re-Entry Criteria 1 : If Long SL is Hit, Reverse the position by going Short OR If Short SL is Hit, Reverse the position by going Long
A16: Strategy 2 : | B16: Opening Range Break-Out (ORB) with High Probability Trades
A17: 1 | B17: Scrip Selection Criteria 1 : 8 Day H-L Range % Diff. >= 80% of 500 Day H-L Range % Diff.
A18: =A17+1 -> 2 | B18: Scrip Selection Criteria 2 : 13 Day H-L Range % Diff. >= 80% of 500 Day H-L Range % Diff.
A19: =A18+1 -> 3 | B19: Scrip Selection Criteria 3 : 21 Day H-L Range % Diff. >= 80% of 500 Day H-L Range % Diff.
A20: =A19+1 -> 4 | B20: Scrip Selection Criteria 4 : Select the Scrip as per the Categorisation Table
A21: =A20+1 -> 5 | B21: Scrip Selection Criteria 5 : ORB is Above Previous Day's High for Long OR ORB is Below Previous Day's Low for Short [High Probability Trade]
A22: =A21+1 -> 6 | B22: Identify the HL Range of the Scrip @ 9:30 AM [HL Range = High @ 9:30 AM - Low @ 9:30 AM]
A23: =A22+1 -> 7 | B23: Entry Criteria 1 : The % Difference of (High - Low) should be >= 0.50% [(High - Low) / (LTP @ 9:30 AM) x 100]
A24: =A23+1 -> 8 | B24: Entry Criteria 2 : The % Change should be >=0.50% & <=1.50% [(Curr. Open - Prev. Close) / Prev. Close x 100]
A25: =A24+1 -> 9 | B25: Entry Criteria 4 : VOLUME, YESTERDAY's Values - Buy or Sell Easier Days, O=H or O=L, Gap-Up/Dn along with the Gap Zones.
A26: =A25+1 -> 10 | B26: Entry Criteria 3 : Go Long if Price crosses Above High by Rs. 0.20 [Long @ High + 0.20] OR Go Short if Price crosses Below Low by Rs. 0.20 [Short @ Low - 0.20]
A27: =A26+1 -> 11 | B27: Entry Criteria 4 : Add to the existing position (Pyramiding) if after going Long, the Prev. Day's High is broken OR if after going Short, the Prev. Day's Low is broken.
A28: =A27+1 -> 12 | B28: Exit Criteria 1 : Long Target = Entry + 75% of ATR OR Short Target = Entry - 75% of ATR
A29: =A28+1 -> 13 | B29: Exit Criteria 2 :
... A32: =A31+1 -> 16 | B32: Exit Criteria 5 : If Target or SL is not Hit during the day, Exit the position @ 3:15 PM
B33: Exit & Re-Entry Criteria 1 : If Long SL Hit, Reverse the position by going Short OR If Short SL Hit, Reverse the position by going Long
B34: Exit & Re-Entry Criteria 2 :
A36: Strategy 3 : | B36: Fading the Opening Range (FOR) with High Probability Trades
A37: 1 | B37: Select Scrips from Nifty F&O with Beta of < 1
A38: =A37+1 -> 2 | B38: Identify the HL Range of the Scrip @ 9:30 AM [HL Range = High @ 9:30 AM - Low @ 9:30 AM]
A39: =A38+1 -> 3 | B39: Entry Criteria 1 : The % Difference of (High - Low) should be >= 0.50% [(High - Low) / (LTP @ 9:30 AM) x 100]
A40: =A39+1 -> 4 | B40: Entry Criteria 2 : The % Change should be >=0.50% & <=1.50% [(Curr. Open - Prev. Close) / Prev. Close x 100]
A41: =A40+1 -> 5 | B41: Entry Criteria 3 : Go Short if Price touches High and falls by Rs. 0.05 [Short @ High - 0.05] OR Go Short if Price touches Low and rises by Rs. 0.05 [Long @ Low + 0.05]
A42: =A41+1 -> 6 | B42: Exit Criteria 1 : Exit Long when Price touches High [Long Target = High - Entry] OR Exit Short when Price touches Low [Short Target = Entry - Low]
A43: =A42+1 -> 7 | B43: Exit Criteria 2 : Long SL => When Price crosses Below Low @ 9:30 AM OR Short SL => When Price crosses Above High @ 9:30 AM
A44: =A43+1 -> 8 | B44: Exit Criteria 3 : If Target or SL is not Hit during the day, Exit the position @ 3:15 PM
A45: =A44+1 -> 9 | B45: Exit & Re-Entry Criteria 1 : If Long SL is Hit, Reverse the position by going Short OR If Short SL is Hit, Reverse the position by going Long

Sheet Base Data
A1: Expiry | D1: 16JunFut | G1: 16JulFut | H1: 16AugFut
A2: Initial Portfolio Size (Rs.) | D2: 10000000
A3: Initial Max. Risk per Trade % | D3: 0.0025
A4: Current P&L (Rs.) | F4: Link this cell to the current P&L
A5: Current Portfolio Size (Rs.) | D5: =D2+D4 -> 10000000
A6: Current Max. Risk per Trade % | D6: =IF((D5>=100%*D2),D3,IF(AND((D5>=90%*D2),(D5<100%*D2)),C22,IF(AND((D5>=80%*D2),(D5<90%*D2)),D22,IF(AND((D5>=70%*D2),(D5<80%*D2)),E22,IF(AND((D5>=60%*D2),(D5<70%*D2)),F22,IF(AND((D5>=50%*D2),(D5<60%*D2)),G22,IF(AND((D5>=40%*D2),(D5<50%*D2)),H22,IF(AND((D5>=30%*D2),(D5<40%*D2)),I22,IF(AND((D5>=20%*D2),(D5<30%*D2)),J22,IF(AND((D5>=10%*D2),(D5<20%*D2)),K22,IF((D5<=10%*D2),L22,"Check"))))))))))) -> 0.0025
A7: Max. Risk per Trade (Rs.) | D7: =D5*D6 -> 25000
A8: Avg. No. of Trades | D8: =D5/D7 -> 400
A9: % Reduction in Risk | D9: 0.2
A10: ATR Multiple for SL & TP (Positional) | D10: 2
A11: Max. Positions per Scrip for Pyramiding (Positional) | D11: 5
A12: ATR Multiple for Pyramiding (Positional) | D12: 0.4
A13: ATR Multiple for SL & TP (Intraday) | D13: 0.75
A14: ORB - Points Above / Below Entry Criteria | D14: 0.05
A15: Trend Finder - RSI Up / Down Value | D15: 51 | E15: 49
A16: Gann Angle - Trade Type (IntraDay / Positional) | D16: IntraDay
A17: Gann Angle - Trade Holding Period (Positional Trades) | D17: 10
A18: Gann Angle - Market Stabilisation Time | D18: =DATE(YEAR(NOW()),MONTH(NOW()),DAY(NOW()))+TIME(9,15,0) -> 45353.385 | E18: 0.41666667
A19: Gann Angle - Current Time | D19: =NOW() -> 45353.031
A21: DrawDown % | C21: 90-100% | D21: 80-90% | E21: 70-80% | F21: 60-70% | G21: 50-60% | H21: 40-50% | I21: 30-40% | J21: 20-30% | K21: 10-20% | L21: 0-10%
A22: Max. Risk per Trade % | C22: =D3 -> 0.0025 | D22: =C22*(100%-$D$9) -> 0.002 | E22: =D22*(100%-$D$9) -> 0.0016 | F22: =E22*(100%-$D$9) -> 0.00128 | G22: =F22*(100%-$D$9) -> 0.001024 | H22: =G22*(100%-$D$9) -> 0.0008192 | I22: =H22*(100%-$D$9) -> 0.00065536 | J22: =I22*(100%-$D$9) -> 0.000524288 | K22: =J22*(100%-$D$9) -> 0.0004194304 | L22: =K22*(100%-$D$9) -> 0.00033554432
A24: Charges | C24: Brokerage | D24: Turnover | E24: Service Tax | F24: Edu. Cess | G24: H. Edu. Cess | H24: SEBI | I24: Stamp | J24: STT | K24: Slippage
A25: % of Turnover | C25: 0.0002 | D25: 2.1e-05 | E25: 0.14 | F25: 0.005 | G25: 0.005 | H25: - | I25: 2e-05 | J25: 0.0001 | K25: 0.0004
A26: Rate per Transaction (Rs.) | C26: 20 | D26: - | E26: - | F26: - | G26: - | H26: =20/10000000 -> 2e-06 | I26: - | J26: -
A78: Trade Type
A79: IntraDay
A80: Positional

Sheet Gap Z, OH-OL & Prev. BO Rules
A1: Sr. No. | B1: Price Action & Indicators | I1: Trade | J1: Entry | K1: Hard Stop Loss | L1: Trailing Stop Loss | M1: Target (Only 1 Lot) | N1: Target (More than 1 Lots)
B2: ORB | D2: O=H / O=L | E2: Gaps | F2: Gap Zone | G2: Fade / GA | H2: BO
A3: Set - I : ORB with Gap Zone :-
A4: 1 | B4: BO-Abv. 9:30 AM High | C4: Other ORB Criteria | D4: - | E4: Par. GUp | F4: U-HC | G4: Go Along | H4: - | I4: Long | J4: 9:30 AM High + 0.10 | K4: Below 9:30 AM Low | L4: No TSL | M4: Entry + (75% of ATR) | N4: Entry + (50% / 75% / 100% of ATR)
B5: BO-Blw. 9:30 AM Low | D5: - | E5: Par. GDn | F5: D-CL | H5: - | I5: Short | J5: 9:30 AM Low - 0.10 | K5: Above 9:30 AM High | M5: Entry - (75% of ATR) | N5: Entry - (50% / 75% / 100% of ATR)
A6: =A4+1 -> 2 | B6: BO-Abv. 9:30 AM High | C6: Other ORB Criteria | D6: - | E6: Par. GDn | F6: D-CL | G6: Fade | H6: - | I6: Long | J6: 9:30 AM High + 0.10 | K6: Below 9:30 AM Low | L6: No TSL | M6: Entry + (75% of ATR) | N6: Entry + (50% / 75% / 100% of ATR)
B7: BO-Blw. 9:30 AM Low | D7: - | E7: Par. GUp | F7: U-HC | H7: - | I7: Short | J7: 9:30 AM Low - 0.10 | K7: Above 9:30 AM High | M7: Entry - (75% of ATR) | N7: Entry - (50% / 75% / 100% of ATR)
A8: =A6+1 -> 3 | B8: BO-Abv. 9:30 AM High | C8: Other ORB Criteria | D8: - | E8: Par. GUp | F8: D-OC | G8: Go Along | H8: - | I8: Long | J8: 9:30 AM High + 0.10 | K8: Below 9:30 AM Low | L8: No TSL | M8: Entry + (75% of ATR) | N8: Entry + (50% / 75% / 100% of ATR)
B9: BO-Blw. 9:30 AM Low | D9: - | E9: Par. GDn | F9: U-CO | H9: - | I9: Short | J9: 9:30 AM Low - 0.10 | K9: Above 9:30 AM High | M9: Entry - (75% of ATR) | N9: Entry - (50% / 75% / 100% of ATR)
A10: =A8+1 -> 4 | B10: BO-Abv. 9:30 AM High | C10: Other ORB Criteria | D10: - | E10: Par. GDn | F10: U-CO | G10: Fade | H10: - | I10: Long | J10: 9:30 AM High + 0.10 | K10: Below 9:30 AM Low | L10: No TSL | M10: Entry + (75% of ATR) | N10: Entry + (50% / 75% / 100% of ATR)
B11: BO-Blw. 9:30 AM Low | D11: - | E11: Par. GUp | F11: D-OC | H11: - | I11: Short | J11: 9:30 AM Low - 0.10 | K11: Above 9:30 AM High | M11: Entry - (75% of ATR) | N11: Entry - (50% / 75% / 100% of ATR)
A12: =A10+1 -> 5 | B12: BO-Abv. 9:30 AM High | C12: Other ORB Criteria | D12: - | E12: Par. GUp | F12: D-HO | G12: Go Along | H12: - | I12: Long | J12: 9:30 AM High + 0.10 | K12: Below 9:30 AM Low | L12: No TSL | M12: Entry + (75% of ATR) | N12: Entry + (50% / 75% / 100% of ATR)
B13: BO-Blw. 9:30 AM Low | D13: - | E13: Par. GDn | F13: U-OL | H13: - | I13: Short | J13: 9:30 AM Low - 0.10 | K13: Above 9:30 AM High | M13: Entry - (75% of ATR) | N13: Entry - (50% / 75% / 100% of ATR)
A14: =A12+1 -> 6 | B14: BO-Abv. 9:30 AM High | C14: Other ORB Criteria | D14: - | E14: Par. GDn | F14: U-OL | G14: Fade | H14: - | I14: Long | J14: 9:30 AM High + 0.10 | K14: Below 9:30 AM Low | L14: No TSL | M14: Entry + (75% of ATR) | N14: Entry + (50% / 75% / 100% of ATR)
B15: BO-Blw. 9:30 AM Low | D15: - | E15: Par. GUp | F15: D-HO | H15: - | I15: Short | J15: 9:30 AM Low - 0.10 | K15: Above 9:30 AM High | M15: Entry - (75% of ATR) | N15: Entry - (50% / 75% / 100% of ATR)
A16: =A14+1 -> 7 | B16: BO-Abv. 9:30 AM High | C16: Other ORB Criteria | D16: - | E16: Full GDn | F16: U-L | G16: Fade | H16: - | I16: Long | J16: 9:30 AM Low + 0.10 | K16: Below 9:30 AM Low | L16: No TSL | M16: Entry + (75% of ATR) | N16: Entry + (50% / 75% / 100% of ATR)
B17: BO-Blw. 9:30 AM Low | D17: - | E17: Full GUp | F17: D-H | H17: - | I17: Short | J17: 9:30 AM High - 0.10 | K17: Above 9:30 AM High | M17: Entry - (75% of ATR) | N17: Entry - (50% / 75% / 100% of ATR)
A18: =A16+1 -> 8 | B18: BO-Abv. 9:30 AM High | C18: Other ORB Criteria | D18: - | E18: Full GDn | F18: U-L | G18: Fade | H18: - | I18: Long | J18: 9:30 AM High + 0.10 | K18: Below 9:30 AM Low | L18: No TSL | M18: Entry + (75% of ATR) | N18: Entry + (50% / 75% / 100% of ATR)
B19: BO-Blw. 9:30 AM Low | D19: - | E19: Full GUp | F19: D-H | H19: - | I19: Short | J19: 9:30 AM Low - 0.10 | K19: Above 9:30 AM High | M19: Entry - (75% of ATR) | N19: Entry - (50% / 75% / 100% of ATR)
A20: =A18+1 -> 9 | B20: BO-Abv. 9:30 AM High | C20: Other ORB Criteria | D20: - | E20: Full GDn | F20: D-L | G20: Fade | H20: - | I20: Long | J20: 9:30 AM Low + 0.10 | K20: Below 9:30 AM Low | L20: No TSL | M20: Entry + (75% of ATR) | N20: Entry + (50% / 75% / 100% of ATR)
B21: BO-Blw. 9:30 AM Low | D21: - | E21: Full GUp | F21: U-H | H21: - | I21: Short | J21: 9:30 AM High - 0.10 | K21: Above 9:30 AM High | M21: Entry - (75% of ATR) | N21: Entry - (50% / 75% / 100% of ATR)
A22: =A20+1 -> 10 | B22: BO-Abv. 9:30 AM High | C22: Other ORB Criteria | D22: - | E22: Full GDn | F22: D-L | G22: Fade | H22: - | I22: Long | J22: 9:30 AM High + 0.10 | K22: Below 9:30 AM Low | L22: No TSL | M22: Entry + (75% of ATR) | N22: Entry + (50% / 75% / 100% of ATR)
B23: BO-Blw. 9:30 AM Low | D23: - | E23: Full GUp | F23: U-H | H23: - | I23: Short | J23: 9:30 AM Low - 0.10 | K23: Above 9:30 AM High | M23: Entry - (75% of ATR) | N23: Entry - (50% / 75% / 100% of ATR)
A24: Set - II : ORB with Prev. Day Break Out :-
A25: =A22+1 -> 11 | B25: BO-Abv. 9:30 AM High | C25: Other ORB Criteria | D25: - | E25: - | F25: - | G25: - | H25: BO-Abv. PD High | I25: Long | J25: (9:30 AM High OR Prev. Day High, whichever Later) + 0.10 | K25: Below 9:30 AM Low | L25: No TSL | M25: Entry + (75% of ATR) | N25: Entry + (50% / 75% / 100% of ATR)
B26: BO-Blw. 9:30 AM Low | D26: - | E26: - | F26: - | H26: BO-Blw. PD Low | I26: Short | J26: (9:30 AM Low OR Prev. Day Low, whichever Later) - 0.10 | K26: Above 9:30 AM High | M26: Entry - (75% of ATR) | N26: Entry - (50% / 75% / 100% of ATR)
A27: =A25+1 -> 12 | B27: BO-Abv. 9:30 AM High | C27: Other ORB Criteria | D27: - | E27: - | F27: - | G27: - | H27: BO-Abv. PD Low | I27: Long | J27: (9:30 AM High OR Prev. Day Low, whichever Later) + 0.10 | K27: Below 9:30 AM Low | L27: No TSL | M27: Entry + (75% of ATR) | N27: Entry + (50% / 75% / 100% of ATR)
B28: BO-Blw. 9:30 AM Low | D28: - | E28: - | F28: - | H28: BO-Blw. PD High | I28: Short | J28: (9:30 AM Low OR Prev. Day High, whichever Later) - 0.10 | K28: Above 9:30 AM High | M28: Entry - (75% of ATR) | N28: Entry - (50% / 75% / 100% of ATR)
A29: Set - III : ORB with Gap Zone & Prev. Day Break Out :-
A30: =A27+1 -> 13 | B30: BO-Abv. 9:30 AM High | C30: Other ORB Criteria | D30: - | E30: Par. GUp | F30: U-HC | G30: Go Along | H30: BO-Abv. PD High | I30: Long | J30: (9:30 AM High OR Prev. Day High, whichever Later) + 0.10 | K30: Below 9:30 AM Low | L30: No TSL | M30: Entry + (75% of ATR) | N30: Entry + (50% / 75% / 100% of ATR)
B31: BO-Blw. 9:30 AM Low | D31: - | E31: Par. GDn | F31: D-CL | H31: BO-Blw. PD Low | I31: Short | J31: (9:30 AM Low OR Prev. Day Low, whichever Later) - 0.10 | K31: Above 9:30 AM High | M31: Entry - (75% of ATR) | N31: Entry - (50% / 75% / 100% of ATR)
A32: =A30+1 -> 14 | B32: BO-Abv. 9:30 AM High | C32: Other ORB Criteria | D32: - | E32: Par. GDn | F32: D-CL | G32: Fade | H32: BO-Abv. PD High | I32: Long | J32: (9:30 AM High OR Prev. Day High, whichever Later) + 0.10 | K32: Below 9:30 AM Low | L32: No TSL | M32: Entry + (75% of ATR) | N32: Entry + (50% / 75% / 100% of ATR)
B33: BO-Blw. 9:30 AM Low | D33: - | E33: Par. GUp | F33: U-HC | H33: BO-Blw. PD Low | I33: Short | J33: (9:30 AM Low OR Prev. Day Low, whichever Later) - 0.10 | K33: Above 9:30 AM High | M33: Entry - (75% of ATR) | N33: Entry - (50% / 75% / 100% of ATR)
A34: =A32+1 -> 15 | B34: BO-Abv. 9:30 AM High | C34: Other ORB Criteria | D34: - | E34: Par. GUp | F34: D-OC | G34: Go Along | H34: BO-Abv. PD High | I34: Long | J34: (9:30 AM High OR Prev. Day High, whichever Later) + 0.10 | K34: Below 9:30 AM Low | L34: No TSL | M34: Entry + (75% of ATR) | N34: Entry + (50% / 75% / 100% of ATR)
B35: BO-Blw. 9:30 AM Low | D35: - | E35: Par. GDn | F35: U-CO | H35: BO-Blw. PD Low | I35: Short | J35: (9:30 AM Low OR Prev. Day Low, whichever Later) - 0.10 | K35: Above 9:30 AM High | M35: Entry - (75% of ATR) | N35: Entry - (50% / 75% / 100% of ATR)
A36: =A34+1 -> 16 | B36: BO-Abv. 9:30 AM High | C36: Other ORB Criteria | D36: - | E36: Par. GDn | F36: U-CO | G36: Fade | H36: BO-Abv. PD High | I36: Long | J36: (9:30 AM High OR Prev. Day High, whichever Later) + 0.10 | K36: Below 9:30 AM Low | L36: No TSL | M36: Entry + (75% of ATR) | N36: Entry + (50% / 75% / 100% of ATR)
B37: BO-Blw. 9:30 AM Low | D37: - | E37: Par. GUp | F37: D-OC | H37: BO-Blw. PD Low | I37: Short | J37: (9:30 AM Low OR Prev. Day Low, whichever Later) - 0.10 | K37: Above 9:30 AM High | M37: Entry - (75% of ATR) | N37: Entry - (50% / 75% / 100% of ATR)
A38: =A36+1 -> 17 | B38: BO-Abv. 9:30 AM High | C38: Other ORB Criteria | D38: - | E38: Par. GUp | F38: D-HO | G38: Go Along | H38: BO-Abv. PD High | I38: Long | J38: (9:30 AM High OR Prev. Day High, whichever Later) + 0.10 | K38: Below 9:30 AM Low | L38: No TSL | M38: Entry + (75% of ATR) | N38: Entry + (50% / 75% / 100% of ATR)
B39: BO-Blw. 9:30 AM Low | D39: - | E39: Par. GDn | F39: U-OL | H39: BO-Blw. PD Low | I39: Short | J39: (9:30 AM Low OR Prev. Day Low, whichever Later) - 0.10 | K39: Above 9:30 AM High | M39: Entry - (75% of ATR) | N39: Entry - (50% / 75% / 100% of ATR)
A40: =A38+1 -> 18 | B40: BO-Abv. 9:30 AM High | C40: Other ORB Criteria | D40: - | E40: Par. GDn | F40: U-OL | G40: Fade | H40: BO-Abv. PD High | I40: Long | J40: (9:30 AM High OR Prev. Day High, whichever Later) + 0.10 | K40: Below 9:30 AM Low | L40: No TSL | M40: Entry + (75% of ATR) | N40: Entry + (50% / 75% / 100% of ATR)
...

Sheet ORB
B1: =[1]NOW!$C$6 -> 8183.2 | C1: =[1]NOW!$E$6 -> -41.9 | D1: =NOW() -> 45353.031 | E1: IntraDay Strategies | I1: IntraDay Trend | U1: IntraDay (ORB, Gap Up/Dn & O=H/O=L Strategies) | AB1: Positional (RSI Crossover & SMA Crossover Strategies)
A2: Sr. No. | B2: Scrip | C2: Current Market Price | D2: LTP - Open | E2: ORB | F2: Gap Zone | G2: O=H & O=L | H2: Prev. Day's High/Low Break-Out | I2: IntraDay Trend (Tom Demark Method) | J2: IntraDay Trend (Modified Pivot) | K2: No. of Lots | L2: Enter High at 9:30 AM | M2: Enter Low at 9:30 AM | N2: Enter Long/Short Price | O2: Points (Pre Charges) | P2: Gross Profit/Loss (Pre Charges) | Q2: Net Profit/Loss (Post Charges) | R2: %Returns (Post Charges) | S2: Approx. Margin Utilised | T2: ORB Exit / Hold | U2: Average True Range (8) | V2: =CONCATENATE("Max. Lots with Risk per Trade of Rs. ",'Base Data'!$D$7," [No. of Lots]") -> Max. Lots with Risk per Trade of Rs. 25000 [No. of Lots] | W2: =CONCATENATE("Hard Stop Loss & Target Points. from Entry [",'Base Data'!$D$13,"N]") -> Hard Stop Loss & Target Points. from Entry [0.75N] | X2: Points till Hard Stop Loss | Y2: =CONCATENATE("Hard Stop Loss [",'Base Data'!$D$13,"N]") -> Hard Stop Loss [0.75N] | Z2: =CONCATENATE("Target [",'Base Data'!$D$13,"N]") -> Target [0.75N] | AA2: Points till Target | AB2: Average True Range (21) | AC2: =CONCATENATE("Max. Lots with Risk per Trade of Rs. ",'Base Data'!$D$7," [No. of Lots]") -> Max. Lots with Risk per Trade of Rs. 25000 [No. of Lots] | AD2: =CONCATENATE("Hard Stop Loss & Target Points. from Entry [",'Base Data'!$D$10,"N]") -> Hard Stop Loss & Target Points. from Entry [2N] | AE2: Points till Hard Stop Loss | AF2: =CONCATENATE("Hard Stop Loss [",'Base Data'!$D$10,"N]") -> Hard Stop Loss [2N] | AG2: =CONCATENATE("Enter Additional Position [",1*'Base Data'!$D$12,"N]") -> Enter Additional Position [0.4N] | AH2: =CONCATENATE("Enter Additional Position [",2*'Base Data'!$D$12,"N]") -> Enter Additional Position [0.8N] | AI2: =CONCATENATE("Enter Additional Position [",3*'Base Data'!$D$12,"N]") -> Enter Additional Position [1.2N] | AJ2: =CONCATENATE("Enter Additional Position [",4*'Base Data'!$D$12,"N]") -> Enter Additional Position [1.6N] | AK2: =CONCATENATE("Target [",'Base Data'!$D$10,"N]") -> Target [2N] | AL2: Points till Target | AM2: Transaction Value | AN2: Brokerage | AO2: Turnover Charges | AP2: Service Tax (incl. Cess) | AQ2: SEBI Charges | AR2: Stamp Duty Charges | AS2: STT | AT2: Slippage | AU2: Total Charges | AV2: In Market | AW2: Scrip with Expiry | AX2: Best Buy Rate | AY2: Last Traded Price | AZ2: Best Sell Rate | BA2: Qty | BB2: Approx. Margin Required Per Lot | BC2: Open | BD2: High | BE2: Low | BF2: Prev. Close | BG2: Prev. Open | BH2: Prev. High | BI2: Prev. Low | BJ2: Gap Up / Dn | BK2: Gap Zone Reco. (Fade / GA) | BL2: Reco. ORB (Basic) | BM2: % Change (LTP - Prev. Close) | BN2: % Diff. (High - Low) | BO2: HL Avg. % Change Status | BP2: HL Avg. % Change (8 Day) | BQ2: HL Avg. % Change (13 Day) | BR2: HL Avg. % Change (21 Day) | BS2: HL Avg. % Change (60 Day) | BT2: ORB In Trade | BU2: Exit & Reverse
A4: 1 | B4: BankNifty | C4: =IF(AND(BL4=1,AZ4<>0),AZ4,IF(AND(BL4=2,AX4<>0),AX4,AY4)) -> 17551 | D4: =(AY4-BC4) -> -49 | E4: =IF(AND(BL4=1,OR(AND(BM4>=0.5%,BM4<=1.5%),AND(BM4<=-0.5%,BM4>=-1.5%)),BN4>=0.5%),CONCATENATE("Long ",B4),IF(AND(BL4=2,OR(AND(BM4>=0.5%,BM4<=1.5%),AND(BM4<=-0.5%,BM4>=-1.5%)),BN4>=0.5%),CONCATENATE("Short ",B4),"Do Not Trade")) -> Do Not Trade | F4: =IF(BF4>BG4,IF(BC4>BH4,"U-H",IF(AND(BC4<=BH4,BC4>BF4),"U-HC",IF(AND(BC4<BF4,BC4>=BG4),"U-CO",IF(AND(BC4<BG4,BC4>=BI4),"U-OL",IF(BC4<BI4,"U-L","-"))))),IF(BF4<BG4,IF(BC4>BH4,"D-H",IF(AND(BC4<=BH4,BC4>BG4),"D-HO",IF(AND(BC4<=BG4,BC4>BF4),"D-OC",IF(AND(BC4<BF4,BC4>=BI4),"D-CL",IF(BC4<BI4,"D-L","-"))))),"-")) -> D-L | G4: =IF(BC4=BE4,1,IF(BC4=BD4,2,0)) -> 0 | H4: =IF(AND(BC4<BH4,AY4>BH4),"Up-BO",IF(AND(BC4>BI4,AY4<BI4),"Dn-BO",IF(AND(BJ4="FGDn",AY4>BI4),"Dn2Up-BO",IF(AND(BJ4="FGUp",AY4<BH4),"Up2Dn-BO",0)))) -> 0 | I4: =IF(AY4>(BD4-(BC4*0.5%)),1,IF(AY4<(BE4+(BC4*0.5%)),2,0)) -> 2 | J4: =IF(C4>((BC4+BH4+BI4+BF4)/4),1,IF(C4<((BC4+BH4+BI4+BF4)/4),2,0)) -> 2 | K4: =V4 -> 4 | O4: =IF(N4="","",IF(N4>0,(C4-N4),IF(N4<0,(-N4-C4),"Check"))) | P4: =IF(N4="","",IF(N4>0,((C4-N4)*K4*BA4),IF(N4<0,((-N4-C4)*K4*BA4),"Check"))) | Q4: =IF(N4="","",(P4-AU4)) | R4: =IF(N4<>"",Q4/S4,"") | S4: =IF(N4<>"",(BB4*K4),"") | T4: =IF(N4="","",IF(N4>0,IF(AY4<M4,"Exit Long & Go Short",IF(AY4>(N4+(L4-M4)),"Exit - TP","Hold")),IF(N4<0,IF(AY4>L4,"Exit Short & Go Long",IF(AY4<(-N4-(L4-M4)),"Exit - TP","Hold"))))) | U4: ='BNF-Nifty'!$AA$65 -> 260.36582 | V4: ='BNF-Nifty'!$AD$65 -> 4 | W4: =IF(N4="","",'Base Data'!$D$13*U4) | X4: =IF(Y4="","",IF(N4>0,(Y4-N4),IF(N4<0,(Y4+N4),"Check"))) | Y4: =IF(N4="","",IF(N4>0,(N4-W4),IF(N4<0,(-N4+W4),"Check"))) | Z4: =IF(N4="","",IF(N4>0,(N4+W4),IF(N4<0,(-N4-W4),"Check"))) | AA4: =IF(Z4="","",IF(N4>0,(Z4-N4),IF(N4<0,(Z4+N4),"Check"))) | AB4: ='BNF-Nifty'!$AK$65 -> 263.41512 | AC4: ='BNF-Nifty'!$AN$65 -> 1 | AD4: =IF(N4="","",'Base Data'!$D$10*AB4) | AE4: =IF(AF4="","",IF(N4>0,(AF4-N4),IF(N4<0,(AF4+N4),"Check"))) | AF4: =IF(N4="","",IF(N4>0,(N4-AD4),IF(N4<0,(-N4+AD4),"Check"))) | AG4: =IF(N4="","",IF(N4>0,(N4+(1*'Base Data'!$D$12*AB4)),IF(N4<0,(-N4-(1*'Base Data'!$D$12*AB4)),"Check"))) | AH4: =IF(N4="","",IF(N4>0,(N4+(2*'Base Data'!$D$12*AB4)),IF(N4<0,(-N4-(2*'Base Data'!$D$12*AB4)),"Check"))) | AI4: =IF(N4="","",IF(N4>0,(N4+(3*'Base Data'!$D$12*AB4)),IF(N4<0,(-N4-(3*'Base Data'!$D$12*AB4)),"Check"))) | AJ4: =IF(N4="","",IF(N4>0,(N4+(4*'Base Data'!$D$12*AB4)),IF(N4<0,(-N4-(4*'Base Data'!$D$12*AB4)),"Check"))) | AK4: =IF(N4="","",IF(N4>0,(N4+AD4),IF(N4<0,(-N4-AD4),"Check"))) | AL4: =IF(AK4="","",IF(N4>0,(AK4-N4),IF(N4<0,(AK4+N4),"Check"))) | AM4: =(C4*K4*BA4) -> 2106120 | AN4: =IF(N4="","",(AM4*'Base Data'!$C$25*2)) | AO4: =IF(N4="","",(AM4*'Base Data'!$D$25*2)) | AP4: =IF(N4="","",((AN4+AO4)*'Base Data'!$E$25)+(((AN4+AO4)*'Base Data'!$E$25)*'Base Data'!$F$25)+(((AN4+AO4)*'Base Data'!$E$25)*'Base Data'!$G$25)) | AQ4: =IF(N4="","",(AM4*'Base Data'!$H$26*2)) | AR4: =IF(N4="","",(AM4*'Base Data'!$I$25*2)) | AS4: =IF(N4="","",(AM4*'Base Data'!$J$25)) | AT4: =IF(N4="","",(AM4*'Base Data'!$K$25*2)) | AU4: =IF(N4="","",SUM(AN4:AT4)) | AV4: =IF(N4="","",IF(N4>0,1,IF(N4<0,2,0))) | AW4: =CONCATENATE(B4,'Base Data'!$D$1) -> BankNifty16JunFut | AX4: =VLOOKUP(AW4,[1]NOW!$A:$D,2,FALSE) -> 17551 | AY4: =VLOOKUP(AW4,[1]NOW!$A:$D,3,FALSE) -> 17551 | AZ4: =VLOOKUP(AW4,[1]NOW!$A:$D,4,FALSE) -> 17553.3 | BA4: =VLOOKUP(B4,'[2]Margin - NSE Fut (5Paisa)'!$A:$K,2,FALSE) -> 30 | BB4: =VLOOKUP(B4,'[2]Margin - NSE Fut (5Paisa)'!$A:$K,11,FALSE) -> 42945.06 | BC4: =VLOOKUP(AW4,[1]NOW!$A:$L,9,FALSE) -> 17600 | BD4: =VLOOKUP(AW4,[1]NOW!$A:$L,10,FALSE) -> 17765.65 | BE4: =VLOOKUP(AW4,[1]NOW!$A:$L,11,FALSE) -> 17500 | BF4: =VLOOKUP(AW4,[1]NOW!$A:$L,12,FALSE) -> 17623.1 | BG4: ='BNF-Nifty'!$N$63 -> 17715.301 | BH4: ='BNF-Nifty'!$O$63 -> 17754.85 | BI4: ='BNF-Nifty'!$P$63 -> 17603 | BJ4: =IF(AND(BC4>BF4,BC4<BH4),"PGUp",IF(AND(BC4>BF4,BC4>BH4),"FGUp",IF(AND(BC4<BF4,BC4>BI4),"PGDn",IF(AND(BC4<BF4,BC4<BI4),"FGDn",0)))) -> FGDn | BK4: =IF(BF4>BG4,IF(BC4>BH4,"Fade-Short",IF(AND(BC4<=BH4,BC4>BF4),"Fade-Short",IF(AND(BC4<BF4,BC4>=BG4),"Fade-Long",IF(AND(BC4<BG4,BC4>=BI4),"Fade-Long",IF(BC4<BI4,"GA-Short","-"))))),IF(BF4<BG4,IF(BC4>BH4,"GA-Long",IF(AND(BC4<=BH4,BC4>BG4),"Fade-Short",IF(AND(BC4<=BG4,BC4>BF4),"Fade-Short",IF(AND(BC4<BF4,BC4>=BI4),"Fade-Long",IF(BC4<BI4,"Fade-Long","-"))))),"-")) -> Fade-Long | BL4: =IF(OR(L4="",M4=""),"",IF(AY4>=(L4+'Base Data'!$D$14),1,IF(AY4<=(M4-'Base Data'!$D$14),2,0))) | BM4: =(AY4-BF4)/BF4 -> -0.0040912212 | BN4: =IF(OR(L4<>"",M4<>""),(L4-M4)/BC4,(BD4-BE4)/BC4) -> 0.01509375 | BO4: =IF(AND(BP4="",BQ4="",BR4="",BS4=""),"",IF(AND(BP4<(80%*BS4),BQ4<(80%*BS4),BR4<(80%*BS4)),0,IF(AND(BP4>=(80%*BS4),BQ4<(80%*BS4),BR4<(80%*BS4)),5,IF(AND(BP4<(80%*BS4),BQ4>=(80%*BS4),BR4<(80%*BS4)),10,IF(AND(BP4<(80%*BS4),BQ4<(80%*BS4),BR4>=(80%*BS4)),15,IF(AND(BP4>=(80%*BS4),BQ4>=(80%*BS4),BR4<(80%*BS4)),20,IF(AND(BP4>=(80%*BS4),BQ4<(80%*BS4),BR4>=(80%*BS4)),25,IF(AND(BP4<(80%*BS4),BQ4>=(80%*BS4),BR4>=(80%*BS4)),30,IF(AND(BP4>=(80%*BS4),BQ4>=(80%*BS4),BR4>=(80%*BS4)),35,"Check"))))))))) -> 35 | BP4: ='BNF-Nifty'!$AV$65 -> 0.013957533 | BQ4: ='BNF-Nifty'!$AW$65 -> 0.013093817 | BR4: ='BNF-Nifty'!$AX$65 -> 0.013935545 | BS4: ='BNF-Nifty'!$AU$69 -> 0.016332234 | BT4: =IF(OR(AND(BL4=1,OR(AND(BM4>=0.5%,BM4<=1.5%),AND(BM4<=-0.5%,BM4>=-1.5%)),BN4>=0.5%),AND(BL4=2,OR(AND(BM4>=0.5%,BM4<=1.5%),AND(BM4<=-0.5%,BM4>=-1.5%)),BN4>=0.5%)),1,0) -> 0 | BU4: =IF(OR(T4="Exit Long & Go Short",T4="Exit Short & Go Long"),1,0) -> 0
A5: =A4+1 -> 2 | B5: Nifty | C5: =IF(AND(BL5=1,AZ5<>0),AZ5,IF(AND(BL5=2,AX5<>0),AX5,AY5)) -> 8183.2 | D5: =(AY5-BC5) -> -43.65 | E5: =IF(AND(BL5=1,OR(AND(BM5>=0.5%,BM5<=1.5%),AND(BM5<=-0.5%,BM5>=-1.5%)),BN5>=0.5%),CONCATENATE("Long ",B5),IF(AND(BL5=2,OR(AND(BM5>=0.5%,BM5<=1.5%),AND(BM5<=-0.5%,BM5>=-1.5%)),BN5>=0.5%),CONCATENATE("Short ",B5),"Do Not Trade")) -> Do Not Trade | F5: =IF(BF5>BG5,IF(BC5>BH5,"U-H",IF(AND(BC5<=BH5,BC5>BF5),"U-HC",IF(AND(BC5<BF5,BC5>=BG5),"U-CO",IF(AND(BC5<BG5,BC5>=BI5),"U-OL",IF(BC5<BI5,"U-L","-"))))),IF(BF5<BG5,IF(BC5>BH5,"D-H",IF(AND(BC5<=BH5,BC5>BG5),"D-HO",IF(AND(BC5<=BG5,BC5>BF5),"D-OC",IF(AND(BC5<BF5,BC5>=BI5),"D-CL",IF(BC5<BI5,"D-L","-"))))),"-")) -> D-OC | G5: =IF(BC5=BE5,1,IF(BC5=BD5,2,0)) -> 0 | H5: =IF(AND(BC5<BH5,AY5>BH5),"Up-BO",IF(AND(BC5>BI5,AY5<BI5),"Dn-BO",IF(AND(BJ5="FGDn",AY5>BI5),"Dn2Up-BO",IF(AND(BJ5="FGUp",AY5<BH5),"Up2Dn-BO",0)))) -> Dn-BO | I5: =IF(AY5>(BD5-(BC5*0.5%)),1,IF(AY5<(BE5+(BC5*0.5%)),2,0)) -> 2 | J5: =IF(C5>((BC5+BH5+BI5+BF5)/4),1,IF(C5<((BC5+BH5+BI5+BF5)/4),2,0)) -> 2 | K5: =V5 -> 4 | O5: =IF(N5="","",IF(N5>0,(C5-N5),IF(N5<0,(-N5-C5),"Check"))) | P5: =IF(N5="","",IF(N5>0,((C5-N5)*K5*BA5),IF(N5<0,((-N5-C5)*K5*BA5),"Check"))) | Q5: =IF(N5="","",(P5-AU5)) | R5: =IF(N5<>"",Q5/S5,"") | S5: =IF(N5<>"",(BB5*K5),"") | T5: =IF(N5="","",IF(N5>0,IF(AY5<M5,"Exit Long & Go Short",IF(AY5>(N5+(L5-M5)),"Exit - TP","Hold")),IF(N5<0,IF(AY5>L5,"Exit Short & Go Long",IF(AY5<(-N5-(L5-M5)),"Exit - TP","Hold"))))) | U5: ='BNF-Nifty'!$AF$65 -> 96.188727 | V5: ='BNF-Nifty'!$AI$65 -> 4 | W5: =IF(N5="","",'Base Data'!$D$13*U5) | X5: =IF(Y5="","",IF(N5>0,(Y5-N5),IF(N5<0,(Y5+N5),"Check"))) | Y5: =IF(N5="","",IF(N5>0,(N5-W5),IF(N5<0,(-N5+W5),"Check"))) | Z5: =IF(N5="","",IF(N5>0,(N5+W5),IF(N5<0,(-N5-W5),"Check"))) | AA5: =IF(Z5="","",IF(N5>0,(Z5-N5),IF(N5<0,(Z5+N5),"Check"))) | AB5: ='BNF-Nifty'!$AP$65 -> 93.924742 | AC5: ='BNF-Nifty'!$AS$65 -> 1 | AD5: =IF(N5="","",'Base Data'!$D$10*AB5) | AE5: =IF(AF5="","",IF(N5>0,(AF5-N5),IF(N5<0,(AF5+N5),"Check"))) | AF5: =IF(N5="","",IF(N5>0,(N5-AD5),IF(N5<0,(-N5+AD5),"Check"))) | AG5: =IF(N5="","",IF(N5>0,(N5+(1*'Base Data'!$D$12*AB5)),IF(N5<0,(-N5-(1*'Base Data'!$D$12*AB5)),"Check"))) | AH5: =IF(N5="","",IF(N5>0,(N5+(2*'Base Data'!$D$12*AB5)),IF(N5<0,(-N5-(2*'Base Data'!$D$12*AB5)),"Check"))) | AI5: =IF(N5="","",IF(N5>0,(N5+(3*'Base Data'!$D$12*AB5)),IF(N5<0,(-N5-(3*'Base Data'!$D$12*AB5)),"Check"))) | AJ5: =IF(N5="","",IF(N5>0,(N5+(4*'Base Data'!$D$12*AB5)),IF(N5<0,(-N5-(4*'Base Data'!$D$12*AB5)),"Check"))) | AK5: =IF(N5="","",IF(N5>0,(N5+AD5),IF(N5<0,(-N5-AD5),"Check"))) | AL5: =IF(AK5="","",IF(N5>0,(AK5-N5),IF(N5<0,(AK5+N5),"Check"))) | AM5: =(C5*K5*BA5) -> 2454960 | AN5: =IF(N5="","",(AM5*'Base Data'!$C$25*2)) | AO5: =IF(N5="","",(AM5*'Base Data'!$D$25*2)) | AP5: =IF(N5="","",((AN5+AO5)*'Base Data'!$E$25)+(((AN5+AO5)*'Base Data'!$E$25)*'Base Data'!$F$25)+(((AN5+AO5)*'Base Data'!$E$25)*'Base Data'!$G$25)) | AQ5: =IF(N5="","",(AM5*'Base Data'!$H$26*2)) | AR5: =IF(N5="","",(AM5*'Base Data'!$I$25*2)) | AS5: =IF(N5="","",(AM5*'Base Data'!$J$25)) | AT5: =IF(N5="","",(AM5*'Base Data'!$K$25*2)) | AU5: =IF(N5="","",SUM(AN5:AT5)) | AV5: =IF(N5="","",IF(N5>0,1,IF(N5<0,2,0))) | AW5: =CONCATENATE(B5,'Base Data'!$D$1) -> Nifty16JunFut | AX5: =VLOOKUP(AW5,[1]NOW!$A:$D,2,FALSE) -> 8183.2 | AY5: =VLOOKUP(AW5,[1]NOW!$A:$D,3,FALSE) -> 8183.2 | AZ5: =VLOOKUP(AW5,[1]NOW!$A:$D,4,FALSE) -> 8183.4 | BA5: =VLOOKUP(B5,'[2]Margin - NSE Fut (5Paisa)'!$A:$K,2,FALSE) -> 75 | BB5: =VLOOKUP(B5,'[2]Margin - NSE Fut (5Paisa)'!$A:$K,11,FALSE) -> 49704.088 | BC5: =VLOOKUP(AW5,[1]NOW!$A:$L,9,FALSE) -> 8226.85 | BD5: =VLOOKUP(AW5,[1]NOW!$A:$L,10,FALSE) -> 8253.25 | BE5: =VLOOKUP(AW5,[1]NOW!$A:$L,11,FALSE) -> 8154 | BF5: =VLOOKUP(AW5,[1]NOW!$A:$L,12,FALSE) -> 8225.1 | BG5: ='BNF-Nifty'!$T$63 -> 8251.1504 | BH5: ='BNF-Nifty'!$U$63 -> 8253 | BI5: ='BNF-Nifty'!$V$63 -> 8205.7998 | BJ5: =IF(AND(BC5>BF5,BC5<BH5),"PGUp",IF(AND(BC5>BF5,BC5>BH5),"FGUp",IF(AND(BC5<BF5,BC5>BI5),"PGDn",IF(AND(BC5<BF5,BC5<BI5),"FGDn",0)))) -> PGUp | BK5: =IF(BF5>BG5,IF(BC5>BH5,"Fade-Short",IF(AND(BC5<=BH5,BC5>BF5),"Fade-Short",IF(AND(BC5<BF5,BC5>=BG5),"Fade-Long",IF(AND(BC5<BG5,BC5>=BI5),"Fade-Long",IF(BC5<BI5,"GA-Short","-"))))),IF(BF5<BG5,IF(BC5>BH5,"GA-Long",IF(AND(BC5<=BH5,BC5>BG5),"Fade-Short",IF(AND(BC5<=BG5,BC5>BF5),"Fade-Short",IF(AND(BC5<BF5,BC5>=BI5),"Fade-Long",IF(BC5<BI5,"Fade-Long","-"))))),"-")) -> Fade-Short | BL5: =IF(OR(L5="",M5=""),"",IF(AY5>=(L5+'Base Data'!$D$14),1,IF(AY5<=(M5-'Base Data'!$D$14),2,0))) | BM5: =(AY5-BF5)/BF5 -> -0.005094163 | BN5: =IF(OR(L5<>"",M5<>""),(L5-M5)/BC5,(BD5-BE5)/BC5) -> 0.012064156 | BO5: =IF(AND(BP5="",BQ5="",BR5="",BS5=""),"",IF(AND(BP5<(80%*BS5),BQ5<(80%*BS5),BR5<(80%*BS5)),0,IF(AND(BP5>=(80%*BS5),BQ5<(80%*BS5),BR5<(80%*BS5)),5,IF(AND(BP5<(80%*BS5),BQ5>=(80%*BS5),BR5<(80%*BS5)),10,IF(AND(BP5<(80%*BS5),BQ5<(80%*BS5),BR5>=(80%*BS5)),15,IF(AND(BP5>=(80%*BS5),BQ5>=(80%*BS5),BR5<(80%*BS5)),20,IF(AND(BP5>=(80%*BS5),BQ5<(80%*BS5),BR5>=(80%*BS5)),25,IF(AND(BP5<(80%*BS5),BQ5>=(80%*BS5),BR5>=(80%*BS5)),30,IF(AND(BP5>=(80%*BS5),BQ5>=(80%*BS5),BR5>=(80%*BS5)),35,"Check"))))))))) -> 35 | BP5: ='BNF-Nifty'!$BA$65 -> 0.011279248 | BQ5: ='BNF-Nifty'!$BB$65 -> 0.010628939 | BR5: ='BNF-Nifty'!$BC$65 -> 0.010592512 | BS5: ='BNF-Nifty'!$AZ$69 -> 0.011381795 | BT5: =IF(OR(AND(BL5=1,OR(AND(BM5>=0.5%,BM5<=1.5%),AND(BM5<=-0.5%,BM5>=-1.5%)),BN5>=0.5%),AND(BL5=2,OR(AND(BM5>=0.5%,BM5<=1.5%),AND(BM5<=-0.5%,BM5>=-1.5%)),BN5>=0.5%)),1,0) -> 0 | BU5: =IF(OR(T5="Exit Long & Go Short",T5="Exit Short & Go Long"),1,0) -> 0

Sheet BNF-Nifty
A1: Directional Trading System : | D1: BankNifty | E1: Nifty | F1: BNF | G1: Nifty | L1: Sr. No. | M1: =CONCATENATE($F$1," - Open, High, Low & Close") -> BNF - Open, High, Low & Close | S1: =CONCATENATE($G$1," - Open, High, Low & Close") -> Nifty - Open, High, Low & Close | Z1: =CONCATENATE($F$1," - MM (Market Normalisation) with ATR (8) for IntraDay Trades") -> BNF - MM (Market Normalisation) with ATR (8) for IntraDay Trades | AE1: =CONCATENATE($G$1," - MM (Market Normalisation) with ATR (8) for IntraDay Trades") -> Nifty - MM (Market Normalisation) with ATR (8) for IntraDay Trades | AJ1: =CONCATENATE($F$1," - MM (Market Normalisation) with ATR (21) for Positional Trades") -> BNF - MM (Market Normalisation) with ATR (21) for Positional Trades | AO1: =CONCATENATE($G$1," - MM (Market Normalisation) with ATR (21) for Positional Trades") -> Nifty - MM (Market Normalisation) with ATR (21) for Positional Trades | AT1: =CONCATENATE($F$1," - High-Low Range Average for ORB") -> BNF - High-Low Range Average for ORB | AY1: =CONCATENATE($G$1," - High-Low Range Average for ORB") -> Nifty - High-Low Range Average for ORB
A2: Particulars | D2: EOD Data | F2: Real Time Data | M2: Date | N2: =CONCATENATE($F$1," Open") -> BNF Open | O2: =CONCATENATE($F$1," High") -> BNF High | P2: =CONCATENATE($F$1," Low") -> BNF Low | Q2: =CONCATENATE($F$1," Close") -> BNF Close | R2: =CONCATENATE($F$1," Volume") -> BNF Volume | S2: Date | T2: =CONCATENATE($G$1," Open") -> Nifty Open | U2: =CONCATENATE($G$1," High") -> Nifty High | V2: =CONCATENATE($G$1," Low") -> Nifty Low | W2: =CONCATENATE($G$1," Close") -> Nifty Close | X2: =CONCATENATE($G$1," Volume") -> Nifty Volume | Z2: True Range | AA2: Averate True Range (8) [N] | AB2: Rupee Volatility / Risk [N x Lot Size] | AC2: =CONCATENATE("Contract Risk (Unit) [",'Base Data'!$D$13,"N]") -> Contract Risk (Unit) [0.75N] | AD2: =CONCATENATE("Max. Lots that can be Traded with a Unit of Rs. ",'Base Data'!$D$7," [No. of Lots]") -> Max. Lots that can be Traded with a Unit of Rs. 25000 [No. of Lots] | AE2: True Range | AF2: Averate True Range (8) [N] | AG2: Rupee Volatility / Risk [N x Lot Size] | AH2: =CONCATENATE("Contract Risk (Unit) [",'Base Data'!$D$13,"N]") -> Contract Risk (Unit) [0.75N] | AI2: =CONCATENATE("Max. Lots that can be Traded with a Unit of Rs. ",'Base Data'!$D$7," [No. of Lots]") -> Max. Lots that can be Traded with a Unit of Rs. 25000 [No. of Lots] | AJ2: True Range | AK2: Averate True Range (21) [N] | AL2: Rupee Volatility / Risk [N x Lot Size] | AM2: =CONCATENATE("Contract Risk (Unit) [",'Base Data'!$D$10,"N]") -> Contract Risk (Unit) [2N] | AN2: =CONCATENATE("Max. Lots that can be Traded with a Unit of Rs. ",'Base Data'!$D$7," [No. of Lots]") -> Max. Lots that can be Traded with a Unit of Rs. 25000 [No. of Lots] | AO2: True Range | AP2: Averate True Range (21) [N] | AQ2: Rupee Volatility / Risk [N x Lot Size] | AR2: =CONCATENATE("Contract Risk (Unit) [",'Base Data'!$D$10,"N]") -> Contract Risk (Unit) [2N] | AS2: =CONCATENATE("Max. Lots that can be Traded with a Unit of Rs. ",'Base Data'!$D$7," [No. of Lots]") -> Max. Lots that can be Traded with a Unit of Rs. 25000 [No. of Lots] | AT2: High-Low Range | AU2: % Change (High-Low Range with Open) | AV2: Avg. % Change (8 Day) | AW2: Avg. % Change (13 Day) | AX2: Avg. % Change (21 Day) | AY2: High-Low Range | AZ2: % Change (High-Low Range with Open) | BA2: Avg. % Change (8 Day) | BB2: Avg. % Change (13 Day) | BC2: Avg. % Change (21 Day)
D3: =$F$1 -> BNF | E3: =$G$1 -> Nifty | F3: =$F$1 -> BNF | G3: =$G$1 -> Nifty
A4: Last Traded Price / Lot Size | D4: =VLOOKUP(D5,[1]NOW!$A:$O,3,FALSE) -> 17551 | E4: =VLOOKUP(E5,[1]NOW!$A:$O,3,FALSE) -> 8183.2 | F4: =VLOOKUP(D1,'[2]Margin - NSE Fut (5Paisa)'!$A:$K,2,FALSE) -> 30 | G4: =VLOOKUP(E1,'[2]Margin - NSE Fut (5Paisa)'!$A:$K,2,FALSE) -> 75 | L4: 1 | M4: ='[3]BANKNIFTY-I'!B302 -> 42452 | N4: ='[3]BANKNIFTY-I'!D302 -> 15952.65 | O4: ='[3]BANKNIFTY-I'!E302 -> 15963 | P4: ='[3]BANKNIFTY-I'!F302 -> 15810 | Q4: ='[3]BANKNIFTY-I'!G302 -> 15936.2 | R4: ='[3]BANKNIFTY-I'!I302 -> 2820750 | S4: ='[4]NIFTY-I'!B302 -> 42452 | T4: ='[4]NIFTY-I'!D302 -> 7696.6499 | U4: ='[4]NIFTY-I'!E302 -> 7746.5498 | V4: ='[4]NIFTY-I'!F302 -> 7678.2002 | W4: ='[4]NIFTY-I'!G302 -> 7736.2998 | X4: ='[4]NIFTY-I'!I302 -> 12288900 | Z4: 0 | AA4: 0 | AB4: 0 | AC4: 0 | AD4: - | AE4: 0 | AF4: 0 | AG4: 0 | AH4: 0 | AI4: - | AJ4: 0 | AK4: 0 | AL4: 0 | AM4: 0 | AN4: - | AO4: 0 | AP4: 0 | AQ4: 0 | AR4: 0 | AS4: - | AT4: =(O4-P4) -> 153 | AU4: =AT4/N4 -> 0.0095908828 | AV4: 0 | AW4: 0 | AX4: 0 | AY4: =(U4-V4) -> 68.3496 | AZ4: =AY4/T4 -> 0.0088804351 | BA4: 0 | BB4: 0 | BC4: 0
A5: Scrip Name with Expiry | D5: =CONCATENATE($D$1,$F$5) -> BankNifty16JunFut | E5: =CONCATENATE($E$1,$F$5) -> Nifty16JunFut | F5: ='Base Data'!$D$1 -> 16JunFut | L5: =L4+1 -> 2 | M5: ='[3]BANKNIFTY-I'!B303 -> 42457 | N5: ='[3]BANKNIFTY-I'!D303 -> 15890.1 | O5: ='[3]BANKNIFTY-I'!E303 -> 15909.6 | P5: ='[3]BANKNIFTY-I'!F303 -> 15569.95 | Q5: ='[3]BANKNIFTY-I'!G303 -> 15666.7 | R5: ='[3]BANKNIFTY-I'!I303 -> 3251880 | S5: ='[4]NIFTY-I'!B303 -> 42457 | T5: ='[4]NIFTY-I'!D303 -> 7715.25 | U5: ='[4]NIFTY-I'!E303 -> 7730.4502 | V5: ='[4]NIFTY-I'!F303 -> 7611.5 | W5: ='[4]NIFTY-I'!G303 -> 7638.6001 | X5: ='[4]NIFTY-I'!I303 -> 15136500 | Z5: =MAX(O5-P5,ABS(O5-Q4),ABS(Q4-P5)) -> 366.25 | AA5: 0 | AB5: 0 | AC5: 0 | AD5: - | AE5: =MAX(U5-V5,ABS(U5-W4),ABS(W4-V5)) -> 124.7998 | AF5: 0 | AG5: 0 | AH5: 0 | AI5: - | AJ5: =MAX(O5-P5,ABS(O5-Q4),ABS(Q4-P5)) -> 366.25 | AK5: 0 | AL5: 0 | AM5: 0 | AN5: 0 | AO5: =MAX(U5-V5,ABS(U5-W4),ABS(W4-V5)) -> 124.7998 | AP5: 0 | AQ5: 0 | AR5: 0 | AS5: - | AT5: =(O5-P5) -> 339.6494 | AU5: =AT5/N5 -> 0.021374907 | AV5: 0 | AW5: 0 | AX5: 0 | AY5: =(U5-V5) -> 118.9502 | AZ5: =AY5/T5 -> 0.015417543 | BA5: 0 | BB5: 0 | BC5: 0
L6: =L5+1 -> 3 | M6: ='[3]BANKNIFTY-I'!B304 -> 42458 | N6: ='[3]BANKNIFTY-I'!D304 -> 15640 | O6: ='[3]BANKNIFTY-I'!E304 -> 15827 | P6: ='[3]BANKNIFTY-I'!F304 -> 15622.95 | Q6: ='[3]BANKNIFTY-I'!G304 -> 15714.5 | R6: ='[3]BANKNIFTY-I'!I304 -> 3241470 | S6: ='[4]NIFTY-I'!B304 -> 42458 | T6: ='[4]NIFTY-I'!D304 -> 7629 | U6: ='[4]NIFTY-I'!E304 -> 7674.8999 | V6: ='[4]NIFTY-I'!F304 -> 7597.5 | W6: ='[4]NIFTY-I'!G304 -> 7620.0498 | X6: ='[4]NIFTY-I'!I304 -> 17362800 | Z6: =MAX(O6-P6,ABS(O6-Q5),ABS(Q5-P6)) -> 204.0498 | AA6: 0 | AB6: 0 | AC6: 0 | AD6: - | AE6: =MAX(U6-V6,ABS(U6-W5),ABS(W5-V6)) -> 77.3999 | AF6: 0 | AG6: 0 | AH6: 0 | AI6: - | AJ6: =MAX(O6-P6,ABS(O6-Q5),ABS(Q5-P6)) -> 204.0498 | AK6: 0 | AL6: 0 | AM6: 0 | AN6: 0 | AO6: =MAX(U6-V6,ABS(U6-W5),ABS(W5-V6)) -> 77.3999 | AP6: 0 | AQ6: 0 | AR6: 0 | AS6: - | AT6: =(O6-P6) -> 204.0498 | AU6: =AT6/N6 -> 0.013046662 | AV6: 0 | AW6: 0 | AX6: 0 | AY6: =(U6-V6) -> 77.3999 | AZ6: =AY6/T6 -> 0.010145484 | BA6: 0 | BB6: 0 | BC6: 0
L7: =L6+1 -> 4 | M7: ='[3]BANKNIFTY-I'!B305 -> 42459 | N7: ='[3]BANKNIFTY-I'!D305 -> 15879 | O7: ='[3]BANKNIFTY-I'!E305 -> 16179 | P7: ='[3]BANKNIFTY-I'!F305 -> 15784.25 | Q7: ='[3]BANKNIFTY-I'!G305 -> 16147.4 | R7: ='[3]BANKNIFTY-I'!I305 -> 3788970 | S7: ='[4]NIFTY-I'!B305 -> 42459 | T7: ='[4]NIFTY-I'!D305 -> 7674.4502 | U7: ='[4]NIFTY-I'!E305 -> 7749 | V7: ='[4]NIFTY-I'!F305 -> 7651.1001 | W7: ='[4]NIFTY-I'!G305 -> 7741 | X7: ='[4]NIFTY-I'!I305 -> 14385975 | Z7: =MAX(O7-P7,ABS(O7-Q6),ABS(Q6-P7)) -> 464.5 | AA7: 0 | AB7: 0 | AC7: 0 | AD7: - | AE7: =MAX(U7-V7,ABS(U7-W6),ABS(W6-V7)) -> 128.9502 | AF7: 0 | AG7: 0 | AH7: 0 | AI7: - | AJ7: =MAX(O7-P7,ABS(O7-Q6),ABS(Q6-P7)) -> 464.5 | AK7: 0 | AL7: 0 | AM7: 0 | AN7: 0 | AO7: =MAX(U7-V7,ABS(U7-W6),ABS(W6-V7)) -> 128.9502 | AP7: 0 | AQ7: 0 | AR7: 0 | AS7: - | AT7: =(O7-P7) -> 394.75 | AU7: =AT7/N7 -> 0.024859878 | AV7: 0 | AW7: 0 | AX7: 0 | AY7: =(U7-V7) -> 97.8999 | AZ7: =AY7/T7 -> 0.012756601 | BA7: 0 | BB7: 0 | BC7: 0
L8: =L7+1 -> 5 | M8: ='[3]BANKNIFTY-I'!B306 -> 42460 | N8: ='[3]BANKNIFTY-I'!D306 -> 16100 | O8: ='[3]BANKNIFTY-I'!E306 -> 16293.95 | P8: ='[3]BANKNIFTY-I'!F306 -> 16079.6 | Q8: ='[3]BANKNIFTY-I'!G306 -> 16148.6 | R8: ='[3]BANKNIFTY-I'!I306 -> 3388920 | S8: ='[4]NIFTY-I'!B306 -> 42460 | T8: ='[4]NIFTY-I'!D306 -> 7734.9502 | U8: ='[4]NIFTY-I'!E306 -> 7778.9502 | V8: ='[4]NIFTY-I'!F306 -> 7718.2998 | W8: ='[4]NIFTY-I'!G306 -> 7740.2002 | X8: ='[4]NIFTY-I'!I306 -> 18968400 | Z8: =MAX(O8-P8,ABS(O8-Q7),ABS(Q7-P8)) -> 214.3506 | AA8: 0 | AB8: 0 | AC8: 0 | AD8: - | AE8: =MAX(U8-V8,ABS(U8-W7),ABS(W7-V8)) -> 60.6504 | AF8: 0 | AG8: 0 | AH8: 0 | AI8: - | AJ8: =MAX(O8-P8,ABS(O8-Q7),ABS(Q7-P8)) -> 214.3506 | AK8: 0 | AL8: 0 | AM8: 0 | AN8: 0 | AO8: =MAX(U8-V8,ABS(U8-W7),ABS(W7-V8)) -> 60.6504 | AP8: 0 | AQ8: 0 | AR8: 0 | AS8: - | AT8: =(O8-P8) -> 214.3506 | AU8: =AT8/N8 -> 0.013313702 | AV8: 0 | AW8: 0 | AX8: 0 | AY8: =(U8-V8) -> 60.6504 | AZ8: =AY8/T8 -> 0.0078410847 | BA8: 0 | BB8: 0 | BC8: 0
L9: =L8+1 -> 6 | M9: ='[3]BANKNIFTY-I'!B307 -> 42461 | N9: ='[3]BANKNIFTY-I'!D307 -> 16200 | O9: ='[3]BANKNIFTY-I'!E307 -> 16320 | P9: ='[3]BANKNIFTY-I'!F307 -> 16088 | Q9: ='[3]BANKNIFTY-I'!G307 -> 16253.15 | R9: ='[3]BANKNIFTY-I'!I307 -> 2962320 | S9: ='[4]NIFTY-I'!B307 -> 42461 | T9: ='[4]NIFTY-I'!D307 -> 7754.8501 | U9: ='[4]NIFTY-I'!E307 -> 7772.6001 | V9: ='[4]NIFTY-I'!F307 -> 7704.1001 | W9: ='[4]NIFTY-I'!G307 -> 7748.75 | X9: ='[4]NIFTY-I'!I307 -> 13695225 | Z9: =MAX(O9-P9,ABS(O9-Q8),ABS(Q8-P9)) -> 232 | AA9: 0 | AB9: 0 | AC9: 0 | AD9: - | AE9: =MAX(U9-V9,ABS(U9-W8),ABS(W8-V9)) -> 68.5 | AF9: 0 | AG9: 0 | AH9: 0 | AI9: - | AJ9: =MAX(O9-P9,ABS(O9-Q8),ABS(Q8-P9)) -> 232 | AK9: 0 | AL9: 0 | AM9: 0 | AN9: 0 | AO9: =MAX(U9-V9,ABS(U9-W8),ABS(W8-V9)) -> 68.5 | AP9: 0 | AQ9: 0 | AR9: 0 | AS9: - | AT9: =(O9-P9) -> 232 | AU9: =AT9/N9 -> 0.014320988 | AV9: 0 | AW9: 0 | AX9: 0 | AY9: =(U9-V9) -> 68.5 | AZ9: =AY9/T9 -> 0.0088331817 | BA9: 0 | BB9: 0 | BC9: 0
L10: =L9+1 -> 7 | M10: ='[3]BANKNIFTY-I'!B308 -> 42464 | N10: ='[3]BANKNIFTY-I'!D308 -> 16306.95 | O10: ='[3]BANKNIFTY-I'!E308 -> 16341.65 | P10: ='[3]BANKNIFTY-I'!F308 -> 16126 | Q10: ='[3]BANKNIFTY-I'!G308 -> 16257.9 | R10: ='[3]BANKNIFTY-I'!I308 -> 2216460 | S10: ='[4]NIFTY-I'!B308 -> 42464 | T10: ='[4]NIFTY-I'!D308 -> 7778 | U10: ='[4]NIFTY-I'!E308 -> 7809.8999 | V10: ='[4]NIFTY-I'!F308 -> 7737 | W10: ='[4]NIFTY-I'!G308 -> 7790.75 | X10: ='[4]NIFTY-I'!I308 -> 8339175 | Z10: =MAX(O10-P10,ABS(O10-Q9),ABS(Q9-P10)) -> 215.6504 | AA10: 0 | AB10: 0 | AC10: 0 | AD10: - | AE10: =MAX(U10-V10,ABS(U10-W9),ABS(W9-V10)) -> 72.8999 | AF10: 0 | AG10: 0 | AH10: 0 | AI10: - | AJ10: =MAX(O10-P10,ABS(O10-Q9),ABS(Q9-P10)) -> 215.6504 | AK10: 0 | AL10: 0 | AM10: 0 | AN10: 0 | AO10: =MAX(U10-V10,ABS(U10-W9),ABS(W9-V10)) -> 72.8999 | AP10: 0 | AQ10: 0 | AR10: 0 | AS10: - | AT10: =(O10-P10) -> 215.6504 | AU10: =AT10/N10 -> 0.013224447 | AV10: 0 | AW10: 0 | AX10: 0 | AY10: =(U10-V10) -> 72.8999 | AZ10: =AY10/T10 -> 0.0093725765 | BA10: 0 | BB10: 0 | BC10: 0
L11: =L10+1 -> 8 | M11: ='[3]BANKNIFTY-I'!B309 -> 42465 | N11: ='[3]BANKNIFTY-I'!D309 -> 16143 | O11: ='[3]BANKNIFTY-I'!E309 -> 16261.55 | P11: ='[3]BANKNIFTY-I'!F309 -> 15692.2 | Q11: ='[3]BANKNIFTY-I'!G309 -> 15732.6 | R11: ='[3]BANKNIFTY-I'!I309 -> 5677440 | S11: ='[4]NIFTY-I'!B309 -> 42465 | T11: ='[4]NIFTY-I'!D309 -> 7735 | U11: ='[4]NIFTY-I'!E309 -> 7759.5 | V11: ='[4]NIFTY-I'!F309 -> 7609.9502 | W11: ='[4]NIFTY-I'!G309 -> 7623.5 | X11: ='[4]NIFTY-I'!I309 -> 19685100 | Z11: =MAX(O11-P11,ABS(O11-Q10),ABS(Q10-P11)) -> 569.3496 | AA11: 0 | AB11: 0 | AC11: 0 | AD11: - | AE11: =MAX(U11-V11,ABS(U11-W10),ABS(W10-V11)) -> 180.7998 | AF11: 0 | AG11: 0 | AH11: 0 | AI11: - | AJ11: =MAX(O11-P11,ABS(O11-Q10),ABS(Q10-P11)) -> 569.3496 | AK11: 0 | AL11: 0 | AM11: 0 | AN11: 0 | AO11: =MAX(U11-V11,ABS(U11-W10),ABS(W10-V11)) -> 180.7998 | AP11: 0 | AQ11: 0 | AR11: 0 | AS11: - | AT11: =(O11-P11) -> 569.3496 | AU11: =AT11/N11 -> 0.035269132 | AV11: =AVERAGE(AU4:AU11) -> 0.018125075 | AW11: 0 | AX11: 0 | AY11: =(U11-V11) -> 149.5498 | AZ11: =AY11/T11 -> 0.019334169 | BA11: =AVERAGE(AZ4:AZ11) -> 0.011572635 | BB11: 0 | BC11: 0
L12: =L11+1 -> 9 | M12: ='[3]BANKNIFTY-I'!B310 -> 42466 | N12: ='[3]BANKNIFTY-I'!D310 -> 15750 | O12: ='[3]BANKNIFTY-I'!E310 -> 15819 | P12: ='[3]BANKNIFTY-I'!F310 -> 15621 | Q12: ='[3]BANKNIFTY-I'!G310 -> 15706.05 | R12: ='[3]BANKNIFTY-I'!I310 -> 2950830 | S12: ='[4]NIFTY-I'!B310 -> 42466 | T12: ='[4]NIFTY-I'!D310 -> 7645.2002 | U12: ='[4]NIFTY-I'!E310 -> 7653.7998 | V12: ='[4]NIFTY-I'!F310 -> 7603.4502 | W12: ='[4]NIFTY-I'!G310 -> 7634.7002 | X12: ='[4]NIFTY-I'!I310 -> 10226250 | Z12: =MAX(O12-P12,ABS(O12-Q11),ABS(Q11-P12)) -> 198 | AA12: =AVERAGE(Z5:Z12) -> 308.0188 | AB12: =AA12*$F$4 -> 9240.564 | AC12: =AB12*'Base Data'!$D$13 -> 6930.423 | AD12: =IF(INT(('Base Data'!$D$7)/AC12)=0,0,INT(('Base Data'!$D$7)/AC12)) -> 3 | AE12: =MAX(U12-V12,ABS(U12-W11),ABS(W11-V12)) -> 50.3496 | AF12: =AVERAGE(AE5:AE12) -> 95.5437 | AG12: =AF12*$G$4 -> 7165.7775 | AH12: =AG12*'Base Data'!$D$13 -> 5374.3331 | AI12: =IF(INT(('Base Data'!$D$7)/AH12)=0,0,INT(('Base Data'!$D$7)/AH12)) -> 4 | AJ12: =MAX(O12-P12,ABS(O12-Q11),ABS(Q11-P12)) -> 198 | AK12: 0 | AL12: 0 | AM12: 0 | AN12: 0 | AO12: =MAX(U12-V12,ABS(U12-W11),ABS(W11-V12)) -> 50.3496 | AP12: 0 | AQ12: 0 | AR12: 0 | AS12: 0 | AT12: =(O12-P12) -> 198 | AU12: =AT12/N12 -> 0.012571429 | AV12: =AVERAGE(AU5:AU12) -> 0.018497643 | AW12: 0 | AX12: 0 | AY12: =(U12-V12) -> 50.3496 | AZ12: =AY12/T12 -> 0.0065857791 | BA12: =AVERAGE(AZ5:AZ12) -> 0.011285803 | BB12: 0 | BC12: 0
L13: =L12+1 -> 10 | M13: ='[3]BANKNIFTY-I'!B311 -> 42467 | N13: ='[3]BANKNIFTY-I'!D311 -> 15755.9 | O13: ='[3]BANKNIFTY-I'!E311 -> 15795.4 | P13: ='[3]BANKNIFTY-I'!F311 -> 15509 | Q13: ='[3]BANKNIFTY-I'!G311 -> 15591.4 | R13: ='[3]BANKNIFTY-I'!I311 -> 3891840 | S13: ='[4]NIFTY-I'!B311 -> 42467 | T13: ='[4]NIFTY-I'!D311 -> 7629 | U13: ='[4]NIFTY-I'!E311 -> 7634.7998 | V13: ='[4]NIFTY-I'!F311 -> 7555 | W13: ='[4]NIFTY-I'!G311 -> 7565.0498 | X13: ='[4]NIFTY-I'!I311 -> 13869675 | Z13: =MAX(O13-P13,ABS(O13-Q12),ABS(Q12-P13)) -> 286.4004 | AA13: =((Z13-AA12)*(2/(1+8)))+AA12 -> 303.21471 | AB13: =AA13*$F$4 -> 9096.4413 | AC13: =AB13*'Base Data'!$D$13 -> 6822.331 | AD13: =IF(INT(('Base Data'!$D$7)/AC13)=0,0,INT(('Base Data'!$D$7)/AC13)) -> 3 | AE13: =MAX(U13-V13,ABS(U13-W12),ABS(W12-V13)) -> 79.7998 | AF13: =((AE13-AF12)*(2/(1+8)))+AF12 -> 92.045056 | AG13: =AF13*$G$4 -> 6903.3792 | AH13: =AG13*'Base Data'!$D$13 -> 5177.5344 | AI13: =IF(INT(('Base Data'!$D$7)/AH13)=0,0,INT(('Base Data'!$D$7)/AH13)) -> 4 | AJ13: =MAX(O13-P13,ABS(O13-Q12),ABS(Q12-P13)) -> 286.4004 | AK13: 0 | AL13: 0 | AM13: 0 | AN13: 0 | AO13: =MAX(U13-V13,ABS(U13-W12),ABS(W12-V13)) -> 79.7998 | AP13: 0 | AQ13: 0 | AR13: 0 | AS13: 0 | AT13: =(O13-P13) -> 286.4004 | AU13: =AT13/N13 -> 0.018177343 | AV13: =AVERAGE(AU6:AU13) -> 0.018097948 | AW13: 0 | AX13: 0 | AY13: =(U13-V13) -> 79.7998 | AZ13: =AY13/T13 -> 0.01046006 | BA13: =AVERAGE(AZ6:AZ13) -> 0.010666117 | BB13: 0 | BC13: 0
L14: =L13+1 -> 11 | M14: ='[3]BANKNIFTY-I'!B312 -> 42468 | N14: ='[3]BANKNIFTY-I'!D312 -> 15568 | O14: ='[3]BANKNIFTY-I'!E312 -> 15720 | P14: ='[3]BANKNIFTY-I'!F312 -> 15543.6 | Q14: ='[3]BANKNIFTY-I'!G312 -> 15652.1 | R14: ='[3]BANKNIFTY-I'!I312 -> 2564220 | S14: ='[4]NIFTY-I'!B312 -> 42468 | T14: ='[4]NIFTY-I'!D312 -> 7540 | U14: ='[4]NIFTY-I'!E312 -> 7595.8501 | V14: ='[4]NIFTY-I'!F312 -> 7540 | W14: ='[4]NIFTY-I'!G312 -> 7578.1001 | X14: ='[4]NIFTY-I'!I312 -> 9017775 | Z14: =MAX(O14-P14,ABS(O14-Q13),ABS(Q13-P14)) -> 176.4004 | AA14: =((Z14-AA13)*(2/(1+8)))+AA13 -> 275.03375 | AB14: =AA14*$F$4 -> 8251.0126 | AC14: =AB14*'Base Data'!$D$13 -> 6188.2594 | AD14: =IF(INT(('Base Data'!$D$7)/AC14)=0,0,INT(('Base Data'!$D$7)/AC14)) -> 4 | AE14: =MAX(U14-V14,ABS(U14-W13),ABS(W13-V14)) -> 55.8501 | AF14: =((AE14-AF13)*(2/(1+8)))+AF13 -> 84.001732 | AG14: =AF14*$G$4 -> 6300.1299 | AH14: =AG14*'Base Data'!$D$13 -> 4725.0974 | AI14: =IF(INT(('Base Data'!$D$7)/AH14)=0,0,INT(('Base Data'!$D$7)/AH14)) -> 5 | AJ14: =MAX(O14-P14,ABS(O14-Q13),ABS(Q13-P14)) -> 176.4004 | AK14: 0 | AL14: 0 | AM14: 0 | AN14: 0 | AO14: =MAX(U14-V14,ABS(U14-W13),ABS(W13-V14)) -> 55.8501 | AP14: 0 | AQ14: 0 | AR14: 0 | AS14: 0 | AT14: =(O14-P14) -> 176.4004 | AU14: =AT14/N14 -> 0.011330961 | AV14: =AVERAGE(AU7:AU14) -> 0.017883485 | AW14: 0 | AX14: 0 | AY14: =(U14-V14) -> 55.8501 | AZ14: =AY14/T14 -> 0.0074071751 | BA14: =AVERAGE(AZ7:AZ14) -> 0.010323828 | BB14: 0 | BC14: 0
L15: =L14+1 -> 12 | M15: ='[3]BANKNIFTY-I'!B313 -> 42471 | N15: ='[3]BANKNIFTY-I'!D313 -> 15682 | O15: ='[3]BANKNIFTY-I'!E313 -> 15939.85 | P15: ='[3]BANKNIFTY-I'!F313 -> 15480 | Q15: ='[3]BANKNIFTY-I'!G313 -> 15896.05 | R15: ='[3]BANKNIFTY-I'!I313 -> 4071570 | S15: ='[4]NIFTY-I'!B313 -> 42471 | T15: ='[4]NIFTY-I'!D313 -> 7580.25 | U15: ='[4]NIFTY-I'!E313 -> 7712.8501 | V15: ='[4]NIFTY-I'!F313 -> 7533 | W15: ='[4]NIFTY-I'!G313 -> 7702.1001 | X15: ='[4]NIFTY-I'!I313 -> 15689700 | Z15: =MAX(O15-P15,ABS(O15-Q14),ABS(Q14-P15)) -> 459.8496 | AA15: =((Z15-AA14)*(2/(1+8)))+AA14 -> 316.10394 | AB15: =AA15*$F$4 -> 9483.1182 | AC15: =AB15*'Base Data'!$D$13 -> 7112.3387 | AD15: =IF(INT(('Base Data'!$D$7)/AC15)=0,0,INT(('Base Data'!$D$7)/AC15)) -> 3 | AE15: =MAX(U15-V15,ABS(U15-W14),ABS(W14-V15)) -> 179.8501 | AF15: =((AE15-AF14)*(2/(1+8)))+AF14 -> 105.30137 | AG15: =AF15*$G$4 -> 7897.6027 | AH15: =AG15*'Base Data'!$D$13 -> 5923.202 | AI15: =IF(INT(('Base Data'!$D$7)/AH15)=0,0,INT(('Base Data'!$D$7)/AH15)) -> 4 | AJ15: =MAX(O15-P15,ABS(O15-Q14),ABS(Q14-P15)) -> 459.8496 | AK15: 0 | AL15: 0 | AM15: 0 | AN15: 0 | AO15: =MAX(U15-V15,ABS(U15-W14),ABS(W14-V15)) -> 179.8501 | AP15: 0 | AQ15: 0 | AR15: 0 | AS15: 0 | AT15: =(O15-P15) -> 459.8496 | AU15: =AT15/N15 -> 0.029323403 | AV15: =AVERAGE(AU8:AU15) -> 0.018441425 | AW15: 0 | AX15: 0 | AY15: =(U15-V15) -> 179.8501 | AZ15: =AY15/T15 -> 0.023726144 | BA15: =AVERAGE(AZ8:AZ15) -> 0.011695021 | BB15: 0 | BC15: 0
L16: =L15+1 -> 13 | M16: ='[3]BANKNIFTY-I'!B314 -> 42472 | N16: ='[3]BANKNIFTY-I'!D314 -> 15821.05 | O16: ='[3]BANKNIFTY-I'!E314 -> 15998 | P16: ='[3]BANKNIFTY-I'!F314 -> 15821.05 | Q16: ='[3]BANKNIFTY-I'!G314 -> 15936.75 | R16: ='[3]BANKNIFTY-I'!I314 -> 2943120 | S16: ='[4]NIFTY-I'!B314 -> 42472 | T16: ='[4]NIFTY-I'!D314 -> 7694 | U16: ='[4]NIFTY-I'!E314 -> 7738 | V16: ='[4]NIFTY-I'!F314 -> 7685.3999 | W16: ='[4]NIFTY-I'!G314 -> 7732.7998 | X16: ='[4]NIFTY-I'!I314 -> 11439975 | Z16: =MAX(O16-P16,ABS(O16-Q15),ABS(Q15-P16)) -> 176.9502 | AA16: =((Z16-AA15)*(2/(1+8)))+AA15 -> 285.18089 | AB16: =AA16*$F$4 -> 8555.4266 | AC16: =AB16*'Base Data'!$D$13 -> 6416.57 | AD16: =IF(INT(('Base Data'!$D$7)/AC16)=0,0,INT(('Base Data'!$D$7)/AC16)) -> 3 | AE16: =MAX(U16-V16,ABS(U16-W15),ABS(W15-V16)) -> 52.6001 | AF16: =((AE16-AF15)*(2/(1+8)))+AF15 -> 93.589976 | AG16: =AF16*$G$4 -> 7019.2482 | AH16: =AG16*'Base Data'!$D$13 -> 5264.4362 | AI16: =IF(INT(('Base Data'!$D$7)/AH16)=0,0,INT(('Base Data'!$D$7)/AH16)) -> 4 | AJ16: =MAX(O16-P16,ABS(O16-Q15),ABS(Q15-P16)) -> 176.9502 | AK16: 0 | AL16: 0 | AM16: 0 | AN16: 0 | AO16: =MAX(U16-V16,ABS(U16-W15),ABS(W15-V16)) -> 52.6001 | AP16: 0 | AQ16: 0 | AR16: 0 | AS16: 0 | AT16: =(O16-P16) -> 176.9502 | AU16: =AT16/N16 -> 0.011184479 | AV16: =AVERAGE(AU9:AU16) -> 0.018175273 | AW16: =AVERAGE(AU4:AU16) -> 0.017506786 | AX16: 0 | AY16: =(U16-V16) -> 52.6001 | AZ16: =AY16/T16 -> 0.006836509 | BA16: =AVERAGE(AZ9:AZ16) -> 0.011569449 | BB16: =AVERAGE(AZ4:AZ16) -> 0.011353596 | BC16: 0
L17: =L16+1 -> 14 | M17: ='[3]BANKNIFTY-I'!B315 -> 42473 | N17: ='[3]BANKNIFTY-I'!D315 -> 16131 | O17: ='[3]BANKNIFTY-I'!E315 -> 16416 | P17: ='[3]BANKNIFTY-I'!F315 -> 16085.1 | Q17: ='[3]BANKNIFTY-I'!G315 -> 16332.75 | R17: ='[3]BANKNIFTY-I'!I315 -> 3469800 | S17: ='[4]NIFTY-I'!B315 -> 42473 | T17: ='[4]NIFTY-I'!D315 -> 7792.5 | U17: ='[4]NIFTY-I'!E315 -> 7893.4502 | V17: ='[4]NIFTY-I'!F315 -> 7791.1001 | W17: ='[4]NIFTY-I'!G315 -> 7867.8501 | X17: ='[4]NIFTY-I'!I315 -> 14597475 | Z17: =MAX(O17-P17,ABS(O17-Q16),ABS(Q16-P17)) -> 479.25 | AA17: =((Z17-AA16)*(2/(1+8)))+AA16 -> 328.30736 | AB17: =AA17*$F$4 -> 9849.2207 | AC17: =AB17*'Base Data'!$D$13 -> 7386.9155 | AD17: =IF(INT(('Base Data'!$D$7)/AC17)=0,0,INT(('Base Data'!$D$7)/AC17)) -> 3 | AE17: =MAX(U17-V17,ABS(U17-W16),ABS(W16-V17)) -> 160.6504 | AF17: =((AE17-AF16)*(2/(1+8)))+AF16 -> 108.49229 | AG17: =AF17*$G$4 -> 8136.9219 | AH17: =AG17*'Base Data'!$D$13 -> 6102.6915 | AI17: =IF(INT(('Base Data'!$D$7)/AH17)=0,0,INT(('Base Data'!$D$7)/AH17)) -> 4 | AJ17: =MAX(O17-P17,ABS(O17-Q16),ABS(Q16-P17)) -> 479.25 | AK17: 0 | AL17: 0 | AM17: 0 | AN17: 0 | AO17: =MAX(U17-V17,ABS(U17-W16),ABS(W16-V17)) -> 160.6504 | AP17: 0 | AQ17: 0 | AR17: 0 | AS17: 0 | AT17: =(O17-P17) -> 330.9004 | AU17: =AT17/N17 -> 0.020513322 | AV17: =AVERAGE(AU10:AU17) -> 0.018949314 | AW17: =AVERAGE(AU5:AU17) -> 0.018346973 | AX17: 0 | AY17: =(U17-V17) -> 102.3501 | AZ17: =AY17/T17 -> 0.013134437 | BA17: =AVERAGE(AZ10:AZ17) -> 0.012107106 | BB17: =AVERAGE(AZ5:AZ17) -> 0.011680827 | BC17: 0
